<sdf version='1.6'>
  <world name='default'>
    <light name='sun' type='directional'>
      <cast_shadows>1</cast_shadows>
      <pose frame=''>0 0 10 0 -0 0</pose>
      <diffuse>0.8 0.8 0.8 1</diffuse>
      <specular>0.2 0.2 0.2 1</specular>
      <attenuation>
        <range>1000</range>
        <constant>0.9</constant>
        <linear>0.01</linear>
        <quadratic>0.001</quadratic>
      </attenuation>
      <direction>-0.5 0.1 -0.9</direction>
    </light>
    <model name='ground_plane'>
      <static>1</static>
      <link name='link'>
        <collision name='collision'>
          <geometry>
            <plane>
              <normal>0 0 1</normal>
              <size>100 100</size>
            </plane>
          </geometry>
          <surface>
            <friction>
              <ode>
                <mu>100</mu>
                <mu2>50</mu2>
              </ode>
              <torsional>
                <ode/>
              </torsional>
            </friction>
            <contact>
              <ode/>
            </contact>
            <bounce/>
          </surface>
          <max_contacts>10</max_contacts>
        </collision>
        <visual name='visual'>
          <cast_shadows>0</cast_shadows>
          <geometry>
            <plane>
              <normal>0 0 1</normal>
              <size>100 100</size>
            </plane>
          </geometry>
          <material>
            <script>
              <uri>file://media/materials/scripts/gazebo.material</uri>
              <name>Gazebo/Grey</name>
            </script>
          </material>
        </visual>
        <self_collide>0</self_collide>
        <kinematic>0</kinematic>
      </link>
    </model>
    <gravity>0 0 -9.8</gravity>
    <magnetic_field>6e-06 2.3e-05 -4.2e-05</magnetic_field>
    <atmosphere type='adiabatic'/>
    <physics name='default_physics' default='0' type='ode'>
      <max_step_size>0.001</max_step_size>
      <real_time_factor>1</real_time_factor>
      <real_time_update_rate>1000</real_time_update_rate>
    </physics>
    <scene>
      <ambient>0.4 0.4 0.4 1</ambient>
      <background>0.7 0.7 0.7 1</background>
      <shadows>1</shadows>
    </scene>
    <spherical_coordinates>
      <surface_model>EARTH_WGS84</surface_model>
      <latitude_deg>0</latitude_deg>
      <longitude_deg>0</longitude_deg>
      <elevation>0</elevation>
      <heading_deg>0</heading_deg>
    </spherical_coordinates>
    <model name='table'>
      <static>1</static>
      <link name='link'>
        <collision name='surface'>
          <pose frame=''>0 0 1 0 -0 0</pose>
          <geometry>
            <box>
              <size>1.5 0.8 0.03</size>
            </box>
          </geometry>
          <surface>
            <friction>
              <ode>
                <mu>0.6</mu>
                <mu2>0.6</mu2>
              </ode>
              <torsional>
                <ode/>
              </torsional>
            </friction>
            <contact>
              <ode/>
            </contact>
            <bounce/>
          </surface>
          <max_contacts>10</max_contacts>
        </collision>
        <visual name='visual1'>
          <pose frame=''>0 0 1 0 -0 0</pose>
          <geometry>
            <box>
              <size>1.5 0.8 0.03</size>
            </box>
          </geometry>
          <material>
            <script>
              <uri>file://media/materials/scripts/gazebo.material</uri>
              <name>Gazebo/Wood</name>
            </script>
          </material>
        </visual>
        <collision name='front_left_leg'>
          <pose frame=''>0.68 0.38 0.5 0 -0 0</pose>
          <geometry>
            <cylinder>
              <radius>0.02</radius>
              <length>1</length>
            </cylinder>
          </geometry>
          <max_contacts>10</max_contacts>
          <surface>
            <contact>
              <ode/>
            </contact>
            <bounce/>
            <friction>
              <torsional>
                <ode/>
              </torsional>
              <ode/>
            </friction>
          </surface>
        </collision>
        <visual name='front_left_leg'>
          <pose frame=''>0.68 0.38 0.5 0 -0 0</pose>
          <geometry>
            <cylinder>
              <radius>0.02</radius>
              <length>1</length>
            </cylinder>
          </geometry>
          <material>
            <script>
              <uri>file://media/materials/scripts/gazebo.material</uri>
              <name>Gazebo/Grey</name>
            </script>
          </material>
        </visual>
        <collision name='front_right_leg'>
          <pose frame=''>0.68 -0.38 0.5 0 -0 0</pose>
          <geometry>
            <cylinder>
              <radius>0.02</radius>
              <length>1</length>
            </cylinder>
          </geometry>
          <max_contacts>10</max_contacts>
          <surface>
            <contact>
              <ode/>
            </contact>
            <bounce/>
            <friction>
              <torsional>
                <ode/>
              </torsional>
              <ode/>
            </friction>
          </surface>
        </collision>
        <visual name='front_right_leg'>
          <pose frame=''>0.68 -0.38 0.5 0 -0 0</pose>
          <geometry>
            <cylinder>
              <radius>0.02</radius>
              <length>1</length>
            </cylinder>
          </geometry>
          <material>
            <script>
              <uri>file://media/materials/scripts/gazebo.material</uri>
              <name>Gazebo/Grey</name>
            </script>
          </material>
        </visual>
        <collision name='back_right_leg'>
          <pose frame=''>-0.68 -0.38 0.5 0 -0 0</pose>
          <geometry>
            <cylinder>
              <radius>0.02</radius>
              <length>1</length>
            </cylinder>
          </geometry>
          <max_contacts>10</max_contacts>
          <surface>
            <contact>
              <ode/>
            </contact>
            <bounce/>
            <friction>
              <torsional>
                <ode/>
              </torsional>
              <ode/>
            </friction>
          </surface>
        </collision>
        <visual name='back_right_leg'>
          <pose frame=''>-0.68 -0.38 0.5 0 -0 0</pose>
          <geometry>
            <cylinder>
              <radius>0.02</radius>
              <length>1</length>
            </cylinder>
          </geometry>
          <material>
            <script>
              <uri>file://media/materials/scripts/gazebo.material</uri>
              <name>Gazebo/Grey</name>
            </script>
          </material>
        </visual>
        <collision name='back_left_leg'>
          <pose frame=''>-0.68 0.38 0.5 0 -0 0</pose>
          <geometry>
            <cylinder>
              <radius>0.02</radius>
              <length>1</length>
            </cylinder>
          </geometry>
          <max_contacts>10</max_contacts>
          <surface>
            <contact>
              <ode/>
            </contact>
            <bounce/>
            <friction>
              <torsional>
                <ode/>
              </torsional>
              <ode/>
            </friction>
          </surface>
        </collision>
        <visual name='back_left_leg'>
          <pose frame=''>-0.68 0.38 0.5 0 -0 0</pose>
          <geometry>
            <cylinder>
              <radius>0.02</radius>
              <length>1</length>
            </cylinder>
          </geometry>
          <material>
            <script>
              <uri>file://media/materials/scripts/gazebo.material</uri>
              <name>Gazebo/Grey</name>
            </script>
          </material>
        </visual>
        <self_collide>0</self_collide>
        <kinematic>0</kinematic>
      </link>
      <pose frame=''>-0.898858 0.658066 0 0 -0 0</pose>
    </model>
    <model name='table_clone'>
      <static>1</static>
      <link name='link'>
        <collision name='surface'>
          <pose frame=''>0 0 1 0 -0 0</pose>
          <geometry>
            <box>
              <size>1.5 0.8 0.03</size>
            </box>
          </geometry>
          <surface>
            <friction>
              <ode>
                <mu>0.6</mu>
                <mu2>0.6</mu2>
              </ode>
              <torsional>
                <ode/>
              </torsional>
            </friction>
            <contact>
              <ode/>
            </contact>
            <bounce/>
          </surface>
          <max_contacts>10</max_contacts>
        </collision>
        <visual name='visual1'>
          <pose frame=''>0 0 1 0 -0 0</pose>
          <geometry>
            <box>
              <size>1.5 0.8 0.03</size>
            </box>
          </geometry>
          <material>
            <script>
              <uri>file://media/materials/scripts/gazebo.material</uri>
              <name>Gazebo/Wood</name>
            </script>
          </material>
        </visual>
        <collision name='front_left_leg'>
          <pose frame=''>0.68 0.38 0.5 0 -0 0</pose>
          <geometry>
            <cylinder>
              <radius>0.02</radius>
              <length>1</length>
            </cylinder>
          </geometry>
          <max_contacts>10</max_contacts>
          <surface>
            <contact>
              <ode/>
            </contact>
            <bounce/>
            <friction>
              <torsional>
                <ode/>
              </torsional>
              <ode/>
            </friction>
          </surface>
        </collision>
        <visual name='front_left_leg'>
          <pose frame=''>0.68 0.38 0.5 0 -0 0</pose>
          <geometry>
            <cylinder>
              <radius>0.02</radius>
              <length>1</length>
            </cylinder>
          </geometry>
          <material>
            <script>
              <uri>file://media/materials/scripts/gazebo.material</uri>
              <name>Gazebo/Grey</name>
            </script>
          </material>
        </visual>
        <collision name='front_right_leg'>
          <pose frame=''>0.68 -0.38 0.5 0 -0 0</pose>
          <geometry>
            <cylinder>
              <radius>0.02</radius>
              <length>1</length>
            </cylinder>
          </geometry>
          <max_contacts>10</max_contacts>
          <surface>
            <contact>
              <ode/>
            </contact>
            <bounce/>
            <friction>
              <torsional>
                <ode/>
              </torsional>
              <ode/>
            </friction>
          </surface>
        </collision>
        <visual name='front_right_leg'>
          <pose frame=''>0.68 -0.38 0.5 0 -0 0</pose>
          <geometry>
            <cylinder>
              <radius>0.02</radius>
              <length>1</length>
            </cylinder>
          </geometry>
          <material>
            <script>
              <uri>file://media/materials/scripts/gazebo.material</uri>
              <name>Gazebo/Grey</name>
            </script>
          </material>
        </visual>
        <collision name='back_right_leg'>
          <pose frame=''>-0.68 -0.38 0.5 0 -0 0</pose>
          <geometry>
            <cylinder>
              <radius>0.02</radius>
              <length>1</length>
            </cylinder>
          </geometry>
          <max_contacts>10</max_contacts>
          <surface>
            <contact>
              <ode/>
            </contact>
            <bounce/>
            <friction>
              <torsional>
                <ode/>
              </torsional>
              <ode/>
            </friction>
          </surface>
        </collision>
        <visual name='back_right_leg'>
          <pose frame=''>-0.68 -0.38 0.5 0 -0 0</pose>
          <geometry>
            <cylinder>
              <radius>0.02</radius>
              <length>1</length>
            </cylinder>
          </geometry>
          <material>
            <script>
              <uri>file://media/materials/scripts/gazebo.material</uri>
              <name>Gazebo/Grey</name>
            </script>
          </material>
        </visual>
        <collision name='back_left_leg'>
          <pose frame=''>-0.68 0.38 0.5 0 -0 0</pose>
          <geometry>
            <cylinder>
              <radius>0.02</radius>
              <length>1</length>
            </cylinder>
          </geometry>
          <max_contacts>10</max_contacts>
          <surface>
            <contact>
              <ode/>
            </contact>
            <bounce/>
            <friction>
              <torsional>
                <ode/>
              </torsional>
              <ode/>
            </friction>
          </surface>
        </collision>
        <visual name='back_left_leg'>
          <pose frame=''>-0.68 0.38 0.5 0 -0 0</pose>
          <geometry>
            <cylinder>
              <radius>0.02</radius>
              <length>1</length>
            </cylinder>
          </geometry>
          <material>
            <script>
              <uri>file://media/materials/scripts/gazebo.material</uri>
              <name>Gazebo/Grey</name>
            </script>
          </material>
        </visual>
        <self_collide>0</self_collide>
        <kinematic>0</kinematic>
      </link>
      <pose frame=''>-1.32325 1.64119 0 0 0 -1.58073</pose>
    </model>
    <model name='table_clone_0'>
      <static>1</static>
      <link name='link'>
        <collision name='surface'>
          <pose frame=''>0 0 1 0 -0 0</pose>
          <geometry>
            <box>
              <size>1.5 0.8 0.03</size>
            </box>
          </geometry>
          <surface>
            <friction>
              <ode>
                <mu>0.6</mu>
                <mu2>0.6</mu2>
              </ode>
              <torsional>
                <ode/>
              </torsional>
            </friction>
            <contact>
              <ode/>
            </contact>
            <bounce/>
          </surface>
          <max_contacts>10</max_contacts>
        </collision>
        <visual name='visual1'>
          <pose frame=''>0 0 1 0 -0 0</pose>
          <geometry>
            <box>
              <size>1.5 0.8 0.03</size>
            </box>
          </geometry>
          <material>
            <script>
              <uri>file://media/materials/scripts/gazebo.material</uri>
              <name>Gazebo/Wood</name>
            </script>
          </material>
        </visual>
        <collision name='front_left_leg'>
          <pose frame=''>0.68 0.38 0.5 0 -0 0</pose>
          <geometry>
            <cylinder>
              <radius>0.02</radius>
              <length>1</length>
            </cylinder>
          </geometry>
          <max_contacts>10</max_contacts>
          <surface>
            <contact>
              <ode/>
            </contact>
            <bounce/>
            <friction>
              <torsional>
                <ode/>
              </torsional>
              <ode/>
            </friction>
          </surface>
        </collision>
        <visual name='front_left_leg'>
          <pose frame=''>0.68 0.38 0.5 0 -0 0</pose>
          <geometry>
            <cylinder>
              <radius>0.02</radius>
              <length>1</length>
            </cylinder>
          </geometry>
          <material>
            <script>
              <uri>file://media/materials/scripts/gazebo.material</uri>
              <name>Gazebo/Grey</name>
            </script>
          </material>
        </visual>
        <collision name='front_right_leg'>
          <pose frame=''>0.68 -0.38 0.5 0 -0 0</pose>
          <geometry>
            <cylinder>
              <radius>0.02</radius>
              <length>1</length>
            </cylinder>
          </geometry>
          <max_contacts>10</max_contacts>
          <surface>
            <contact>
              <ode/>
            </contact>
            <bounce/>
            <friction>
              <torsional>
                <ode/>
              </torsional>
              <ode/>
            </friction>
          </surface>
        </collision>
        <visual name='front_right_leg'>
          <pose frame=''>0.68 -0.38 0.5 0 -0 0</pose>
          <geometry>
            <cylinder>
              <radius>0.02</radius>
              <length>1</length>
            </cylinder>
          </geometry>
          <material>
            <script>
              <uri>file://media/materials/scripts/gazebo.material</uri>
              <name>Gazebo/Grey</name>
            </script>
          </material>
        </visual>
        <collision name='back_right_leg'>
          <pose frame=''>-0.68 -0.38 0.5 0 -0 0</pose>
          <geometry>
            <cylinder>
              <radius>0.02</radius>
              <length>1</length>
            </cylinder>
          </geometry>
          <max_contacts>10</max_contacts>
          <surface>
            <contact>
              <ode/>
            </contact>
            <bounce/>
            <friction>
              <torsional>
                <ode/>
              </torsional>
              <ode/>
            </friction>
          </surface>
        </collision>
        <visual name='back_right_leg'>
          <pose frame=''>-0.68 -0.38 0.5 0 -0 0</pose>
          <geometry>
            <cylinder>
              <radius>0.02</radius>
              <length>1</length>
            </cylinder>
          </geometry>
          <material>
            <script>
              <uri>file://media/materials/scripts/gazebo.material</uri>
              <name>Gazebo/Grey</name>
            </script>
          </material>
        </visual>
        <collision name='back_left_leg'>
          <pose frame=''>-0.68 0.38 0.5 0 -0 0</pose>
          <geometry>
            <cylinder>
              <radius>0.02</radius>
              <length>1</length>
            </cylinder>
          </geometry>
          <max_contacts>10</max_contacts>
          <surface>
            <contact>
              <ode/>
            </contact>
            <bounce/>
            <friction>
              <torsional>
                <ode/>
              </torsional>
              <ode/>
            </friction>
          </surface>
        </collision>
        <visual name='back_left_leg'>
          <pose frame=''>-0.68 0.38 0.5 0 -0 0</pose>
          <geometry>
            <cylinder>
              <radius>0.02</radius>
              <length>1</length>
            </cylinder>
          </geometry>
          <material>
            <script>
              <uri>file://media/materials/scripts/gazebo.material</uri>
              <name>Gazebo/Grey</name>
            </script>
          </material>
        </visual>
        <self_collide>0</self_collide>
        <kinematic>0</kinematic>
      </link>
      <pose frame=''>3.23306 0.062335 0 0 0 -1.58073</pose>
    </model>
    <model name='table_clone_0_clone'>
      <static>1</static>
      <link name='link'>
        <collision name='surface'>
          <pose frame=''>0 0 1 0 -0 0</pose>
          <geometry>
            <box>
              <size>1.5 0.8 0.03</size>
            </box>
          </geometry>
          <surface>
            <friction>
              <ode>
                <mu>0.6</mu>
                <mu2>0.6</mu2>
              </ode>
              <torsional>
                <ode/>
              </torsional>
            </friction>
            <contact>
              <ode/>
            </contact>
            <bounce/>
          </surface>
          <max_contacts>10</max_contacts>
        </collision>
        <visual name='visual1'>
          <pose frame=''>0 0 1 0 -0 0</pose>
          <geometry>
            <box>
              <size>1.5 0.8 0.03</size>
            </box>
          </geometry>
          <material>
            <script>
              <uri>file://media/materials/scripts/gazebo.material</uri>
              <name>Gazebo/Wood</name>
            </script>
          </material>
        </visual>
        <collision name='front_left_leg'>
          <pose frame=''>0.68 0.38 0.5 0 -0 0</pose>
          <geometry>
            <cylinder>
              <radius>0.02</radius>
              <length>1</length>
            </cylinder>
          </geometry>
          <max_contacts>10</max_contacts>
          <surface>
            <contact>
              <ode/>
            </contact>
            <bounce/>
            <friction>
              <torsional>
                <ode/>
              </torsional>
              <ode/>
            </friction>
          </surface>
        </collision>
        <visual name='front_left_leg'>
          <pose frame=''>0.68 0.38 0.5 0 -0 0</pose>
          <geometry>
            <cylinder>
              <radius>0.02</radius>
              <length>1</length>
            </cylinder>
          </geometry>
          <material>
            <script>
              <uri>file://media/materials/scripts/gazebo.material</uri>
              <name>Gazebo/Grey</name>
            </script>
          </material>
        </visual>
        <collision name='front_right_leg'>
          <pose frame=''>0.68 -0.38 0.5 0 -0 0</pose>
          <geometry>
            <cylinder>
              <radius>0.02</radius>
              <length>1</length>
            </cylinder>
          </geometry>
          <max_contacts>10</max_contacts>
          <surface>
            <contact>
              <ode/>
            </contact>
            <bounce/>
            <friction>
              <torsional>
                <ode/>
              </torsional>
              <ode/>
            </friction>
          </surface>
        </collision>
        <visual name='front_right_leg'>
          <pose frame=''>0.68 -0.38 0.5 0 -0 0</pose>
          <geometry>
            <cylinder>
              <radius>0.02</radius>
              <length>1</length>
            </cylinder>
          </geometry>
          <material>
            <script>
              <uri>file://media/materials/scripts/gazebo.material</uri>
              <name>Gazebo/Grey</name>
            </script>
          </material>
        </visual>
        <collision name='back_right_leg'>
          <pose frame=''>-0.68 -0.38 0.5 0 -0 0</pose>
          <geometry>
            <cylinder>
              <radius>0.02</radius>
              <length>1</length>
            </cylinder>
          </geometry>
          <max_contacts>10</max_contacts>
          <surface>
            <contact>
              <ode/>
            </contact>
            <bounce/>
            <friction>
              <torsional>
                <ode/>
              </torsional>
              <ode/>
            </friction>
          </surface>
        </collision>
        <visual name='back_right_leg'>
          <pose frame=''>-0.68 -0.38 0.5 0 -0 0</pose>
          <geometry>
            <cylinder>
              <radius>0.02</radius>
              <length>1</length>
            </cylinder>
          </geometry>
          <material>
            <script>
              <uri>file://media/materials/scripts/gazebo.material</uri>
              <name>Gazebo/Grey</name>
            </script>
          </material>
        </visual>
        <collision name='back_left_leg'>
          <pose frame=''>-0.68 0.38 0.5 0 -0 0</pose>
          <geometry>
            <cylinder>
              <radius>0.02</radius>
              <length>1</length>
            </cylinder>
          </geometry>
          <max_contacts>10</max_contacts>
          <surface>
            <contact>
              <ode/>
            </contact>
            <bounce/>
            <friction>
              <torsional>
                <ode/>
              </torsional>
              <ode/>
            </friction>
          </surface>
        </collision>
        <visual name='back_left_leg'>
          <pose frame=''>-0.68 0.38 0.5 0 -0 0</pose>
          <geometry>
            <cylinder>
              <radius>0.02</radius>
              <length>1</length>
            </cylinder>
          </geometry>
          <material>
            <script>
              <uri>file://media/materials/scripts/gazebo.material</uri>
              <name>Gazebo/Grey</name>
            </script>
          </material>
        </visual>
        <self_collide>0</self_collide>
        <kinematic>0</kinematic>
      </link>
      <pose frame=''>6.2487 1.7053 0 0 0 -3.13587</pose>
    </model>
    <model name='table_clone_0_clone_0'>
      <static>1</static>
      <link name='link'>
        <collision name='surface'>
          <pose frame=''>0 0 1 0 -0 0</pose>
          <geometry>
            <box>
              <size>1.5 0.8 0.03</size>
            </box>
          </geometry>
          <surface>
            <friction>
              <ode>
                <mu>0.6</mu>
                <mu2>0.6</mu2>
              </ode>
              <torsional>
                <ode/>
              </torsional>
            </friction>
            <contact>
              <ode/>
            </contact>
            <bounce/>
          </surface>
          <max_contacts>10</max_contacts>
        </collision>
        <visual name='visual1'>
          <pose frame=''>0 0 1 0 -0 0</pose>
          <geometry>
            <box>
              <size>1.5 0.8 0.03</size>
            </box>
          </geometry>
          <material>
            <script>
              <uri>file://media/materials/scripts/gazebo.material</uri>
              <name>Gazebo/Wood</name>
            </script>
          </material>
        </visual>
        <collision name='front_left_leg'>
          <pose frame=''>0.68 0.38 0.5 0 -0 0</pose>
          <geometry>
            <cylinder>
              <radius>0.02</radius>
              <length>1</length>
            </cylinder>
          </geometry>
          <max_contacts>10</max_contacts>
          <surface>
            <contact>
              <ode/>
            </contact>
            <bounce/>
            <friction>
              <torsional>
                <ode/>
              </torsional>
              <ode/>
            </friction>
          </surface>
        </collision>
        <visual name='front_left_leg'>
          <pose frame=''>0.68 0.38 0.5 0 -0 0</pose>
          <geometry>
            <cylinder>
              <radius>0.02</radius>
              <length>1</length>
            </cylinder>
          </geometry>
          <material>
            <script>
              <uri>file://media/materials/scripts/gazebo.material</uri>
              <name>Gazebo/Grey</name>
            </script>
          </material>
        </visual>
        <collision name='front_right_leg'>
          <pose frame=''>0.68 -0.38 0.5 0 -0 0</pose>
          <geometry>
            <cylinder>
              <radius>0.02</radius>
              <length>1</length>
            </cylinder>
          </geometry>
          <max_contacts>10</max_contacts>
          <surface>
            <contact>
              <ode/>
            </contact>
            <bounce/>
            <friction>
              <torsional>
                <ode/>
              </torsional>
              <ode/>
            </friction>
          </surface>
        </collision>
        <visual name='front_right_leg'>
          <pose frame=''>0.68 -0.38 0.5 0 -0 0</pose>
          <geometry>
            <cylinder>
              <radius>0.02</radius>
              <length>1</length>
            </cylinder>
          </geometry>
          <material>
            <script>
              <uri>file://media/materials/scripts/gazebo.material</uri>
              <name>Gazebo/Grey</name>
            </script>
          </material>
        </visual>
        <collision name='back_right_leg'>
          <pose frame=''>-0.68 -0.38 0.5 0 -0 0</pose>
          <geometry>
            <cylinder>
              <radius>0.02</radius>
              <length>1</length>
            </cylinder>
          </geometry>
          <max_contacts>10</max_contacts>
          <surface>
            <contact>
              <ode/>
            </contact>
            <bounce/>
            <friction>
              <torsional>
                <ode/>
              </torsional>
              <ode/>
            </friction>
          </surface>
        </collision>
        <visual name='back_right_leg'>
          <pose frame=''>-0.68 -0.38 0.5 0 -0 0</pose>
          <geometry>
            <cylinder>
              <radius>0.02</radius>
              <length>1</length>
            </cylinder>
          </geometry>
          <material>
            <script>
              <uri>file://media/materials/scripts/gazebo.material</uri>
              <name>Gazebo/Grey</name>
            </script>
          </material>
        </visual>
        <collision name='back_left_leg'>
          <pose frame=''>-0.68 0.38 0.5 0 -0 0</pose>
          <geometry>
            <cylinder>
              <radius>0.02</radius>
              <length>1</length>
            </cylinder>
          </geometry>
          <max_contacts>10</max_contacts>
          <surface>
            <contact>
              <ode/>
            </contact>
            <bounce/>
            <friction>
              <torsional>
                <ode/>
              </torsional>
              <ode/>
            </friction>
          </surface>
        </collision>
        <visual name='back_left_leg'>
          <pose frame=''>-0.68 0.38 0.5 0 -0 0</pose>
          <geometry>
            <cylinder>
              <radius>0.02</radius>
              <length>1</length>
            </cylinder>
          </geometry>
          <material>
            <script>
              <uri>file://media/materials/scripts/gazebo.material</uri>
              <name>Gazebo/Grey</name>
            </script>
          </material>
        </visual>
        <self_collide>0</self_collide>
        <kinematic>0</kinematic>
      </link>
      <pose frame=''>5.76717 -2.47907 0 0 0 -3.13587</pose>
    </model>
    <model name='table_clone_0_clone_0_clone'>
      <static>1</static>
      <link name='link'>
        <collision name='surface'>
          <pose frame=''>0 0 1 0 -0 0</pose>
          <geometry>
            <box>
              <size>1.5 0.8 0.03</size>
            </box>
          </geometry>
          <surface>
            <friction>
              <ode>
                <mu>0.6</mu>
                <mu2>0.6</mu2>
              </ode>
              <torsional>
                <ode/>
              </torsional>
            </friction>
            <contact>
              <ode/>
            </contact>
            <bounce/>
          </surface>
          <max_contacts>10</max_contacts>
        </collision>
        <visual name='visual1'>
          <pose frame=''>0 0 1 0 -0 0</pose>
          <geometry>
            <box>
              <size>1.5 0.8 0.03</size>
            </box>
          </geometry>
          <material>
            <script>
              <uri>file://media/materials/scripts/gazebo.material</uri>
              <name>Gazebo/Wood</name>
            </script>
          </material>
        </visual>
        <collision name='front_left_leg'>
          <pose frame=''>0.68 0.38 0.5 0 -0 0</pose>
          <geometry>
            <cylinder>
              <radius>0.02</radius>
              <length>1</length>
            </cylinder>
          </geometry>
          <max_contacts>10</max_contacts>
          <surface>
            <contact>
              <ode/>
            </contact>
            <bounce/>
            <friction>
              <torsional>
                <ode/>
              </torsional>
              <ode/>
            </friction>
          </surface>
        </collision>
        <visual name='front_left_leg'>
          <pose frame=''>0.68 0.38 0.5 0 -0 0</pose>
          <geometry>
            <cylinder>
              <radius>0.02</radius>
              <length>1</length>
            </cylinder>
          </geometry>
          <material>
            <script>
              <uri>file://media/materials/scripts/gazebo.material</uri>
              <name>Gazebo/Grey</name>
            </script>
          </material>
        </visual>
        <collision name='front_right_leg'>
          <pose frame=''>0.68 -0.38 0.5 0 -0 0</pose>
          <geometry>
            <cylinder>
              <radius>0.02</radius>
              <length>1</length>
            </cylinder>
          </geometry>
          <max_contacts>10</max_contacts>
          <surface>
            <contact>
              <ode/>
            </contact>
            <bounce/>
            <friction>
              <torsional>
                <ode/>
              </torsional>
              <ode/>
            </friction>
          </surface>
        </collision>
        <visual name='front_right_leg'>
          <pose frame=''>0.68 -0.38 0.5 0 -0 0</pose>
          <geometry>
            <cylinder>
              <radius>0.02</radius>
              <length>1</length>
            </cylinder>
          </geometry>
          <material>
            <script>
              <uri>file://media/materials/scripts/gazebo.material</uri>
              <name>Gazebo/Grey</name>
            </script>
          </material>
        </visual>
        <collision name='back_right_leg'>
          <pose frame=''>-0.68 -0.38 0.5 0 -0 0</pose>
          <geometry>
            <cylinder>
              <radius>0.02</radius>
              <length>1</length>
            </cylinder>
          </geometry>
          <max_contacts>10</max_contacts>
          <surface>
            <contact>
              <ode/>
            </contact>
            <bounce/>
            <friction>
              <torsional>
                <ode/>
              </torsional>
              <ode/>
            </friction>
          </surface>
        </collision>
        <visual name='back_right_leg'>
          <pose frame=''>-0.68 -0.38 0.5 0 -0 0</pose>
          <geometry>
            <cylinder>
              <radius>0.02</radius>
              <length>1</length>
            </cylinder>
          </geometry>
          <material>
            <script>
              <uri>file://media/materials/scripts/gazebo.material</uri>
              <name>Gazebo/Grey</name>
            </script>
          </material>
        </visual>
        <collision name='back_left_leg'>
          <pose frame=''>-0.68 0.38 0.5 0 -0 0</pose>
          <geometry>
            <cylinder>
              <radius>0.02</radius>
              <length>1</length>
            </cylinder>
          </geometry>
          <max_contacts>10</max_contacts>
          <surface>
            <contact>
              <ode/>
            </contact>
            <bounce/>
            <friction>
              <torsional>
                <ode/>
              </torsional>
              <ode/>
            </friction>
          </surface>
        </collision>
        <visual name='back_left_leg'>
          <pose frame=''>-0.68 0.38 0.5 0 -0 0</pose>
          <geometry>
            <cylinder>
              <radius>0.02</radius>
              <length>1</length>
            </cylinder>
          </geometry>
          <material>
            <script>
              <uri>file://media/materials/scripts/gazebo.material</uri>
              <name>Gazebo/Grey</name>
            </script>
          </material>
        </visual>
        <self_collide>0</self_collide>
        <kinematic>0</kinematic>
      </link>
      <pose frame=''>7.05747 -2.66676 0 0 0 -3.13587</pose>
    </model>
    <model name='table_clone_1'>
      <static>1</static>
      <link name='link'>
        <collision name='surface'>
          <pose frame=''>0 0 1 0 -0 0</pose>
          <geometry>
            <box>
              <size>1.5 0.8 0.03</size>
            </box>
          </geometry>
          <surface>
            <friction>
              <ode>
                <mu>0.6</mu>
                <mu2>0.6</mu2>
              </ode>
              <torsional>
                <ode/>
              </torsional>
            </friction>
            <contact>
              <ode/>
            </contact>
            <bounce/>
          </surface>
          <max_contacts>10</max_contacts>
        </collision>
        <visual name='visual1'>
          <pose frame=''>0 0 1 0 -0 0</pose>
          <geometry>
            <box>
              <size>1.5 0.8 0.03</size>
            </box>
          </geometry>
          <material>
            <script>
              <uri>file://media/materials/scripts/gazebo.material</uri>
              <name>Gazebo/Wood</name>
            </script>
          </material>
        </visual>
        <collision name='front_left_leg'>
          <pose frame=''>0.68 0.38 0.5 0 -0 0</pose>
          <geometry>
            <cylinder>
              <radius>0.02</radius>
              <length>1</length>
            </cylinder>
          </geometry>
          <max_contacts>10</max_contacts>
          <surface>
            <contact>
              <ode/>
            </contact>
            <bounce/>
            <friction>
              <torsional>
                <ode/>
              </torsional>
              <ode/>
            </friction>
          </surface>
        </collision>
        <visual name='front_left_leg'>
          <pose frame=''>0.68 0.38 0.5 0 -0 0</pose>
          <geometry>
            <cylinder>
              <radius>0.02</radius>
              <length>1</length>
            </cylinder>
          </geometry>
          <material>
            <script>
              <uri>file://media/materials/scripts/gazebo.material</uri>
              <name>Gazebo/Grey</name>
            </script>
          </material>
        </visual>
        <collision name='front_right_leg'>
          <pose frame=''>0.68 -0.38 0.5 0 -0 0</pose>
          <geometry>
            <cylinder>
              <radius>0.02</radius>
              <length>1</length>
            </cylinder>
          </geometry>
          <max_contacts>10</max_contacts>
          <surface>
            <contact>
              <ode/>
            </contact>
            <bounce/>
            <friction>
              <torsional>
                <ode/>
              </torsional>
              <ode/>
            </friction>
          </surface>
        </collision>
        <visual name='front_right_leg'>
          <pose frame=''>0.68 -0.38 0.5 0 -0 0</pose>
          <geometry>
            <cylinder>
              <radius>0.02</radius>
              <length>1</length>
            </cylinder>
          </geometry>
          <material>
            <script>
              <uri>file://media/materials/scripts/gazebo.material</uri>
              <name>Gazebo/Grey</name>
            </script>
          </material>
        </visual>
        <collision name='back_right_leg'>
          <pose frame=''>-0.68 -0.38 0.5 0 -0 0</pose>
          <geometry>
            <cylinder>
              <radius>0.02</radius>
              <length>1</length>
            </cylinder>
          </geometry>
          <max_contacts>10</max_contacts>
          <surface>
            <contact>
              <ode/>
            </contact>
            <bounce/>
            <friction>
              <torsional>
                <ode/>
              </torsional>
              <ode/>
            </friction>
          </surface>
        </collision>
        <visual name='back_right_leg'>
          <pose frame=''>-0.68 -0.38 0.5 0 -0 0</pose>
          <geometry>
            <cylinder>
              <radius>0.02</radius>
              <length>1</length>
            </cylinder>
          </geometry>
          <material>
            <script>
              <uri>file://media/materials/scripts/gazebo.material</uri>
              <name>Gazebo/Grey</name>
            </script>
          </material>
        </visual>
        <collision name='back_left_leg'>
          <pose frame=''>-0.68 0.38 0.5 0 -0 0</pose>
          <geometry>
            <cylinder>
              <radius>0.02</radius>
              <length>1</length>
            </cylinder>
          </geometry>
          <max_contacts>10</max_contacts>
          <surface>
            <contact>
              <ode/>
            </contact>
            <bounce/>
            <friction>
              <torsional>
                <ode/>
              </torsional>
              <ode/>
            </friction>
          </surface>
        </collision>
        <visual name='back_left_leg'>
          <pose frame=''>-0.68 0.38 0.5 0 -0 0</pose>
          <geometry>
            <cylinder>
              <radius>0.02</radius>
              <length>1</length>
            </cylinder>
          </geometry>
          <material>
            <script>
              <uri>file://media/materials/scripts/gazebo.material</uri>
              <name>Gazebo/Grey</name>
            </script>
          </material>
        </visual>
        <self_collide>0</self_collide>
        <kinematic>0</kinematic>
      </link>
      <pose frame=''>3.28341 -2.66037 0 0 0 -1.58073</pose>
    </model>
    <model name='table_clone_2'>
      <static>1</static>
      <link name='link'>
        <collision name='surface'>
          <pose frame=''>0 0 1 0 -0 0</pose>
          <geometry>
            <box>
              <size>1.5 0.8 0.03</size>
            </box>
          </geometry>
          <surface>
            <friction>
              <ode>
                <mu>0.6</mu>
                <mu2>0.6</mu2>
              </ode>
              <torsional>
                <ode/>
              </torsional>
            </friction>
            <contact>
              <ode/>
            </contact>
            <bounce/>
          </surface>
          <max_contacts>10</max_contacts>
        </collision>
        <visual name='visual1'>
          <pose frame=''>0 0 1 0 -0 0</pose>
          <geometry>
            <box>
              <size>1.5 0.8 0.03</size>
            </box>
          </geometry>
          <material>
            <script>
              <uri>file://media/materials/scripts/gazebo.material</uri>
              <name>Gazebo/Wood</name>
            </script>
          </material>
        </visual>
        <collision name='front_left_leg'>
          <pose frame=''>0.68 0.38 0.5 0 -0 0</pose>
          <geometry>
            <cylinder>
              <radius>0.02</radius>
              <length>1</length>
            </cylinder>
          </geometry>
          <max_contacts>10</max_contacts>
          <surface>
            <contact>
              <ode/>
            </contact>
            <bounce/>
            <friction>
              <torsional>
                <ode/>
              </torsional>
              <ode/>
            </friction>
          </surface>
        </collision>
        <visual name='front_left_leg'>
          <pose frame=''>0.68 0.38 0.5 0 -0 0</pose>
          <geometry>
            <cylinder>
              <radius>0.02</radius>
              <length>1</length>
            </cylinder>
          </geometry>
          <material>
            <script>
              <uri>file://media/materials/scripts/gazebo.material</uri>
              <name>Gazebo/Grey</name>
            </script>
          </material>
        </visual>
        <collision name='front_right_leg'>
          <pose frame=''>0.68 -0.38 0.5 0 -0 0</pose>
          <geometry>
            <cylinder>
              <radius>0.02</radius>
              <length>1</length>
            </cylinder>
          </geometry>
          <max_contacts>10</max_contacts>
          <surface>
            <contact>
              <ode/>
            </contact>
            <bounce/>
            <friction>
              <torsional>
                <ode/>
              </torsional>
              <ode/>
            </friction>
          </surface>
        </collision>
        <visual name='front_right_leg'>
          <pose frame=''>0.68 -0.38 0.5 0 -0 0</pose>
          <geometry>
            <cylinder>
              <radius>0.02</radius>
              <length>1</length>
            </cylinder>
          </geometry>
          <material>
            <script>
              <uri>file://media/materials/scripts/gazebo.material</uri>
              <name>Gazebo/Grey</name>
            </script>
          </material>
        </visual>
        <collision name='back_right_leg'>
          <pose frame=''>-0.68 -0.38 0.5 0 -0 0</pose>
          <geometry>
            <cylinder>
              <radius>0.02</radius>
              <length>1</length>
            </cylinder>
          </geometry>
          <max_contacts>10</max_contacts>
          <surface>
            <contact>
              <ode/>
            </contact>
            <bounce/>
            <friction>
              <torsional>
                <ode/>
              </torsional>
              <ode/>
            </friction>
          </surface>
        </collision>
        <visual name='back_right_leg'>
          <pose frame=''>-0.68 -0.38 0.5 0 -0 0</pose>
          <geometry>
            <cylinder>
              <radius>0.02</radius>
              <length>1</length>
            </cylinder>
          </geometry>
          <material>
            <script>
              <uri>file://media/materials/scripts/gazebo.material</uri>
              <name>Gazebo/Grey</name>
            </script>
          </material>
        </visual>
        <collision name='back_left_leg'>
          <pose frame=''>-0.68 0.38 0.5 0 -0 0</pose>
          <geometry>
            <cylinder>
              <radius>0.02</radius>
              <length>1</length>
            </cylinder>
          </geometry>
          <max_contacts>10</max_contacts>
          <surface>
            <contact>
              <ode/>
            </contact>
            <bounce/>
            <friction>
              <torsional>
                <ode/>
              </torsional>
              <ode/>
            </friction>
          </surface>
        </collision>
        <visual name='back_left_leg'>
          <pose frame=''>-0.68 0.38 0.5 0 -0 0</pose>
          <geometry>
            <cylinder>
              <radius>0.02</radius>
              <length>1</length>
            </cylinder>
          </geometry>
          <material>
            <script>
              <uri>file://media/materials/scripts/gazebo.material</uri>
              <name>Gazebo/Grey</name>
            </script>
          </material>
        </visual>
        <self_collide>0</self_collide>
        <kinematic>0</kinematic>
      </link>
      <pose frame=''>2.43494 2.31407 0 0 0 -1.58073</pose>
    </model>
    <model name='bookshelf'>
      <static>1</static>
      <link name='link'>
        <inertial>
          <mass>1</mass>
        </inertial>
        <collision name='back'>
          <pose frame=''>0 0.005 0.6 0 -0 0</pose>
          <geometry>
            <box>
              <size>0.9 0.01 1.2</size>
            </box>
          </geometry>
          <max_contacts>10</max_contacts>
          <surface>
            <contact>
              <ode/>
            </contact>
            <bounce/>
            <friction>
              <torsional>
                <ode/>
              </torsional>
              <ode/>
            </friction>
          </surface>
        </collision>
        <visual name='visual1'>
          <pose frame=''>0 0.005 0.6 0 -0 0</pose>
          <geometry>
            <box>
              <size>0.9 0.01 1.2</size>
            </box>
          </geometry>
          <material>
            <script>
              <uri>file://media/materials/scripts/gazebo.material</uri>
              <name>Gazebo/Wood</name>
            </script>
          </material>
        </visual>
        <collision name='left_side'>
          <pose frame=''>0.45 -0.195 0.6 0 -0 0</pose>
          <geometry>
            <box>
              <size>0.02 0.4 1.2</size>
            </box>
          </geometry>
          <max_contacts>10</max_contacts>
          <surface>
            <contact>
              <ode/>
            </contact>
            <bounce/>
            <friction>
              <torsional>
                <ode/>
              </torsional>
              <ode/>
            </friction>
          </surface>
        </collision>
        <visual name='visual2'>
          <pose frame=''>0.45 -0.195 0.6 0 -0 0</pose>
          <geometry>
            <box>
              <size>0.02 0.4 1.2</size>
            </box>
          </geometry>
          <material>
            <script>
              <uri>file://media/materials/scripts/gazebo.material</uri>
              <name>Gazebo/Wood</name>
            </script>
          </material>
        </visual>
        <collision name='right_side'>
          <pose frame=''>-0.45 -0.195 0.6 0 -0 0</pose>
          <geometry>
            <box>
              <size>0.02 0.4 1.2</size>
            </box>
          </geometry>
          <max_contacts>10</max_contacts>
          <surface>
            <contact>
              <ode/>
            </contact>
            <bounce/>
            <friction>
              <torsional>
                <ode/>
              </torsional>
              <ode/>
            </friction>
          </surface>
        </collision>
        <visual name='visual3'>
          <pose frame=''>-0.45 -0.195 0.6 0 -0 0</pose>
          <geometry>
            <box>
              <size>0.02 0.4 1.2</size>
            </box>
          </geometry>
          <material>
            <script>
              <uri>file://media/materials/scripts/gazebo.material</uri>
              <name>Gazebo/Wood</name>
            </script>
          </material>
        </visual>
        <collision name='bottom'>
          <pose frame=''>0 -0.195 0.03 0 -0 0</pose>
          <geometry>
            <box>
              <size>0.88 0.4 0.06</size>
            </box>
          </geometry>
          <max_contacts>10</max_contacts>
          <surface>
            <contact>
              <ode/>
            </contact>
            <bounce/>
            <friction>
              <torsional>
                <ode/>
              </torsional>
              <ode/>
            </friction>
          </surface>
        </collision>
        <visual name='visual4'>
          <pose frame=''>0 -0.195 0.03 0 -0 0</pose>
          <geometry>
            <box>
              <size>0.88 0.4 0.06</size>
            </box>
          </geometry>
          <material>
            <script>
              <uri>file://media/materials/scripts/gazebo.material</uri>
              <name>Gazebo/Wood</name>
            </script>
          </material>
        </visual>
        <collision name='top'>
          <pose frame=''>0 -0.195 1.19 0 -0 0</pose>
          <geometry>
            <box>
              <size>0.88 0.4 0.02</size>
            </box>
          </geometry>
          <max_contacts>10</max_contacts>
          <surface>
            <contact>
              <ode/>
            </contact>
            <bounce/>
            <friction>
              <torsional>
                <ode/>
              </torsional>
              <ode/>
            </friction>
          </surface>
        </collision>
        <visual name='visual5'>
          <pose frame=''>0 -0.195 1.19 0 -0 0</pose>
          <geometry>
            <box>
              <size>0.88 0.4 0.02</size>
            </box>
          </geometry>
          <material>
            <script>
              <uri>file://media/materials/scripts/gazebo.material</uri>
              <name>Gazebo/Wood</name>
            </script>
          </material>
        </visual>
        <collision name='low_shelf'>
          <pose frame=''>0 -0.195 0.43 0 -0 0</pose>
          <geometry>
            <box>
              <size>0.88 0.4 0.02</size>
            </box>
          </geometry>
          <max_contacts>10</max_contacts>
          <surface>
            <contact>
              <ode/>
            </contact>
            <bounce/>
            <friction>
              <torsional>
                <ode/>
              </torsional>
              <ode/>
            </friction>
          </surface>
        </collision>
        <visual name='visual6'>
          <pose frame=''>0 -0.195 0.43 0 -0 0</pose>
          <geometry>
            <box>
              <size>0.88 0.4 0.02</size>
            </box>
          </geometry>
          <material>
            <script>
              <uri>file://media/materials/scripts/gazebo.material</uri>
              <name>Gazebo/Wood</name>
            </script>
          </material>
        </visual>
        <collision name='high_shelf'>
          <pose frame=''>0 -0.195 0.8 0 -0 0</pose>
          <geometry>
            <box>
              <size>0.88 0.4 0.02</size>
            </box>
          </geometry>
          <max_contacts>10</max_contacts>
          <surface>
            <contact>
              <ode/>
            </contact>
            <bounce/>
            <friction>
              <torsional>
                <ode/>
              </torsional>
              <ode/>
            </friction>
          </surface>
        </collision>
        <visual name='visual7'>
          <pose frame=''>0 -0.195 0.8 0 -0 0</pose>
          <geometry>
            <box>
              <size>0.88 0.4 0.02</size>
            </box>
          </geometry>
          <material>
            <script>
              <uri>file://media/materials/scripts/gazebo.material</uri>
              <name>Gazebo/Wood</name>
            </script>
          </material>
        </visual>
        <self_collide>0</self_collide>
        <kinematic>0</kinematic>
      </link>
      <pose frame=''>2.09409 -1.27469 0 0 -0 0</pose>
    </model>
    <state world_name='default'>
      <sim_time>932 168000000</sim_time>
      <real_time>314 745322048</real_time>
      <wall_time>1499413946 402231755</wall_time>
      <iterations>254538</iterations>
      <model name='bender_model'>
        <pose frame=''>-0.000109 1e-05 0.06872 -1e-06 3e-05 -1e-05</pose>
        <scale>1 1 1</scale>
        <link name='bender/base_link'>
          <pose frame=''>-0.000109 1e-05 0.06872 -1e-06 3e-05 -1e-05</pose>
          <velocity>2e-06 1e-06 9.6e-05 -1e-05 2.7e-05 -0</velocity>
          <acceleration>-0.002767 -0.005138 0.000424 0.009367 -0.00497 -0.000582</acceleration>
          <wrench>-0.074975 -0.139246 0.01149 0 -0 0</wrench>
        </link>
        <link name='bender/face_link'>
          <pose frame=''>-0.036105 0.026811 1.45052 -5e-06 0.884641 -0.000759</pose>
          <velocity>4.7e-05 1.6e-05 9.6e-05 -1.9e-05 -0.001575 -0.000106</velocity>
          <acceleration>0.003196 -0.001013 -0.042448 0.03013 0.396998 0.086416</acceleration>
          <wrench>0.001061 -0.000336 -0.014087 0 -0 0</wrench>
        </link>
        <link name='bender/front_left_wheel'>
          <pose frame=''>0.117873 0.157509 0.099717 -1e-06 7.2e-05 -1e-05</pose>
          <velocity>3e-06 1e-06 9.1e-05 -1.1e-05 2.7e-05 0</velocity>
          <acceleration>-0.000493 -0.00105 0.002637 0.010497 -0.004934 -5.9e-05</acceleration>
          <wrench>-0.024655 -0.052484 0.131872 0 -0 0</wrench>
        </link>
        <link name='bender/front_right_wheel'>
          <pose frame=''>0.11787 -0.157491 0.099717 -1e-06 6.7e-05 -1e-05</pose>
          <velocity>3e-06 1e-06 9.4e-05 -1.1e-05 2.8e-05 -0</velocity>
          <acceleration>-0.000527 -0.001069 -0.000883 0.010691 -0.005274 -9.7e-05</acceleration>
          <wrench>-0.02635 -0.053454 -0.044151 0 -0 0</wrench>
        </link>
        <link name='bender/head_link'>
          <pose frame=''>-0.036128 0.000831 1.38262 -2e-06 5.1e-05 -0.000752</pose>
          <velocity>3.9e-05 1.6e-05 9.7e-05 -1.2e-05 0.000104 -9.4e-05</velocity>
          <acceleration>-0.007998 -0.016179 9.7e-05 0.00949 -0.021615 0.125597</acceleration>
          <wrench>-0.001438 -0.002909 1.7e-05 0 -0 0</wrench>
        </link>
        <link name='bender/l_elbow_pitch_link'>
          <pose frame=''>-0.01266 0.29349 0.848304 0.005195 -0.076771 -0.003223</pose>
          <velocity>6.6e-05 -0.001143 -0.00016 0.004013 1.6e-05 -0.002196</velocity>
          <acceleration>0.004193 0.379461 -0.097193 -2.18004 -0.072513 -2.29971</acceleration>
          <wrench>0.000604 0.054635 -0.013994 0 -0 0</wrench>
        </link>
        <link name='bender/l_elbow_yaw_link'>
          <pose frame=''>-0.022301 0.271447 0.795398 0.005022 -0.076783 -0.001069</pose>
          <velocity>1.8e-05 -0.000831 -0.000246 0.002608 3.8e-05 -0.002563</velocity>
          <acceleration>0.033507 0.199781 -0.110828 -1.59468 0.62898 3.08272</acceleration>
          <wrench>0.005612 0.033463 -0.018564 0 -0 0</wrench>
        </link>
        <link name='bender/l_ext_finger_link'>
          <pose frame=''>0.000519 0.291513 0.412743 0.523317 0.018603 -0.00059</pose>
          <velocity>3.9e-05 0.000185 -0.000223 0.003324 0.000154 -0.002423</velocity>
          <acceleration>-0.021921 -0.117196 -0.137357 1.22889 -0.792615 -2.95514</acceleration>
          <wrench>-0.003507 -0.018751 -0.021977 0 -0 0</wrench>
        </link>
        <link name='bender/l_int_finger_link'>
          <pose frame=''>-0.027001 0.255129 0.413072 0.493027 -0.018599 3.141</pose>
          <velocity>-5.6e-05 0.00023 -0.000313 0.00273 0.000256 -0.002626</velocity>
          <acceleration>-0.023252 -0.084864 -0.079736 1.57157 -0.474205 -1.04482</acceleration>
          <wrench>-0.00372 -0.013578 -0.012758 0 -0 0</wrench>
        </link>
        <link name='bender/l_shoulder_pitch_link'>
          <pose frame=''>-0.009131 0.23543 1.22432 -0.000134 -0.006382 -7e-06</pose>
          <velocity>2.9e-05 -3e-05 7.6e-05 -0.008826 3.9e-05 3e-05</velocity>
          <acceleration>-0.015221 0.015002 -0.027802 0.43341 0.465549 2.80621</acceleration>
          <wrench>-0.002611 0.002573 -0.004769 0 -0 0</wrench>
        </link>
        <link name='bender/l_shoulder_roll_link'>
          <pose frame=''>-0.032958 0.269327 1.19416 0.005122 -0.006399 0</pose>
          <velocity>3.2e-05 -0.000348 -0.000101 -0.002593 -6.6e-05 0.000547</velocity>
          <acceleration>-0.010112 0.200211 -0.093568 -2.28483 1.3895 -0.65591</acceleration>
          <wrench>-0.001628 0.032242 -0.015068 0 -0 0</wrench>
        </link>
        <link name='bender/l_shoulder_yaw_link'>
          <pose frame=''>0.001832 0.270023 1.05828 0.005151 -0.006382 -0.002857</pose>
          <velocity>3.5e-05 -0.000791 -0.000108 -0.001391 -7.8e-05 -0.001887</velocity>
          <acceleration>-0.008635 0.383579 -0.109426 0.835763 0.850726 3.13708</acceleration>
          <wrench>-0.001495 0.066405 -0.018944 0 -0 0</wrench>
        </link>
        <link name='bender/l_wrist_pitch_link'>
          <pose frame=''>-0.017251 0.290275 0.492482 0.005012 0.018602 -0.00059</pose>
          <velocity>4.7e-05 -5.1e-05 -0.000216 0.003459 0.000115 -0.002535</velocity>
          <acceleration>0.029843 0.01286 -0.10502 2.92487 1.40199 2.13254</acceleration>
          <wrench>0.005434 0.002341 -0.019121 0 -0 0</wrench>
        </link>
        <link name='bender/r_elbow_pitch_link'>
          <pose frame=''>-0.017307 -0.238381 0.848776 0.020171 -0.041836 0.000753</pose>
          <velocity>-6e-05 4.8e-05 0.000183 -9.8e-05 0.00643 0.000109</velocity>
          <acceleration>0.135424 0.00988 0.078245 2.61634 -0.743762 2.05621</acceleration>
          <wrench>0.019498 0.001423 0.011266 0 -0 0</wrench>
        </link>
        <link name='bender/r_elbow_yaw_link'>
          <pose frame=''>-0.028689 -0.259683 0.795911 0.020325 -0.041888 -0.003625</pose>
          <velocity>-0.000405 5e-05 0.000132 -7.1e-05 -0.000829 -0.000304</velocity>
          <acceleration>0.064001 0.011735 0.114366 -1.01001 0.692839 0.849818</acceleration>
          <wrench>0.01072 0.001966 0.019156 0 -0 0</wrench>
        </link>
        <link name='bender/r_ext_finger_link'>
          <pose frame=''>-0.046604 -0.270112 0.413754 0.481088 -0.051815 3.13986</pose>
          <velocity>-8.6e-05 3.1e-05 0.000105 0.000259 -0.000708 -0.000484</velocity>
          <acceleration>-0.075589 0.006341 0.118062 2.59653 1.46635 -1.12365</acceleration>
          <wrench>-0.012094 0.001015 0.01889 0 -0 0</wrench>
        </link>
        <link name='bender/r_int_finger_link'>
          <pose frame=''>-0.019041 -0.233766 0.413068 0.532553 0.05183 -0.001748</pose>
          <velocity>-5.9e-05 -1.2e-05 0.000125 -0.000192 -0.000272 -0.001067</velocity>
          <acceleration>-0.032896 -0.019222 0.103646 0.0259 -0.359745 2.67749</acceleration>
          <wrench>-0.005263 -0.003076 0.016583 0 -0 0</wrench>
        </link>
        <link name='bender/r_shoulder_pitch_link'>
          <pose frame=''>-0.009133 -0.233767 1.22433 -3.2e-05 0.005861 -9e-06</pose>
          <velocity>0.000109 4.4e-05 0.000139 -0.000326 0.006695 -5.6e-05</velocity>
          <acceleration>0.006589 -0.022221 -0.013984 0.043288 0.495599 -0.225912</acceleration>
          <wrench>0.00113 -0.003811 -0.002398 0 -0 0</wrench>
        </link>
        <link name='bender/r_shoulder_roll_link'>
          <pose frame=''>-0.033325 -0.267667 1.19446 0.02016 0.005746 -3.2e-05</pose>
          <velocity>5.9e-05 2.7e-05 0.000218 -2e-06 0.002443 5.9e-05</velocity>
          <acceleration>0.056195 -0.010561 0.067354 -1.19486 1.04585 -0.905232</acceleration>
          <wrench>0.00905 -0.001701 0.010847 0 -0 0</wrench>
        </link>
        <link name='bender/r_shoulder_yaw_link'>
          <pose frame=''>-0.000185 -0.264924 1.05819 0.020165 0.005679 0.00171</pose>
          <velocity>-0.00016 4.1e-05 0.000104 3.9e-05 0.001686 0.00015</velocity>
          <acceleration>0.125045 0.015553 0.06317 -2.10013 1.35328 -1.64654</acceleration>
          <wrench>0.021648 0.002692 0.010936 0 -0 0</wrench>
        </link>
        <link name='bender/r_wrist_pitch_link'>
          <pose frame=''>-0.034157 -0.236204 0.493326 0.020329 0.051841 -0.001729</pose>
          <velocity>-5.3e-05 3.2e-05 0.000109 -8.5e-05 0.00075 -0.00044</velocity>
          <acceleration>-0.017611 -0.004606 0.117414 1.86456 1.07715 1.6665</acceleration>
          <wrench>-0.003206 -0.000839 0.021377 0 -0 0</wrench>
        </link>
        <link name='bender/rear_left_wheel'>
          <pose frame=''>-0.132127 0.157511 0.099724 -1e-06 6.7e-05 -1e-05</pose>
          <velocity>3e-06 1e-06 9.8e-05 -1.1e-05 2.7e-05 0</velocity>
          <acceleration>-0.00047 -0.001094 0.001249 0.010938 -0.004707 -0.000106</acceleration>
          <wrench>-0.023509 -0.05469 0.062434 0 -0 0</wrench>
        </link>
        <link name='bender/rear_right_wheel'>
          <pose frame=''>-0.13213 -0.157489 0.099725 -1e-06 6.6e-05 -1e-05</pose>
          <velocity>3e-06 1e-06 0.000101 -1.2e-05 2.8e-05 0</velocity>
          <acceleration>-0.000499 -0.001154 -0.002213 0.011541 -0.004999 -0.000113</acceleration>
          <wrench>-0.02497 -0.057709 -0.110646 0 -0 0</wrench>
        </link>
      </model>
      <model name='bookshelf'>
        <pose frame=''>1.21889 1.19547 -0 0 0 -1.58933</pose>
        <scale>1 1 1</scale>
        <link name='link'>
          <pose frame=''>1.21889 1.19547 -0 0 0 -1.58933</pose>
          <velocity>0 0 0 0 -0 0</velocity>
          <acceleration>0 0 0 0 -0 0</acceleration>
          <wrench>0 0 0 0 -0 0</wrench>
        </link>
      </model>
      <model name='ground_plane'>
        <pose frame=''>0 0 0 0 -0 0</pose>
        <scale>1 1 1</scale>
        <link name='link'>
          <pose frame=''>0 0 0 0 -0 0</pose>
          <velocity>0 0 0 0 -0 0</velocity>
          <acceleration>0 0 0 0 -0 0</acceleration>
          <wrench>0 0 0 0 -0 0</wrench>
        </link>
      </model>
      <model name='table'>
        <pose frame=''>-1.33827 0.322435 0 0 0 -1.58073</pose>
        <scale>1 1 1</scale>
        <link name='link'>
          <pose frame=''>-1.33827 0.322435 0 0 0 -1.58073</pose>
          <velocity>0 0 0 0 -0 0</velocity>
          <acceleration>0 0 0 0 -0 0</acceleration>
          <wrench>0 0 0 0 -0 0</wrench>
        </link>
      </model>
      <model name='table_clone'>
        <pose frame=''>-1.32325 1.64119 0 0 0 -1.58073</pose>
        <scale>1 1 1</scale>
        <link name='link'>
          <pose frame=''>-1.32325 1.64119 0 0 0 -1.58073</pose>
          <velocity>0 0 0 0 -0 0</velocity>
          <acceleration>0 0 0 0 -0 0</acceleration>
          <wrench>0 0 0 0 -0 0</wrench>
        </link>
      </model>
      <model name='table_clone_0'>
        <pose frame=''>1.20801 -0.040679 -0.518577 0 0 -3.13587</pose>
        <scale>1 1 1</scale>
        <link name='link'>
          <pose frame=''>1.20801 -0.040679 -0.518577 0 0 -3.13587</pose>
          <velocity>0 0 0 0 -0 0</velocity>
          <acceleration>0 0 0 0 -0 0</acceleration>
          <wrench>0 0 0 0 -0 0</wrench>
        </link>
      </model>
      <model name='table_clone_0_clone'>
        <pose frame=''>5.85461 1.30553 0 0 -0 1.57373</pose>
        <scale>1 1 1</scale>
        <link name='link'>
          <pose frame=''>5.85461 1.30553 0 0 -0 1.57373</pose>
          <velocity>0 0 0 0 -0 0</velocity>
          <acceleration>0 0 0 0 -0 0</acceleration>
          <wrench>0 0 0 0 -0 0</wrench>
        </link>
      </model>
      <model name='table_clone_0_clone_0'>
        <pose frame=''>5.76753 -2.54254 0 0 0 -3.13587</pose>
        <scale>1 1 1</scale>
        <link name='link'>
          <pose frame=''>5.76753 -2.54254 0 0 0 -3.13587</pose>
          <velocity>0 0 0 0 -0 0</velocity>
          <acceleration>0 0 0 0 -0 0</acceleration>
          <wrench>0 0 0 0 -0 0</wrench>
        </link>
      </model>
      <model name='table_clone_0_clone_0_clone'>
        <pose frame=''>7.20338 -2.51858 0 0 0 -3.13587</pose>
        <scale>1 1 1</scale>
        <link name='link'>
          <pose frame=''>7.20338 -2.51858 0 0 0 -3.13587</pose>
          <velocity>0 0 0 0 -0 0</velocity>
          <acceleration>0 0 0 0 -0 0</acceleration>
          <wrench>0 0 0 0 -0 0</wrench>
        </link>
      </model>
      <model name='table_clone_1'>
        <pose frame=''>3.28341 -2.66037 0 0 0 -1.58073</pose>
        <scale>1 1 1</scale>
        <link name='link'>
          <pose frame=''>3.28341 -2.66037 0 0 0 -1.58073</pose>
          <velocity>0 0 0 0 -0 0</velocity>
          <acceleration>0 0 0 0 -0 0</acceleration>
          <wrench>0 0 0 0 -0 0</wrench>
        </link>
      </model>
      <model name='table_clone_2'>
        <pose frame=''>2.43494 2.31407 0 0 0 -1.58073</pose>
        <scale>1 1 1</scale>
        <link name='link'>
          <pose frame=''>2.43494 2.31407 0 0 0 -1.58073</pose>
          <velocity>0 0 0 0 -0 0</velocity>
          <acceleration>0 0 0 0 -0 0</acceleration>
          <wrench>0 0 0 0 -0 0</wrench>
        </link>
      </model>
      <light name='sun'>
        <pose frame=''>0 0 10 0 -0 0</pose>
      </light>
    </state>
    <gui fullscreen='0'>
      <camera name='user_camera'>
        <pose frame=''>-3.20667 4.45281 7.73401 0 0.809797 -1.15699</pose>
        <view_controller>orbit</view_controller>
        <projection_type>perspective</projection_type>
      </camera>
    </gui>
    <model name='bender_model'>
      <link name='bender/base_link'>
        <pose frame=''>0 0 0 0 -0 0</pose>
        <inertial>
          <pose frame=''>0.007251 0.000236 0.470984 0 -0 0</pose>
          <mass>27.0994</mass>
          <inertia>
            <ixx>4.83643</ixx>
            <ixy>-0.00016498</ixy>
            <ixz>0.015279</ixz>
            <iyy>4.92345</iyy>
            <iyz>0.000346575</iyz>
            <izz>0.718139</izz>
          </inertia>
        </inertial>
        <collision name='bender/base_link_fixed_joint_lump__bender/sensors/laser_front_link_collision'>
          <pose frame=''>0.22 0 0.22 0 -0 0</pose>
          <geometry>
            <box>
              <size>0.05 0.05 0.08</size>
            </box>
          </geometry>
          <surface>
            <contact>
              <ode/>
            </contact>
            <friction>
              <ode/>
              <torsional>
                <ode/>
              </torsional>
            </friction>
            <bounce/>
          </surface>
          <max_contacts>10</max_contacts>
        </collision>
        <collision name='bender/base_link_fixed_joint_lump__bender/sensors/laser_rear_link_collision_1'>
          <pose frame=''>-0.22 0 0.09 -3.14159 -0 3.14159</pose>
          <geometry>
            <box>
              <size>0.05 0.05 0.08</size>
            </box>
          </geometry>
          <surface>
            <contact>
              <ode/>
            </contact>
            <friction>
              <ode/>
              <torsional>
                <ode/>
              </torsional>
            </friction>
            <bounce/>
          </surface>
          <max_contacts>10</max_contacts>
        </collision>
        <collision name='bender/base_link_fixed_joint_lump__bender/mobile_base_link_collision_2'>
          <pose frame=''>0 0 0.075 0 -0 0</pose>
          <geometry>
            <box>
              <size>0.4 0.3 0.15</size>
            </box>
          </geometry>
          <max_contacts>10</max_contacts>
          <surface>
            <contact>
              <ode/>
            </contact>
            <bounce/>
            <friction>
              <torsional>
                <ode/>
              </torsional>
              <ode/>
            </friction>
          </surface>
        </collision>
        <collision name='bender/base_link_fixed_joint_lump__bender/mobile_base_link_collision_3'>
          <pose frame=''>0 0 0.17 0 -0 0</pose>
          <geometry>
            <box>
              <size>0.54 0.38 0.05</size>
            </box>
          </geometry>
          <max_contacts>10</max_contacts>
          <surface>
            <contact>
              <ode/>
            </contact>
            <bounce/>
            <friction>
              <torsional>
                <ode/>
              </torsional>
              <ode/>
            </friction>
          </surface>
        </collision>
        <collision name='bender/base_link_fixed_joint_lump__bender/lower_torso_base_collision_4'>
          <pose frame=''>-0.004058 0.000819 0.52 0 -0 0</pose>
          <geometry>
            <box>
              <size>0.25 0.2 0.25</size>
            </box>
          </geometry>
          <max_contacts>10</max_contacts>
          <surface>
            <contact>
              <ode/>
            </contact>
            <bounce/>
            <friction>
              <torsional>
                <ode/>
              </torsional>
              <ode/>
            </friction>
          </surface>
        </collision>
        <collision name='bender/base_link_fixed_joint_lump__bender/lower_torso_base_collision_5'>
          <pose frame=''>-0.004058 0.000819 0.295 0 -0 0</pose>
          <geometry>
            <box>
              <size>0.25 0.4 0.2</size>
            </box>
          </geometry>
          <max_contacts>10</max_contacts>
          <surface>
            <contact>
              <ode/>
            </contact>
            <bounce/>
            <friction>
              <torsional>
                <ode/>
              </torsional>
              <ode/>
            </friction>
          </surface>
        </collision>
        <collision name='bender/base_link_fixed_joint_lump__bender/psu_base_collision_6'>
          <pose frame=''>0.170942 0.000819 0.525 0 -0 0</pose>
          <geometry>
            <box>
              <size>0.12 0.2 0.27</size>
            </box>
          </geometry>
          <surface>
            <contact>
              <ode/>
            </contact>
            <friction>
              <ode>
                <mu>0.2</mu>
                <mu2>0.2</mu2>
              </ode>
              <torsional>
                <ode/>
              </torsional>
            </friction>
            <bounce/>
          </surface>
          <max_contacts>10</max_contacts>
        </collision>
        <collision name='bender/base_link_fixed_joint_lump__bender/upper_torso_base_collision_7'>
          <pose frame=''>-0.004058 0.000819 0.678 0 -0 0</pose>
          <geometry>
            <box>
              <size>0.25 0.2 0.3</size>
            </box>
          </geometry>
          <max_contacts>10</max_contacts>
          <surface>
            <contact>
              <ode/>
            </contact>
            <bounce/>
            <friction>
              <torsional>
                <ode/>
              </torsional>
              <ode/>
            </friction>
          </surface>
        </collision>
        <collision name='bender/base_link_fixed_joint_lump__bender/upper_torso_base_collision_8'>
          <pose frame=''>-0.004058 0.000819 1.048 0 -0 0</pose>
          <geometry>
            <box>
              <size>0.25 0.3 0.44</size>
            </box>
          </geometry>
          <max_contacts>10</max_contacts>
          <surface>
            <contact>
              <ode/>
            </contact>
            <bounce/>
            <friction>
              <torsional>
                <ode/>
              </torsional>
              <ode/>
            </friction>
          </surface>
        </collision>
        <collision name='bender/base_link_fixed_joint_lump__bender/upper_torso_base_collision_9'>
          <pose frame=''>-0.004058 -0.179181 1.148 0 -0 0</pose>
          <geometry>
            <box>
              <size>0.2 0.08 0.2</size>
            </box>
          </geometry>
          <max_contacts>10</max_contacts>
          <surface>
            <contact>
              <ode/>
            </contact>
            <bounce/>
            <friction>
              <torsional>
                <ode/>
              </torsional>
              <ode/>
            </friction>
          </surface>
        </collision>
        <collision name='bender/base_link_fixed_joint_lump__bender/upper_torso_base_collision_10'>
          <pose frame=''>-0.004058 0.180819 1.148 0 -0 0</pose>
          <geometry>
            <box>
              <size>0.2 0.08 0.2</size>
            </box>
          </geometry>
          <max_contacts>10</max_contacts>
          <surface>
            <contact>
              <ode/>
            </contact>
            <bounce/>
            <friction>
              <torsional>
                <ode/>
              </torsional>
              <ode/>
            </friction>
          </surface>
        </collision>
        <collision name='bender/base_link_fixed_joint_lump__bender/l_arm_base_link_collision_11'>
          <pose frame=''>-0.009058 0.200819 1.138 0 -0 0</pose>
          <geometry>
            <box>
              <size>0.07 0.06 0.17</size>
            </box>
          </geometry>
          <max_contacts>10</max_contacts>
          <surface>
            <contact>
              <ode/>
            </contact>
            <bounce/>
            <friction>
              <torsional>
                <ode/>
              </torsional>
              <ode/>
            </friction>
          </surface>
        </collision>
        <collision name='bender/base_link_fixed_joint_lump__bender/neck_link_collision_12'>
          <pose frame=''>-0.039058 0.000819 1.281 0 -0 0</pose>
          <geometry>
            <box>
              <size>0.08 0.1 0.08</size>
            </box>
          </geometry>
          <max_contacts>10</max_contacts>
          <surface>
            <contact>
              <ode/>
            </contact>
            <bounce/>
            <friction>
              <torsional>
                <ode/>
              </torsional>
              <ode/>
            </friction>
          </surface>
        </collision>
        <collision name='bender/base_link_fixed_joint_lump__bender/r_arm_base_link_collision_13'>
          <pose frame=''>-0.009058 -0.199181 1.138 0 -0 0</pose>
          <geometry>
            <box>
              <size>0.07 0.06 0.17</size>
            </box>
          </geometry>
          <max_contacts>10</max_contacts>
          <surface>
            <contact>
              <ode/>
            </contact>
            <bounce/>
            <friction>
              <torsional>
                <ode/>
              </torsional>
              <ode/>
            </friction>
          </surface>
        </collision>
        <visual name='bender/base_link_fixed_joint_lump__bender/sensors/laser_front_link_visual'>
          <pose frame=''>0.22 0 0.22 0 -0 0</pose>
          <geometry>
            <mesh>
              <scale>1 1 1</scale>
              <uri>/home/giovanni/uchile_ws/ros/bender/base_ws/src/bender_core/bender_description/meshes/sensors/hokuyo.dae</uri>
            </mesh>
          </geometry>
          <material>
            <script>
              <uri>__default__</uri>
              <name>__default__</name>
            </script>
          </material>
        </visual>
        <visual name='bender/base_link_fixed_joint_lump__bender/sensors/laser_rear_link_visual_1'>
          <pose frame=''>-0.22 0 0.09 -3.14159 -0 3.14159</pose>
          <geometry>
            <mesh>
              <scale>1 1 1</scale>
              <uri>/home/giovanni/uchile_ws/ros/bender/base_ws/src/bender_core/bender_description/meshes/sensors/hokuyo.dae</uri>
            </mesh>
          </geometry>
          <material>
            <script>
              <uri>__default__</uri>
              <name>__default__</name>
            </script>
          </material>
        </visual>
        <visual name='bender/base_link_fixed_joint_lump__bender/mobile_base_link_visual_2'>
          <pose frame=''>0 0 0 0 -0 0</pose>
          <geometry>
            <mesh>
              <scale>1 1 1</scale>
              <uri>/home/giovanni/uchile_ws/ros/bender/base_ws/src/bender_core/bender_description/meshes/visual/base.dae</uri>
            </mesh>
          </geometry>
        </visual>
        <visual name='bender/base_link_fixed_joint_lump__bender/lower_torso_base_visual_3'>
          <pose frame=''>-0.004058 0.000819 0.195 -1.5708 0 0</pose>
          <geometry>
            <mesh>
              <scale>1 1 1</scale>
              <uri>/home/giovanni/uchile_ws/ros/bender/base_ws/src/bender_core/bender_description/meshes/visual/lower_torso.dae</uri>
            </mesh>
          </geometry>
        </visual>
        <visual name='bender/base_link_fixed_joint_lump__bender/psu_base_visual_4'>
          <pose frame=''>0.170942 0.000819 0.525 0 -0 0</pose>
          <geometry>
            <box>
              <size>0.12 0.2 0.27</size>
            </box>
          </geometry>
          <material>
            <script>
              <name>Gazebo/Grey</name>
              <uri>file://media/materials/scripts/gazebo.material</uri>
            </script>
          </material>
        </visual>
        <visual name='bender/base_link_fixed_joint_lump__bender/upper_torso_base_visual_5'>
          <pose frame=''>-0.004058 0.000819 0.528 -1.5708 0 0</pose>
          <geometry>
            <mesh>
              <scale>1 1 1</scale>
              <uri>/home/giovanni/uchile_ws/ros/bender/base_ws/src/bender_core/bender_description/meshes/visual/upper_torso.dae</uri>
            </mesh>
          </geometry>
        </visual>
        <visual name='bender/base_link_fixed_joint_lump__bender/l_arm_base_link_visual_6'>
          <pose frame=''>-0.009058 0.230819 1.138 -1.5708 0 0</pose>
          <geometry>
            <mesh>
              <scale>1 1 1</scale>
              <uri>/home/giovanni/uchile_ws/ros/bender/base_ws/src/bender_core/bender_description/meshes/visual/shoulder_base_link.dae</uri>
            </mesh>
          </geometry>
        </visual>
        <visual name='bender/base_link_fixed_joint_lump__bender/neck_link_visual_7'>
          <pose frame=''>-0.009058 0.000819 1.261 -1.5708 0 0</pose>
          <geometry>
            <mesh>
              <scale>1 1 1</scale>
              <uri>/home/giovanni/uchile_ws/ros/bender/base_ws/src/bender_core/bender_description/meshes/visual/neck.dae</uri>
            </mesh>
          </geometry>
        </visual>
        <visual name='bender/base_link_fixed_joint_lump__bender/r_arm_base_link_visual_8'>
          <pose frame=''>-0.009058 -0.229181 1.138 -1.5708 -0 -3.14159</pose>
          <geometry>
            <mesh>
              <scale>1 1 1</scale>
              <uri>/home/giovanni/uchile_ws/ros/bender/base_ws/src/bender_core/bender_description/meshes/visual/shoulder_base_link.dae</uri>
            </mesh>
          </geometry>
        </visual>
        <velocity_decay/>
        <sensor name='laser_front' type='ray'>
          <visualize>0</visualize>
          <update_rate>40</update_rate>
          <ray>
            <scan>
              <horizontal>
                <samples>1080</samples>
                <resolution>1</resolution>
                <min_angle>-2.01</min_angle>
                <max_angle>2.01</max_angle>
              </horizontal>
              <vertical>
                <samples>1</samples>
                <min_angle>0</min_angle>
                <max_angle>0</max_angle>
              </vertical>
            </scan>
            <range>
              <min>0.1</min>
              <max>30</max>
              <resolution>0.01</resolution>
            </range>
            <noise>
              <type>gaussian</type>
              <mean>0</mean>
              <stddev>0.01</stddev>
            </noise>
          </ray>
          <plugin name='gazebo_ros_laser_front_hokuyo_controller' filename='libgazebo_ros_laser.so'>
            <topicName>bender/sensors/laser_front/scan</topicName>
            <frameName>bender/sensors/laser_front_link</frameName>
            <robotNamespace>/</robotNamespace>
          </plugin>
          <pose frame=''>0.22 0 0.22 0 -0 0</pose>
        </sensor>
        <velocity_decay/>
        <sensor name='laser_rear' type='ray'>
          <visualize>0</visualize>
          <update_rate>10</update_rate>
          <ray>
            <scan>
              <horizontal>
                <samples>445</samples>
                <resolution>1</resolution>
                <min_angle>-1.4</min_angle>
                <max_angle>1.4</max_angle>
              </horizontal>
              <vertical>
                <samples>1</samples>
                <min_angle>0</min_angle>
                <max_angle>0</max_angle>
              </vertical>
            </scan>
            <range>
              <min>0.1</min>
              <max>4</max>
              <resolution>0.01</resolution>
            </range>
            <noise>
              <type>gaussian</type>
              <mean>0</mean>
              <stddev>0.01</stddev>
            </noise>
          </ray>
          <plugin name='gazebo_ros_laser_rear_hokuyo_controller' filename='libgazebo_ros_laser.so'>
            <topicName>bender/sensors/laser_rear/scan</topicName>
            <frameName>bender/sensors/laser_rear_link</frameName>
            <robotNamespace>/</robotNamespace>
          </plugin>
          <pose frame=''>-0.22 0 0.09 -3.14159 -0 3.14159</pose>
        </sensor>
        <gravity>1</gravity>
        <velocity_decay/>
        <self_collide>0</self_collide>
        <kinematic>0</kinematic>
      </link>
      <link name='bender/front_left_wheel'>
        <pose frame=''>0.11798 0.1575 0.031 0 -0 0</pose>
        <inertial>
          <pose frame=''>0 0.025 0 1.5708 -0 0</pose>
          <mass>50</mass>
          <inertia>
            <ixx>0.135417</ixx>
            <ixy>0</ixy>
            <ixz>0</ixz>
            <iyy>0.135417</iyy>
            <iyz>0</iyz>
            <izz>0.25</izz>
          </inertia>
        </inertial>
        <collision name='bender/front_left_wheel_collision'>
          <pose frame=''>0 0.025 0 -1.5708 0 0</pose>
          <geometry>
            <cylinder>
              <length>0.05</length>
              <radius>0.1</radius>
            </cylinder>
          </geometry>
          <surface>
            <contact>
              <ode>
                <kp>1e+06</kp>
                <kd>100</kd>
                <max_vel>1</max_vel>
                <min_depth>0</min_depth>
              </ode>
            </contact>
            <friction>
              <ode>
                <mu>0.8</mu>
                <mu2>0.8</mu2>
                <fdir1>1 0 0</fdir1>
              </ode>
              <torsional>
                <ode/>
              </torsional>
            </friction>
            <bounce/>
          </surface>
          <max_contacts>10</max_contacts>
        </collision>
        <visual name='bender/front_left_wheel_visual'>
          <pose frame=''>0 0 0 -3.14159 -0 0</pose>
          <geometry>
            <mesh>
              <scale>1 1 1</scale>
              <uri>/home/giovanni/uchile_ws/ros/bender/base_ws/src/bender_core/bender_description/meshes/visual/wheel.dae</uri>
            </mesh>
          </geometry>
          <material>
            <script>
              <uri>__default__</uri>
              <name>__default__</name>
            </script>
          </material>
        </visual>
        <gravity>1</gravity>
        <velocity_decay/>
        <self_collide>0</self_collide>
        <kinematic>0</kinematic>
      </link>
      <joint name='front_left_wheel_joint' type='revolute'>
        <child>bender/front_left_wheel</child>
        <parent>bender/base_link</parent>
        <axis>
          <xyz>0 1 0</xyz>
          <limit>
            <lower>-1e+16</lower>
            <upper>1e+16</upper>
          </limit>
          <dynamics>
            <spring_reference>0</spring_reference>
            <spring_stiffness>0</spring_stiffness>
          </dynamics>
          <use_parent_model_frame>1</use_parent_model_frame>
        </axis>
      </joint>
      <link name='bender/front_right_wheel'>
        <pose frame=''>0.11798 -0.1575 0.031 0 -0 0</pose>
        <inertial>
          <pose frame=''>0 -0.025 0 1.5708 -0 0</pose>
          <mass>50</mass>
          <inertia>
            <ixx>0.135417</ixx>
            <ixy>0</ixy>
            <ixz>0</ixz>
            <iyy>0.135417</iyy>
            <iyz>0</iyz>
            <izz>0.25</izz>
          </inertia>
        </inertial>
        <collision name='bender/front_right_wheel_collision'>
          <pose frame=''>0 -0.025 0 -1.5708 0 0</pose>
          <geometry>
            <cylinder>
              <length>0.05</length>
              <radius>0.1</radius>
            </cylinder>
          </geometry>
          <surface>
            <contact>
              <ode>
                <kp>1e+06</kp>
                <kd>100</kd>
                <max_vel>1</max_vel>
                <min_depth>0</min_depth>
              </ode>
            </contact>
            <friction>
              <ode>
                <mu>0.8</mu>
                <mu2>0.8</mu2>
                <fdir1>1 0 0</fdir1>
              </ode>
              <torsional>
                <ode/>
              </torsional>
            </friction>
            <bounce/>
          </surface>
          <max_contacts>10</max_contacts>
        </collision>
        <visual name='bender/front_right_wheel_visual'>
          <pose frame=''>0 0 0 0 -0 0</pose>
          <geometry>
            <mesh>
              <scale>1 1 1</scale>
              <uri>/home/giovanni/uchile_ws/ros/bender/base_ws/src/bender_core/bender_description/meshes/visual/wheel.dae</uri>
            </mesh>
          </geometry>
          <material>
            <script>
              <uri>__default__</uri>
              <name>__default__</name>
            </script>
          </material>
        </visual>
        <gravity>1</gravity>
        <velocity_decay/>
        <self_collide>0</self_collide>
        <kinematic>0</kinematic>
      </link>
      <joint name='front_right_wheel_joint' type='revolute'>
        <child>bender/front_right_wheel</child>
        <parent>bender/base_link</parent>
        <axis>
          <xyz>0 1 0</xyz>
          <limit>
            <lower>-1e+16</lower>
            <upper>1e+16</upper>
          </limit>
          <dynamics>
            <spring_reference>0</spring_reference>
            <spring_stiffness>0</spring_stiffness>
          </dynamics>
          <use_parent_model_frame>1</use_parent_model_frame>
        </axis>
      </joint>
      <link name='bender/rear_left_wheel'>
        <pose frame=''>-0.13202 0.1575 0.031 0 -0 0</pose>
        <inertial>
          <pose frame=''>0 0.025 0 1.5708 -0 0</pose>
          <mass>50</mass>
          <inertia>
            <ixx>0.135417</ixx>
            <ixy>0</ixy>
            <ixz>0</ixz>
            <iyy>0.135417</iyy>
            <iyz>0</iyz>
            <izz>0.25</izz>
          </inertia>
        </inertial>
        <collision name='bender/rear_left_wheel_collision'>
          <pose frame=''>0 0.025 0 -1.5708 0 0</pose>
          <geometry>
            <cylinder>
              <length>0.05</length>
              <radius>0.1</radius>
            </cylinder>
          </geometry>
          <surface>
            <contact>
              <ode>
                <kp>1e+06</kp>
                <kd>100</kd>
                <max_vel>1</max_vel>
                <min_depth>0</min_depth>
              </ode>
            </contact>
            <friction>
              <ode>
                <mu>0.8</mu>
                <mu2>0.8</mu2>
                <fdir1>1 0 0</fdir1>
              </ode>
              <torsional>
                <ode/>
              </torsional>
            </friction>
            <bounce/>
          </surface>
          <max_contacts>10</max_contacts>
        </collision>
        <visual name='bender/rear_left_wheel_visual'>
          <pose frame=''>0 0 0 -3.14159 -0 0</pose>
          <geometry>
            <mesh>
              <scale>1 1 1</scale>
              <uri>/home/giovanni/uchile_ws/ros/bender/base_ws/src/bender_core/bender_description/meshes/visual/wheel.dae</uri>
            </mesh>
          </geometry>
          <material>
            <script>
              <uri>__default__</uri>
              <name>__default__</name>
            </script>
          </material>
        </visual>
        <gravity>1</gravity>
        <velocity_decay/>
        <self_collide>0</self_collide>
        <kinematic>0</kinematic>
      </link>
      <joint name='rear_left_wheel_joint' type='revolute'>
        <child>bender/rear_left_wheel</child>
        <parent>bender/base_link</parent>
        <axis>
          <xyz>0 1 0</xyz>
          <limit>
            <lower>-1e+16</lower>
            <upper>1e+16</upper>
          </limit>
          <dynamics>
            <spring_reference>0</spring_reference>
            <spring_stiffness>0</spring_stiffness>
          </dynamics>
          <use_parent_model_frame>1</use_parent_model_frame>
        </axis>
      </joint>
      <link name='bender/rear_right_wheel'>
        <pose frame=''>-0.13202 -0.1575 0.031 0 -0 0</pose>
        <inertial>
          <pose frame=''>0 -0.025 0 1.5708 -0 0</pose>
          <mass>50</mass>
          <inertia>
            <ixx>0.135417</ixx>
            <ixy>0</ixy>
            <ixz>0</ixz>
            <iyy>0.135417</iyy>
            <iyz>0</iyz>
            <izz>0.25</izz>
          </inertia>
        </inertial>
        <collision name='bender/rear_right_wheel_collision'>
          <pose frame=''>0 -0.025 0 -1.5708 0 0</pose>
          <geometry>
            <cylinder>
              <length>0.05</length>
              <radius>0.1</radius>
            </cylinder>
          </geometry>
          <surface>
            <contact>
              <ode>
                <kp>1e+06</kp>
                <kd>100</kd>
                <max_vel>1</max_vel>
                <min_depth>0</min_depth>
              </ode>
            </contact>
            <friction>
              <ode>
                <mu>0.8</mu>
                <mu2>0.8</mu2>
                <fdir1>1 0 0</fdir1>
              </ode>
              <torsional>
                <ode/>
              </torsional>
            </friction>
            <bounce/>
          </surface>
          <max_contacts>10</max_contacts>
        </collision>
        <visual name='bender/rear_right_wheel_visual'>
          <pose frame=''>0 0 0 0 -0 0</pose>
          <geometry>
            <mesh>
              <scale>1 1 1</scale>
              <uri>/home/giovanni/uchile_ws/ros/bender/base_ws/src/bender_core/bender_description/meshes/visual/wheel.dae</uri>
            </mesh>
          </geometry>
          <material>
            <script>
              <uri>__default__</uri>
              <name>__default__</name>
            </script>
          </material>
        </visual>
        <gravity>1</gravity>
        <velocity_decay/>
        <self_collide>0</self_collide>
        <kinematic>0</kinematic>
      </link>
      <joint name='rear_right_wheel_joint' type='revolute'>
        <child>bender/rear_right_wheel</child>
        <parent>bender/base_link</parent>
        <axis>
          <xyz>0 1 0</xyz>
          <limit>
            <lower>-1e+16</lower>
            <upper>1e+16</upper>
          </limit>
          <dynamics>
            <spring_reference>0</spring_reference>
            <spring_stiffness>0</spring_stiffness>
          </dynamics>
          <use_parent_model_frame>1</use_parent_model_frame>
        </axis>
      </joint>
      <link name='bender/l_shoulder_pitch_link'>
        <pose frame=''>-0.009058 0.235419 1.1556 0 -0 0</pose>
        <inertial>
          <pose frame=''>0.000233 0.019812 -0.013482 0 -0 0</pose>
          <mass>0.17152</mass>
          <inertia>
            <ixx>0.00010991</ixx>
            <ixy>-5.6413e-07</ixy>
            <ixz>1.0935e-06</ixz>
            <iyy>0.00010993</iyy>
            <iyz>1.8807e-06</iyz>
            <izz>8.8167e-05</izz>
          </inertia>
        </inertial>
        <collision name='bender/l_shoulder_pitch_link_collision'>
          <pose frame=''>0 0.025 -0.01 0 -0 0</pose>
          <geometry>
            <box>
              <size>0.05 0.05 0.07</size>
            </box>
          </geometry>
          <max_contacts>10</max_contacts>
          <surface>
            <contact>
              <ode/>
            </contact>
            <bounce/>
            <friction>
              <torsional>
                <ode/>
              </torsional>
              <ode/>
            </friction>
          </surface>
        </collision>
        <visual name='bender/l_shoulder_pitch_link_visual'>
          <pose frame=''>0 0 0 -1.5708 0 0</pose>
          <geometry>
            <mesh>
              <scale>1 1 1</scale>
              <uri>/home/giovanni/uchile_ws/ros/bender/base_ws/src/bender_core/bender_description/meshes/visual/shoulder_pitch.dae</uri>
            </mesh>
          </geometry>
        </visual>
        <self_collide>0</self_collide>
        <kinematic>0</kinematic>
      </link>
      <joint name='l_shoulder_pitch_joint' type='revolute'>
        <child>bender/l_shoulder_pitch_link</child>
        <parent>bender/base_link</parent>
        <axis>
          <xyz>0 -1 0</xyz>
          <limit>
            <lower>-1.53397</lower>
            <upper>1.94815</upper>
            <effort>10.85</effort>
            <velocity>5.23599</velocity>
          </limit>
          <dynamics>
            <damping>0.15</damping>
            <friction>0.3</friction>
            <spring_reference>0</spring_reference>
            <spring_stiffness>0</spring_stiffness>
          </dynamics>
          <use_parent_model_frame>1</use_parent_model_frame>
        </axis>
      </joint>
      <link name='bender/l_shoulder_roll_link'>
        <pose frame=''>-0.033078 0.269319 1.1256 0 -0 0</pose>
        <inertial>
          <pose frame=''>0.046779 -9e-06 -0.11466 0 -0 0</pose>
          <mass>0.16104</mass>
          <inertia>
            <ixx>0.00050901</ixx>
            <ixy>6.2439e-09</ixy>
            <ixz>0.00010534</ixz>
            <iyy>0.00055051</iyy>
            <iyz>-6.7534e-08</iyz>
            <izz>0.00011428</izz>
          </inertia>
        </inertial>
        <collision name='bender/l_shoulder_roll_link_collision'>
          <pose frame=''>0.04 0 -0.075 0 -0.25 0</pose>
          <geometry>
            <box>
              <size>0.05 0.035 0.18</size>
            </box>
          </geometry>
          <max_contacts>10</max_contacts>
          <surface>
            <contact>
              <ode/>
            </contact>
            <bounce/>
            <friction>
              <torsional>
                <ode/>
              </torsional>
              <ode/>
            </friction>
          </surface>
        </collision>
        <visual name='bender/l_shoulder_roll_link_visual'>
          <pose frame=''>0 0 0 -1.5708 0 0</pose>
          <geometry>
            <mesh>
              <scale>1 1 1</scale>
              <uri>/home/giovanni/uchile_ws/ros/bender/base_ws/src/bender_core/bender_description/meshes/visual/shoulder_roll.dae</uri>
            </mesh>
          </geometry>
        </visual>
        <self_collide>0</self_collide>
        <kinematic>0</kinematic>
      </link>
      <joint name='l_shoulder_roll_joint' type='revolute'>
        <child>bender/l_shoulder_roll_link</child>
        <parent>bender/l_shoulder_pitch_link</parent>
        <axis>
          <xyz>1 0 0</xyz>
          <limit>
            <lower>-0.23776</lower>
            <upper>1.51096</upper>
            <effort>10.85</effort>
            <velocity>5.23599</velocity>
          </limit>
          <dynamics>
            <damping>0.15</damping>
            <friction>0.3</friction>
            <spring_reference>0</spring_reference>
            <spring_stiffness>0</spring_stiffness>
          </dynamics>
          <use_parent_model_frame>1</use_parent_model_frame>
        </axis>
      </joint>
      <link name='bender/l_shoulder_yaw_link'>
        <pose frame=''>0.000842 0.269319 0.9895 0 -0 0</pose>
        <inertial>
          <pose frame=''>-0.017828 -0.000166 -0.14148 0 -0 0</pose>
          <mass>0.17312</mass>
          <inertia>
            <ixx>0.0008473</ixx>
            <ixy>7.9313e-08</ixy>
            <ixz>3.4804e-05</ixz>
            <iyy>0.00084882</iyy>
            <iyz>-3.1674e-06</iyz>
            <izz>6.5527e-05</izz>
          </inertia>
        </inertial>
        <collision name='bender/l_shoulder_yaw_link_collision'>
          <pose frame=''>-0.015 0 -0.115 0 -0 0</pose>
          <geometry>
            <box>
              <size>0.05 0.035 0.23</size>
            </box>
          </geometry>
          <max_contacts>10</max_contacts>
          <surface>
            <contact>
              <ode/>
            </contact>
            <bounce/>
            <friction>
              <torsional>
                <ode/>
              </torsional>
              <ode/>
            </friction>
          </surface>
        </collision>
        <visual name='bender/l_shoulder_yaw_link_visual'>
          <pose frame=''>0 0 0 -1.5708 0 0</pose>
          <geometry>
            <mesh>
              <scale>1 1 1</scale>
              <uri>/home/giovanni/uchile_ws/ros/bender/base_ws/src/bender_core/bender_description/meshes/visual/shoulder_yaw.dae</uri>
            </mesh>
          </geometry>
        </visual>
        <self_collide>0</self_collide>
        <kinematic>0</kinematic>
      </link>
      <joint name='l_shoulder_yaw_joint' type='revolute'>
        <child>bender/l_shoulder_yaw_link</child>
        <parent>bender/l_shoulder_roll_link</parent>
        <axis>
          <xyz>0 0 -1</xyz>
          <limit>
            <lower>-1.48284</lower>
            <upper>1.38057</upper>
            <effort>4.44054</effort>
            <velocity>5.23599</velocity>
          </limit>
          <dynamics>
            <damping>0.15</damping>
            <friction>0.3</friction>
            <spring_reference>0</spring_reference>
            <spring_stiffness>0</spring_stiffness>
          </dynamics>
          <use_parent_model_frame>1</use_parent_model_frame>
        </axis>
      </joint>
      <link name='bender/l_elbow_pitch_link'>
        <pose frame=''>-0.015056 0.291664 0.7795 0 -0 0</pose>
        <inertial>
          <pose frame=''>0.006745 -0.022124 -0.059507 0 -0 0</pose>
          <mass>0.14398</mass>
          <inertia>
            <ixx>0.00012531</ixx>
            <ixy>1.5127e-07</ixy>
            <ixz>3.5125e-06</ixz>
            <iyy>0.00011254</iyy>
            <iyz>-1.3346e-06</iyz>
            <izz>8.6928e-05</izz>
          </inertia>
        </inertial>
        <collision name='bender/l_elbow_pitch_link_collision'>
          <pose frame=''>0.015 -0.025 -0.05 0 -0 0</pose>
          <geometry>
            <box>
              <size>0.05 0.07 0.1</size>
            </box>
          </geometry>
          <max_contacts>10</max_contacts>
          <surface>
            <contact>
              <ode/>
            </contact>
            <bounce/>
            <friction>
              <torsional>
                <ode/>
              </torsional>
              <ode/>
            </friction>
          </surface>
        </collision>
        <visual name='bender/l_elbow_pitch_link_visual'>
          <pose frame=''>0 0 0 -1.5708 0 0</pose>
          <geometry>
            <mesh>
              <scale>1 1 1</scale>
              <uri>/home/giovanni/uchile_ws/ros/bender/base_ws/src/bender_core/bender_description/meshes/visual/elbow_pitch.dae</uri>
            </mesh>
          </geometry>
        </visual>
        <self_collide>0</self_collide>
        <kinematic>0</kinematic>
      </link>
      <joint name='l_elbow_pitch_joint' type='revolute'>
        <child>bender/l_elbow_pitch_link</child>
        <parent>bender/l_shoulder_yaw_link</parent>
        <axis>
          <xyz>0 -1 0</xyz>
          <limit>
            <lower>-1.0431</lower>
            <upper>1.90213</upper>
            <effort>10.85</effort>
            <velocity>5.23599</velocity>
          </limit>
          <dynamics>
            <damping>0.15</damping>
            <friction>0.3</friction>
            <spring_reference>0</spring_reference>
            <spring_stiffness>0</spring_stiffness>
          </dynamics>
          <use_parent_model_frame>1</use_parent_model_frame>
        </axis>
      </joint>
      <link name='bender/l_elbow_yaw_link'>
        <pose frame=''>-0.028656 0.269319 0.7276 0 -0 0</pose>
        <inertial>
          <pose frame=''>-0.0196 8.5e-05 -0.17771 0 -0 0</pose>
          <mass>0.1675</mass>
          <inertia>
            <ixx>0.0017359</ixx>
            <ixy>-4.8507e-09</ixy>
            <ixz>3.1814e-05</ixz>
            <iyy>0.0017441</iyy>
            <iyz>2.1946e-07</iyz>
            <izz>5.881e-05</izz>
          </inertia>
        </inertial>
        <collision name='bender/l_elbow_yaw_link_collision'>
          <pose frame=''>-0.015 0 -0.15 0 -0 0</pose>
          <geometry>
            <box>
              <size>0.05 0.035 0.32</size>
            </box>
          </geometry>
          <max_contacts>10</max_contacts>
          <surface>
            <contact>
              <ode/>
            </contact>
            <bounce/>
            <friction>
              <torsional>
                <ode/>
              </torsional>
              <ode/>
            </friction>
          </surface>
        </collision>
        <visual name='bender/l_elbow_yaw_link_visual'>
          <pose frame=''>0 0 0 -1.5708 0 0</pose>
          <geometry>
            <mesh>
              <scale>1 1 1</scale>
              <uri>/home/giovanni/uchile_ws/ros/bender/base_ws/src/bender_core/bender_description/meshes/visual/elbow_yaw.dae</uri>
            </mesh>
          </geometry>
        </visual>
        <self_collide>0</self_collide>
        <kinematic>0</kinematic>
      </link>
      <joint name='l_elbow_yaw_joint' type='revolute'>
        <child>bender/l_elbow_yaw_link</child>
        <parent>bender/l_elbow_pitch_link</parent>
        <axis>
          <xyz>0 0 -1</xyz>
          <limit>
            <lower>-1.20161</lower>
            <upper>1.30387</upper>
            <effort>4.44054</effort>
            <velocity>5.23599</velocity>
          </limit>
          <dynamics>
            <damping>0.15</damping>
            <friction>0.3</friction>
            <spring_reference>0</spring_reference>
            <spring_stiffness>0</spring_stiffness>
          </dynamics>
          <use_parent_model_frame>1</use_parent_model_frame>
        </axis>
      </joint>
      <link name='bender/l_wrist_pitch_link'>
        <pose frame=''>-0.046877 0.286634 0.4251 0 -0 0</pose>
        <inertial>
          <pose frame=''>3.9e-05 -0.017418 -0.05204 0 -0 0</pose>
          <mass>0.18207</mass>
          <inertia>
            <ixx>0.000168472</ixx>
            <ixy>-2.80655e-11</ixy>
            <ixz>-2.03417e-07</ixz>
            <iyy>0.000108722</iyy>
            <iyz>6.41597e-07</iyz>
            <izz>0.000117584</izz>
          </inertia>
        </inertial>
        <collision name='bender/l_wrist_pitch_link_collision'>
          <pose frame=''>0 -0.02 -0.05 0 -0 0</pose>
          <geometry>
            <box>
              <size>0.04 0.08 0.07</size>
            </box>
          </geometry>
          <max_contacts>10</max_contacts>
          <surface>
            <contact>
              <ode/>
            </contact>
            <bounce/>
            <friction>
              <torsional>
                <ode/>
              </torsional>
              <ode/>
            </friction>
          </surface>
        </collision>
        <visual name='bender/l_wrist_pitch_link_visual'>
          <pose frame=''>0 0 0 -1.5708 0 0</pose>
          <geometry>
            <mesh>
              <scale>1 1 1</scale>
              <uri>/home/giovanni/uchile_ws/ros/bender/base_ws/src/bender_core/bender_description/meshes/visual/wrist_pitch.dae</uri>
            </mesh>
          </geometry>
        </visual>
        <self_collide>0</self_collide>
        <kinematic>0</kinematic>
      </link>
      <joint name='l_wrist_pitch_joint' type='revolute'>
        <child>bender/l_wrist_pitch_link</child>
        <parent>bender/l_elbow_yaw_link</parent>
        <axis>
          <xyz>0 -1 0</xyz>
          <limit>
            <lower>-1.07378</lower>
            <upper>1.22717</upper>
            <effort>3.1</effort>
            <velocity>5.23599</velocity>
          </limit>
          <dynamics>
            <damping>0.15</damping>
            <friction>0.3</friction>
            <spring_reference>0</spring_reference>
            <spring_stiffness>0</spring_stiffness>
          </dynamics>
          <use_parent_model_frame>1</use_parent_model_frame>
        </axis>
      </joint>
      <link name='bender/l_ext_finger_link'>
        <pose frame=''>-0.027627 0.287484 0.3457 0.523599 -0 0</pose>
        <inertial>
          <pose frame=''>-0.018 -0.03 -0.07 -0.523599 0 0</pose>
          <mass>0.16</mass>
          <inertia>
            <ixx>0.000357667</ixx>
            <ixy>0</ixy>
            <ixz>0</ixz>
            <iyy>0.000374667</iyy>
            <iyz>0</iyz>
            <izz>4.96667e-05</izz>
          </inertia>
        </inertial>
        <collision name='bender/l_ext_finger_link_collision'>
          <pose frame=''>0 0 0.011 0 -0 0</pose>
          <geometry>
            <mesh>
              <scale>1 1 1</scale>
              <uri>/home/giovanni/uchile_ws/ros/bender/base_ws/src/bender_core/bender_description/meshes/collision/finger.stl</uri>
            </mesh>
          </geometry>
          <surface>
            <contact>
              <ode>
                <kp>1e+06</kp>
                <kd>1</kd>
                <min_depth>0.005</min_depth>
              </ode>
            </contact>
            <friction>
              <ode>
                <mu>1</mu>
                <mu2>1</mu2>
              </ode>
              <torsional>
                <ode/>
              </torsional>
            </friction>
            <bounce/>
          </surface>
          <max_contacts>10</max_contacts>
        </collision>
        <visual name='bender/l_ext_finger_link_visual'>
          <pose frame=''>0 0 0 0 -0 0</pose>
          <geometry>
            <mesh>
              <scale>1 1 1</scale>
              <uri>/home/giovanni/uchile_ws/ros/bender/base_ws/src/bender_core/bender_description/meshes/visual/one_finger.stl</uri>
            </mesh>
          </geometry>
          <material>
            <script>
              <name>Gazebo/DarkGrey</name>
              <uri>file://media/materials/scripts/gazebo.material</uri>
            </script>
          </material>
        </visual>
        <gravity>1</gravity>
        <velocity_decay/>
        <self_collide>1</self_collide>
        <kinematic>0</kinematic>
      </link>
      <joint name='l_ext_finger_joint' type='revolute'>
        <child>bender/l_ext_finger_link</child>
        <parent>bender/l_wrist_pitch_link</parent>
        <axis>
          <xyz>1 0 0</xyz>
          <limit>
            <lower>-0.02556</lower>
            <upper>0.69029</upper>
            <effort>3.1</effort>
            <velocity>10</velocity>
          </limit>
          <dynamics>
            <damping>0.2</damping>
            <friction>1</friction>
            <spring_reference>0</spring_reference>
            <spring_stiffness>0</spring_stiffness>
          </dynamics>
          <use_parent_model_frame>1</use_parent_model_frame>
        </axis>
      </joint>
      <link name='bender/l_int_finger_link'>
        <pose frame=''>-0.055127 0.251084 0.3457 0.523599 0 -3.14159</pose>
        <inertial>
          <pose frame=''>-0.018 -0.03 -0.07 -0.523599 0 0</pose>
          <mass>0.16</mass>
          <inertia>
            <ixx>0.000357667</ixx>
            <ixy>0</ixy>
            <ixz>0</ixz>
            <iyy>0.000374667</iyy>
            <iyz>0</iyz>
            <izz>4.96667e-05</izz>
          </inertia>
        </inertial>
        <collision name='bender/l_int_finger_link_collision'>
          <pose frame=''>0.005 0 0.011 0 -0 0</pose>
          <geometry>
            <mesh>
              <scale>1 1 1</scale>
              <uri>/home/giovanni/uchile_ws/ros/bender/base_ws/src/bender_core/bender_description/meshes/collision/finger.stl</uri>
            </mesh>
          </geometry>
          <surface>
            <contact>
              <ode>
                <kp>1e+06</kp>
                <kd>1</kd>
                <min_depth>0.005</min_depth>
              </ode>
            </contact>
            <friction>
              <ode>
                <mu>1</mu>
                <mu2>1</mu2>
              </ode>
              <torsional>
                <ode/>
              </torsional>
            </friction>
            <bounce/>
          </surface>
          <max_contacts>10</max_contacts>
        </collision>
        <visual name='bender/l_int_finger_link_visual'>
          <pose frame=''>0.008 0 0 0 -0 0</pose>
          <geometry>
            <mesh>
              <scale>1 1 1</scale>
              <uri>/home/giovanni/uchile_ws/ros/bender/base_ws/src/bender_core/bender_description/meshes/visual/one_finger.stl</uri>
            </mesh>
          </geometry>
          <material>
            <script>
              <name>Gazebo/DarkGrey</name>
              <uri>file://media/materials/scripts/gazebo.material</uri>
            </script>
          </material>
        </visual>
        <gravity>1</gravity>
        <velocity_decay/>
        <self_collide>1</self_collide>
        <kinematic>0</kinematic>
      </link>
      <joint name='l_int_finger_joint' type='revolute'>
        <child>bender/l_int_finger_link</child>
        <parent>bender/l_wrist_pitch_link</parent>
        <axis>
          <xyz>-1 0 0</xyz>
          <limit>
            <lower>-0.02556</lower>
            <upper>0.69029</upper>
            <effort>3.1</effort>
            <velocity>10</velocity>
          </limit>
          <dynamics>
            <damping>0.2</damping>
            <friction>1</friction>
            <spring_reference>0</spring_reference>
            <spring_stiffness>0</spring_stiffness>
          </dynamics>
          <use_parent_model_frame>1</use_parent_model_frame>
        </axis>
      </joint>
      <link name='bender/head_link'>
        <pose frame=''>-0.036058 0.000819 1.3139 0 -0 0</pose>
        <inertial>
          <pose frame=''>-0.012141 -1.8e-05 0.041401 0 -0 0</pose>
          <mass>0.17983</mass>
          <inertia>
            <ixx>0.00015925</ixx>
            <ixy>4.0867e-07</ixy>
            <ixz>-7.9102e-06</ixz>
            <iyy>0.0001892</iyy>
            <iyz>-6.1427e-08</iyz>
            <izz>8.7881e-05</izz>
          </inertia>
        </inertial>
        <collision name='bender/head_link_collision'>
          <pose frame=''>-0.01 0 0.05 0 -0 0</pose>
          <geometry>
            <box>
              <size>0.08 0.06 0.1</size>
            </box>
          </geometry>
          <max_contacts>10</max_contacts>
          <surface>
            <contact>
              <ode/>
            </contact>
            <bounce/>
            <friction>
              <torsional>
                <ode/>
              </torsional>
              <ode/>
            </friction>
          </surface>
        </collision>
        <visual name='bender/head_link_visual'>
          <pose frame=''>0 0 0 -1.5708 0 0</pose>
          <geometry>
            <mesh>
              <scale>1 1 1</scale>
              <uri>/home/giovanni/uchile_ws/ros/bender/base_ws/src/bender_core/bender_description/meshes/visual/head.dae</uri>
            </mesh>
          </geometry>
        </visual>
        <self_collide>0</self_collide>
        <kinematic>0</kinematic>
      </link>
      <joint name='head_yaw_joint' type='revolute'>
        <child>bender/head_link</child>
        <parent>bender/base_link</parent>
        <axis>
          <xyz>0 0 1</xyz>
          <limit>
            <lower>-1.8919</lower>
            <upper>1.8919</upper>
            <effort>4.44054</effort>
            <velocity>1</velocity>
          </limit>
          <dynamics>
            <damping>0.15</damping>
            <friction>0</friction>
            <spring_reference>0</spring_reference>
            <spring_stiffness>0</spring_stiffness>
          </dynamics>
          <use_parent_model_frame>1</use_parent_model_frame>
        </axis>
      </joint>
      <link name='bender/face_link'>
        <pose frame=''>-0.036058 0.026799 1.3818 0 -0 0</pose>
        <inertial>
          <pose frame=''>0.046115 -0.026111 0.10189 0 -0 0</pose>
          <mass>0.33187</mass>
          <inertia>
            <ixx>0.0013461</ixx>
            <ixy>-2.8029e-07</ixy>
            <ixz>-9.224e-05</ixz>
            <iyy>0.00080978</iyy>
            <iyz>-6.6351e-07</iyz>
            <izz>0.00074443</izz>
          </inertia>
        </inertial>
        <collision name='bender/face_link_collision'>
          <pose frame=''>0.05 -0.03 0.08 0 -0 0</pose>
          <geometry>
            <box>
              <size>0.05 0.18 0.18</size>
            </box>
          </geometry>
          <max_contacts>10</max_contacts>
          <surface>
            <contact>
              <ode/>
            </contact>
            <bounce/>
            <friction>
              <torsional>
                <ode/>
              </torsional>
              <ode/>
            </friction>
          </surface>
        </collision>
        <visual name='bender/face_link_visual'>
          <pose frame=''>0 0 0 -1.5708 0 0</pose>
          <geometry>
            <mesh>
              <scale>1 1 1</scale>
              <uri>/home/giovanni/uchile_ws/ros/bender/base_ws/src/bender_core/bender_description/meshes/visual/face.dae</uri>
            </mesh>
          </geometry>
        </visual>
        <gravity>1</gravity>
        <velocity_decay/>
        <sensor name='rgbd_head' type='depth'>
          <always_on>1</always_on>
          <update_rate>5</update_rate>
          <camera name='__default__'>
            <horizontal_fov>0.994838</horizontal_fov>
            <image>
              <format>B8G8R8</format>
              <width>640</width>
              <height>480</height>
            </image>
            <clip>
              <near>0.01</near>
              <far>5</far>
            </clip>
          </camera>
          <plugin name='rgbd_head_controller' filename='libgazebo_ros_openni_kinect.so'>
            <alwaysOn>true</alwaysOn>
            <updateRate>5.0</updateRate>
            <cameraName>rgbd_head</cameraName>
            <imageTopicName>/bender/sensors/rgbd_head/rgb/image_raw</imageTopicName>
            <cameraInfoTopicName>/bender/sensors/rgbd_head/rgb/camera_info</cameraInfoTopicName>
            <depthImageTopicName>/bender/sensors/rgbd_head/depth/image_raw</depthImageTopicName>
            <depthImageCameraInfoTopicName>/bender/sensors/rgbd_head/depth/camera_info</depthImageCameraInfoTopicName>
            <pointCloudTopicName>/bender/sensors/rgbd_head/depth/points</pointCloudTopicName>
            <frameName>bender/sensors/rgbd_head_depth_optical_frame</frameName>
            <baseline>0.1</baseline>
            <distortion_k1>0.0</distortion_k1>
            <distortion_k2>0.0</distortion_k2>
            <distortion_k3>0.0</distortion_k3>
            <distortion_t1>0.0</distortion_t1>
            <distortion_t2>0.0</distortion_t2>
            <pointCloudCutoff>0.35</pointCloudCutoff>
            <pointCloudCutoffMax>2.0</pointCloudCutoffMax>
            <robotNamespace>/</robotNamespace>
          </plugin>
          <pose frame=''>0.05332 0.0208 0.14105 0 0.031904 0</pose>
        </sensor>
        <self_collide>0</self_collide>
        <kinematic>0</kinematic>
      </link>
      <joint name='head_pitch_joint' type='revolute'>
        <child>bender/face_link</child>
        <parent>bender/head_link</parent>
        <axis>
          <xyz>0 1 0</xyz>
          <limit>
            <lower>-0.39372</lower>
            <upper>0.88459</upper>
            <effort>4.44054</effort>
            <velocity>1</velocity>
          </limit>
          <dynamics>
            <damping>0.15</damping>
            <friction>0</friction>
            <spring_reference>0</spring_reference>
            <spring_stiffness>0</spring_stiffness>
          </dynamics>
          <use_parent_model_frame>1</use_parent_model_frame>
        </axis>
      </joint>
      <link name='bender/r_shoulder_pitch_link'>
        <pose frame=''>-0.009058 -0.233781 1.1556 0 -0 0</pose>
        <inertial>
          <pose frame=''>0.000233 0.019812 -0.013482 0 -0 0</pose>
          <mass>0.17152</mass>
          <inertia>
            <ixx>0.00010991</ixx>
            <ixy>-5.6413e-07</ixy>
            <ixz>1.0935e-06</ixz>
            <iyy>0.00010993</iyy>
            <iyz>1.8807e-06</iyz>
            <izz>8.8167e-05</izz>
          </inertia>
        </inertial>
        <collision name='bender/r_shoulder_pitch_link_collision'>
          <pose frame=''>0 -0.025 -0.01 0 -0 0</pose>
          <geometry>
            <box>
              <size>0.05 0.05 0.07</size>
            </box>
          </geometry>
          <max_contacts>10</max_contacts>
          <surface>
            <contact>
              <ode/>
            </contact>
            <bounce/>
            <friction>
              <torsional>
                <ode/>
              </torsional>
              <ode/>
            </friction>
          </surface>
        </collision>
        <visual name='bender/r_shoulder_pitch_link_visual'>
          <pose frame=''>0 0 0 -1.5708 -0 -3.14159</pose>
          <geometry>
            <mesh>
              <scale>1 1 1</scale>
              <uri>/home/giovanni/uchile_ws/ros/bender/base_ws/src/bender_core/bender_description/meshes/visual/shoulder_pitch.dae</uri>
            </mesh>
          </geometry>
        </visual>
        <self_collide>0</self_collide>
        <kinematic>0</kinematic>
      </link>
      <joint name='r_shoulder_pitch_joint' type='revolute'>
        <child>bender/r_shoulder_pitch_link</child>
        <parent>bender/base_link</parent>
        <axis>
          <xyz>0 -1 0</xyz>
          <limit>
            <lower>-1.53397</lower>
            <upper>1.94815</upper>
            <effort>10.85</effort>
            <velocity>5.23599</velocity>
          </limit>
          <dynamics>
            <damping>0.15</damping>
            <friction>0.3</friction>
            <spring_reference>0</spring_reference>
            <spring_stiffness>0</spring_stiffness>
          </dynamics>
          <use_parent_model_frame>1</use_parent_model_frame>
        </axis>
      </joint>
      <link name='bender/r_shoulder_roll_link'>
        <pose frame=''>-0.033078 -0.267681 1.1256 0 -0 0</pose>
        <inertial>
          <pose frame=''>0.046779 -9e-06 -0.11466 0 -0 0</pose>
          <mass>0.16104</mass>
          <inertia>
            <ixx>0.00050901</ixx>
            <ixy>6.2439e-09</ixy>
            <ixz>0.00010534</ixz>
            <iyy>0.00055051</iyy>
            <iyz>-6.7534e-08</iyz>
            <izz>0.00011428</izz>
          </inertia>
        </inertial>
        <collision name='bender/r_shoulder_roll_link_collision'>
          <pose frame=''>0.04 0 -0.075 0 -0.25 0</pose>
          <geometry>
            <box>
              <size>0.05 0.035 0.18</size>
            </box>
          </geometry>
          <max_contacts>10</max_contacts>
          <surface>
            <contact>
              <ode/>
            </contact>
            <bounce/>
            <friction>
              <torsional>
                <ode/>
              </torsional>
              <ode/>
            </friction>
          </surface>
        </collision>
        <visual name='bender/r_shoulder_roll_link_visual'>
          <pose frame=''>0 0 0 -1.5708 0 0</pose>
          <geometry>
            <mesh>
              <scale>1 1 1</scale>
              <uri>/home/giovanni/uchile_ws/ros/bender/base_ws/src/bender_core/bender_description/meshes/visual/shoulder_roll.dae</uri>
            </mesh>
          </geometry>
        </visual>
        <self_collide>0</self_collide>
        <kinematic>0</kinematic>
      </link>
      <joint name='r_shoulder_roll_joint' type='revolute'>
        <child>bender/r_shoulder_roll_link</child>
        <parent>bender/r_shoulder_pitch_link</parent>
        <axis>
          <xyz>-1 0 0</xyz>
          <limit>
            <lower>-0.23776</lower>
            <upper>1.51096</upper>
            <effort>10.85</effort>
            <velocity>5.23599</velocity>
          </limit>
          <dynamics>
            <damping>0.15</damping>
            <friction>0.3</friction>
            <spring_reference>0</spring_reference>
            <spring_stiffness>0</spring_stiffness>
          </dynamics>
          <use_parent_model_frame>1</use_parent_model_frame>
        </axis>
      </joint>
      <link name='bender/r_shoulder_yaw_link'>
        <pose frame=''>0.000842 -0.267681 0.9895 0 -0 0</pose>
        <inertial>
          <pose frame=''>-0.017828 -0.000166 -0.14148 0 -0 0</pose>
          <mass>0.17312</mass>
          <inertia>
            <ixx>0.0008473</ixx>
            <ixy>7.9313e-08</ixy>
            <ixz>3.4804e-05</ixz>
            <iyy>0.00084882</iyy>
            <iyz>-3.1674e-06</iyz>
            <izz>6.5527e-05</izz>
          </inertia>
        </inertial>
        <collision name='bender/r_shoulder_yaw_link_collision'>
          <pose frame=''>-0.015 0 -0.115 0 -0 0</pose>
          <geometry>
            <box>
              <size>0.05 0.035 0.23</size>
            </box>
          </geometry>
          <max_contacts>10</max_contacts>
          <surface>
            <contact>
              <ode/>
            </contact>
            <bounce/>
            <friction>
              <torsional>
                <ode/>
              </torsional>
              <ode/>
            </friction>
          </surface>
        </collision>
        <visual name='bender/r_shoulder_yaw_link_visual'>
          <pose frame=''>0 0 0 -1.5708 0 0</pose>
          <geometry>
            <mesh>
              <scale>1 1 1</scale>
              <uri>/home/giovanni/uchile_ws/ros/bender/base_ws/src/bender_core/bender_description/meshes/visual/shoulder_yaw.dae</uri>
            </mesh>
          </geometry>
        </visual>
        <self_collide>0</self_collide>
        <kinematic>0</kinematic>
      </link>
      <joint name='r_shoulder_yaw_joint' type='revolute'>
        <child>bender/r_shoulder_yaw_link</child>
        <parent>bender/r_shoulder_roll_link</parent>
        <axis>
          <xyz>0 0 1</xyz>
          <limit>
            <lower>-1.48284</lower>
            <upper>1.38057</upper>
            <effort>4.44054</effort>
            <velocity>5.23599</velocity>
          </limit>
          <dynamics>
            <damping>0.15</damping>
            <friction>0.3</friction>
            <spring_reference>0</spring_reference>
            <spring_stiffness>0</spring_stiffness>
          </dynamics>
          <use_parent_model_frame>1</use_parent_model_frame>
        </axis>
      </joint>
      <link name='bender/r_elbow_pitch_link'>
        <pose frame=''>-0.015056 -0.245336 0.7795 0 -0 0</pose>
        <inertial>
          <pose frame=''>0.006745 -0.022124 -0.059507 0 -0 0</pose>
          <mass>0.14398</mass>
          <inertia>
            <ixx>0.00012531</ixx>
            <ixy>1.5127e-07</ixy>
            <ixz>3.5125e-06</ixz>
            <iyy>0.00011254</iyy>
            <iyz>-1.3346e-06</iyz>
            <izz>8.6928e-05</izz>
          </inertia>
        </inertial>
        <collision name='bender/r_elbow_pitch_link_collision'>
          <pose frame=''>0.015 -0.025 -0.05 0 -0 0</pose>
          <geometry>
            <box>
              <size>0.05 0.07 0.1</size>
            </box>
          </geometry>
          <max_contacts>10</max_contacts>
          <surface>
            <contact>
              <ode/>
            </contact>
            <bounce/>
            <friction>
              <torsional>
                <ode/>
              </torsional>
              <ode/>
            </friction>
          </surface>
        </collision>
        <visual name='bender/r_elbow_pitch_link_visual'>
          <pose frame=''>0 0 0 -1.5708 0 0</pose>
          <geometry>
            <mesh>
              <scale>1 1 1</scale>
              <uri>/home/giovanni/uchile_ws/ros/bender/base_ws/src/bender_core/bender_description/meshes/visual/elbow_pitch.dae</uri>
            </mesh>
          </geometry>
        </visual>
        <self_collide>0</self_collide>
        <kinematic>0</kinematic>
      </link>
      <joint name='r_elbow_pitch_joint' type='revolute'>
        <child>bender/r_elbow_pitch_link</child>
        <parent>bender/r_shoulder_yaw_link</parent>
        <axis>
          <xyz>0 -1 0</xyz>
          <limit>
            <lower>-1.0431</lower>
            <upper>1.90213</upper>
            <effort>10.85</effort>
            <velocity>5.23599</velocity>
          </limit>
          <dynamics>
            <damping>0.15</damping>
            <friction>0.3</friction>
            <spring_reference>0</spring_reference>
            <spring_stiffness>0</spring_stiffness>
          </dynamics>
          <use_parent_model_frame>1</use_parent_model_frame>
        </axis>
      </joint>
      <link name='bender/r_elbow_yaw_link'>
        <pose frame=''>-0.028656 -0.267681 0.7276 0 -0 0</pose>
        <inertial>
          <pose frame=''>-0.0196 8.5e-05 -0.17771 0 -0 0</pose>
          <mass>0.1675</mass>
          <inertia>
            <ixx>0.0017359</ixx>
            <ixy>-4.8507e-09</ixy>
            <ixz>3.1814e-05</ixz>
            <iyy>0.0017441</iyy>
            <iyz>2.1946e-07</iyz>
            <izz>5.881e-05</izz>
          </inertia>
        </inertial>
        <collision name='bender/r_elbow_yaw_link_collision'>
          <pose frame=''>-0.015 0 -0.15 0 -0 0</pose>
          <geometry>
            <box>
              <size>0.05 0.035 0.32</size>
            </box>
          </geometry>
          <max_contacts>10</max_contacts>
          <surface>
            <contact>
              <ode/>
            </contact>
            <bounce/>
            <friction>
              <torsional>
                <ode/>
              </torsional>
              <ode/>
            </friction>
          </surface>
        </collision>
        <visual name='bender/r_elbow_yaw_link_visual'>
          <pose frame=''>0 0 0 -1.5708 0 0</pose>
          <geometry>
            <mesh>
              <scale>1 1 1</scale>
              <uri>/home/giovanni/uchile_ws/ros/bender/base_ws/src/bender_core/bender_description/meshes/visual/elbow_yaw.dae</uri>
            </mesh>
          </geometry>
        </visual>
        <self_collide>0</self_collide>
        <kinematic>0</kinematic>
      </link>
      <joint name='r_elbow_yaw_joint' type='revolute'>
        <child>bender/r_elbow_yaw_link</child>
        <parent>bender/r_elbow_pitch_link</parent>
        <axis>
          <xyz>0 0 1</xyz>
          <limit>
            <lower>-1.20161</lower>
            <upper>1.30387</upper>
            <effort>4.44054</effort>
            <velocity>5.23599</velocity>
          </limit>
          <dynamics>
            <damping>0.15</damping>
            <friction>0.3</friction>
            <spring_reference>0</spring_reference>
            <spring_stiffness>0</spring_stiffness>
          </dynamics>
          <use_parent_model_frame>1</use_parent_model_frame>
        </axis>
      </joint>
      <link name='bender/r_wrist_pitch_link'>
        <pose frame=''>-0.046877 -0.250366 0.4251 0 -0 0</pose>
        <inertial>
          <pose frame=''>3.9e-05 -0.017418 -0.05204 0 -0 0</pose>
          <mass>0.18207</mass>
          <inertia>
            <ixx>0.000168472</ixx>
            <ixy>-2.80655e-11</ixy>
            <ixz>-2.03417e-07</ixz>
            <iyy>0.000108722</iyy>
            <iyz>6.41597e-07</iyz>
            <izz>0.000117584</izz>
          </inertia>
        </inertial>
        <collision name='bender/r_wrist_pitch_link_collision'>
          <pose frame=''>0 -0.02 -0.05 0 -0 0</pose>
          <geometry>
            <box>
              <size>0.04 0.08 0.07</size>
            </box>
          </geometry>
          <max_contacts>10</max_contacts>
          <surface>
            <contact>
              <ode/>
            </contact>
            <bounce/>
            <friction>
              <torsional>
                <ode/>
              </torsional>
              <ode/>
            </friction>
          </surface>
        </collision>
        <visual name='bender/r_wrist_pitch_link_visual'>
          <pose frame=''>0 0 0 -1.5708 0 0</pose>
          <geometry>
            <mesh>
              <scale>1 1 1</scale>
              <uri>/home/giovanni/uchile_ws/ros/bender/base_ws/src/bender_core/bender_description/meshes/visual/wrist_pitch.dae</uri>
            </mesh>
          </geometry>
        </visual>
        <self_collide>0</self_collide>
        <kinematic>0</kinematic>
      </link>
      <joint name='r_wrist_pitch_joint' type='revolute'>
        <child>bender/r_wrist_pitch_link</child>
        <parent>bender/r_elbow_yaw_link</parent>
        <axis>
          <xyz>0 -1 0</xyz>
          <limit>
            <lower>-1.07378</lower>
            <upper>1.22717</upper>
            <effort>3.1</effort>
            <velocity>5.23599</velocity>
          </limit>
          <dynamics>
            <damping>0.15</damping>
            <friction>0.3</friction>
            <spring_reference>0</spring_reference>
            <spring_stiffness>0</spring_stiffness>
          </dynamics>
          <use_parent_model_frame>1</use_parent_model_frame>
        </axis>
      </joint>
      <link name='bender/r_ext_finger_link'>
        <pose frame=''>-0.055127 -0.285916 0.3457 0.523599 0 -3.14159</pose>
        <inertial>
          <pose frame=''>-0.018 -0.03 -0.07 -0.523599 0 0</pose>
          <mass>0.16</mass>
          <inertia>
            <ixx>0.000357667</ixx>
            <ixy>0</ixy>
            <ixz>0</ixz>
            <iyy>0.000374667</iyy>
            <iyz>0</iyz>
            <izz>4.96667e-05</izz>
          </inertia>
        </inertial>
        <collision name='bender/r_ext_finger_link_collision'>
          <pose frame=''>0.0355 0 0.011 0 -0 0</pose>
          <geometry>
            <mesh>
              <scale>1 1 1</scale>
              <uri>/home/giovanni/uchile_ws/ros/bender/base_ws/src/bender_core/bender_description/meshes/collision/finger.stl</uri>
            </mesh>
          </geometry>
          <surface>
            <contact>
              <ode>
                <kp>1e+06</kp>
                <kd>1</kd>
                <min_depth>0.005</min_depth>
              </ode>
            </contact>
            <friction>
              <ode>
                <mu>1</mu>
                <mu2>1</mu2>
              </ode>
              <torsional>
                <ode/>
              </torsional>
            </friction>
            <bounce/>
          </surface>
          <max_contacts>10</max_contacts>
        </collision>
        <visual name='bender/r_ext_finger_link_visual'>
          <pose frame=''>0.008 0 0 0 -0 0</pose>
          <geometry>
            <mesh>
              <scale>1 1 1</scale>
              <uri>/home/giovanni/uchile_ws/ros/bender/base_ws/src/bender_core/bender_description/meshes/visual/two_finger.stl</uri>
            </mesh>
          </geometry>
          <material>
            <script>
              <name>Gazebo/DarkGrey</name>
              <uri>file://media/materials/scripts/gazebo.material</uri>
            </script>
          </material>
        </visual>
        <gravity>1</gravity>
        <velocity_decay/>
        <self_collide>1</self_collide>
        <kinematic>0</kinematic>
      </link>
      <joint name='r_ext_finger_joint' type='revolute'>
        <child>bender/r_ext_finger_link</child>
        <parent>bender/r_wrist_pitch_link</parent>
        <axis>
          <xyz>-1 0 0</xyz>
          <limit>
            <lower>-0.02556</lower>
            <upper>0.69029</upper>
            <effort>3.1</effort>
            <velocity>10</velocity>
          </limit>
          <dynamics>
            <damping>0.2</damping>
            <friction>1</friction>
            <spring_reference>0</spring_reference>
            <spring_stiffness>0</spring_stiffness>
          </dynamics>
          <use_parent_model_frame>1</use_parent_model_frame>
        </axis>
      </joint>
      <link name='bender/r_int_finger_link'>
        <pose frame=''>-0.027627 -0.249516 0.3457 0.523599 -0 0</pose>
        <inertial>
          <pose frame=''>-0.018 -0.03 -0.07 -0.523599 0 0</pose>
          <mass>0.16</mass>
          <inertia>
            <ixx>0.000357667</ixx>
            <ixy>0</ixy>
            <ixz>0</ixz>
            <iyy>0.000374667</iyy>
            <iyz>0</iyz>
            <izz>4.96667e-05</izz>
          </inertia>
        </inertial>
        <collision name='bender/r_int_finger_link_collision'>
          <pose frame=''>0.0275 0 0.011 0 -0 0</pose>
          <geometry>
            <mesh>
              <scale>1 1 1</scale>
              <uri>/home/giovanni/uchile_ws/ros/bender/base_ws/src/bender_core/bender_description/meshes/collision/finger.stl</uri>
            </mesh>
          </geometry>
          <surface>
            <contact>
              <ode>
                <kp>1e+06</kp>
                <kd>1</kd>
                <min_depth>0.005</min_depth>
              </ode>
            </contact>
            <friction>
              <ode>
                <mu>1</mu>
                <mu2>1</mu2>
              </ode>
              <torsional>
                <ode/>
              </torsional>
            </friction>
            <bounce/>
          </surface>
          <max_contacts>10</max_contacts>
        </collision>
        <visual name='bender/r_int_finger_link_visual'>
          <pose frame=''>0 0 0 0 -0 0</pose>
          <geometry>
            <mesh>
              <scale>1 1 1</scale>
              <uri>/home/giovanni/uchile_ws/ros/bender/base_ws/src/bender_core/bender_description/meshes/visual/two_finger.stl</uri>
            </mesh>
          </geometry>
          <material>
            <script>
              <name>Gazebo/DarkGrey</name>
              <uri>file://media/materials/scripts/gazebo.material</uri>
            </script>
          </material>
        </visual>
        <gravity>1</gravity>
        <velocity_decay/>
        <self_collide>1</self_collide>
        <kinematic>0</kinematic>
      </link>
      <joint name='r_int_finger_joint' type='revolute'>
        <child>bender/r_int_finger_link</child>
        <parent>bender/r_wrist_pitch_link</parent>
        <axis>
          <xyz>1 0 0</xyz>
          <limit>
            <lower>-0.02556</lower>
            <upper>0.69029</upper>
            <effort>3.1</effort>
            <velocity>10</velocity>
          </limit>
          <dynamics>
            <damping>0.2</damping>
            <friction>1</friction>
            <spring_reference>0</spring_reference>
            <spring_stiffness>0</spring_stiffness>
          </dynamics>
          <use_parent_model_frame>1</use_parent_model_frame>
        </axis>
      </joint>
      <plugin name='skid_steer_drive_controller' filename='libgazebo_ros_skid_steer_drive.so'>
        <robotNamespace>bender/nav</robotNamespace>
        <updateRate>50.0</updateRate>
        <leftFrontJoint>front_left_wheel_joint</leftFrontJoint>
        <rightFrontJoint>front_right_wheel_joint</rightFrontJoint>
        <leftRearJoint>rear_left_wheel_joint</leftRearJoint>
        <rightRearJoint>rear_right_wheel_joint</rightRearJoint>
        <wheelSeparation>0.4</wheelSeparation>
        <wheelDiameter>0.215</wheelDiameter>
        <robotBaseFrame>bender/base_link</robotBaseFrame>
        <torque>400</torque>
        <MaxForce>10.0</MaxForce>
        <commandTopic>base/cmd_vel</commandTopic>
        <odometryTopic>odom</odometryTopic>
        <odometryFrame>bender/odom</odometryFrame>
        <broadcastTF>1</broadcastTF>
      </plugin>
      <static>0</static>
      <plugin name='ros_control' filename='libgazebo_ros_control.so'>
        <robotNamespace>bender/</robotNamespace>
      </plugin>
      <pose frame=''>0 0 0 0 -0 0</pose>
    </model>
  </world>
</sdf>
