<sdf version='1.6'>
  <world name='default'>
    <light name='sun' type='directional'>
      <cast_shadows>1</cast_shadows>
      <pose frame=''>0 0 10 0 -0 0</pose>
      <diffuse>0.8 0.8 0.8 1</diffuse>
      <specular>0.2 0.2 0.2 1</specular>
      <attenuation>
        <range>1000</range>
        <constant>0.9</constant>
        <linear>0.01</linear>
        <quadratic>0.001</quadratic>
      </attenuation>
      <direction>-0.5 0.1 -0.9</direction>
    </light>
    <model name='ground_plane'>
      <static>1</static>
      <link name='link'>
        <collision name='collision'>
          <geometry>
            <plane>
              <normal>0 0 1</normal>
              <size>100 100</size>
            </plane>
          </geometry>
          <surface>
            <friction>
              <ode>
                <mu>100</mu>
                <mu2>50</mu2>
              </ode>
              <torsional>
                <ode/>
              </torsional>
            </friction>
            <contact>
              <ode/>
            </contact>
            <bounce/>
          </surface>
          <max_contacts>10</max_contacts>
        </collision>
        <visual name='visual'>
          <cast_shadows>0</cast_shadows>
          <geometry>
            <plane>
              <normal>0 0 1</normal>
              <size>100 100</size>
            </plane>
          </geometry>
          <material>
            <script>
              <uri>file://media/materials/scripts/gazebo.material</uri>
              <name>Gazebo/Grey</name>
            </script>
          </material>
        </visual>
        <self_collide>0</self_collide>
        <kinematic>0</kinematic>
      </link>
    </model>
    <gravity>0 0 -9.8</gravity>
    <magnetic_field>6e-06 2.3e-05 -4.2e-05</magnetic_field>
    <atmosphere type='adiabatic'/>
    <physics name='default_physics' default='0' type='ode'>
      <max_step_size>0.001</max_step_size>
      <real_time_factor>1</real_time_factor>
      <real_time_update_rate>1000</real_time_update_rate>
    </physics>
    <scene>
      <ambient>0.4 0.4 0.4 1</ambient>
      <background>0.7 0.7 0.7 1</background>
      <shadows>1</shadows>
    </scene>
    <spherical_coordinates>
      <surface_model>EARTH_WGS84</surface_model>
      <latitude_deg>0</latitude_deg>
      <longitude_deg>0</longitude_deg>
      <elevation>0</elevation>
      <heading_deg>0</heading_deg>
    </spherical_coordinates>
    <model name='table_clone_0'>
      <static>1</static>
      <link name='link'>
        <collision name='surface'>
          <pose frame=''>0 0 1 0 -0 0</pose>
          <geometry>
            <box>
              <size>1.5 0.8 0.03</size>
            </box>
          </geometry>
          <surface>
            <friction>
              <ode>
                <mu>0.6</mu>
                <mu2>0.6</mu2>
              </ode>
              <torsional>
                <ode/>
              </torsional>
            </friction>
            <contact>
              <ode/>
            </contact>
            <bounce/>
          </surface>
          <max_contacts>10</max_contacts>
        </collision>
        <visual name='visual1'>
          <pose frame=''>0 0 1 0 -0 0</pose>
          <geometry>
            <box>
              <size>1.5 0.8 0.03</size>
            </box>
          </geometry>
          <material>
            <script>
              <uri>file://media/materials/scripts/gazebo.material</uri>
              <name>Gazebo/Wood</name>
            </script>
          </material>
        </visual>
        <collision name='front_left_leg'>
          <pose frame=''>0.68 0.38 0.5 0 -0 0</pose>
          <geometry>
            <cylinder>
              <radius>0.02</radius>
              <length>1</length>
            </cylinder>
          </geometry>
          <max_contacts>10</max_contacts>
          <surface>
            <contact>
              <ode/>
            </contact>
            <bounce/>
            <friction>
              <torsional>
                <ode/>
              </torsional>
              <ode/>
            </friction>
          </surface>
        </collision>
        <visual name='front_left_leg'>
          <pose frame=''>0.68 0.38 0.5 0 -0 0</pose>
          <geometry>
            <cylinder>
              <radius>0.02</radius>
              <length>1</length>
            </cylinder>
          </geometry>
          <material>
            <script>
              <uri>file://media/materials/scripts/gazebo.material</uri>
              <name>Gazebo/Grey</name>
            </script>
          </material>
        </visual>
        <collision name='front_right_leg'>
          <pose frame=''>0.68 -0.38 0.5 0 -0 0</pose>
          <geometry>
            <cylinder>
              <radius>0.02</radius>
              <length>1</length>
            </cylinder>
          </geometry>
          <max_contacts>10</max_contacts>
          <surface>
            <contact>
              <ode/>
            </contact>
            <bounce/>
            <friction>
              <torsional>
                <ode/>
              </torsional>
              <ode/>
            </friction>
          </surface>
        </collision>
        <visual name='front_right_leg'>
          <pose frame=''>0.68 -0.38 0.5 0 -0 0</pose>
          <geometry>
            <cylinder>
              <radius>0.02</radius>
              <length>1</length>
            </cylinder>
          </geometry>
          <material>
            <script>
              <uri>file://media/materials/scripts/gazebo.material</uri>
              <name>Gazebo/Grey</name>
            </script>
          </material>
        </visual>
        <collision name='back_right_leg'>
          <pose frame=''>-0.68 -0.38 0.5 0 -0 0</pose>
          <geometry>
            <cylinder>
              <radius>0.02</radius>
              <length>1</length>
            </cylinder>
          </geometry>
          <max_contacts>10</max_contacts>
          <surface>
            <contact>
              <ode/>
            </contact>
            <bounce/>
            <friction>
              <torsional>
                <ode/>
              </torsional>
              <ode/>
            </friction>
          </surface>
        </collision>
        <visual name='back_right_leg'>
          <pose frame=''>-0.68 -0.38 0.5 0 -0 0</pose>
          <geometry>
            <cylinder>
              <radius>0.02</radius>
              <length>1</length>
            </cylinder>
          </geometry>
          <material>
            <script>
              <uri>file://media/materials/scripts/gazebo.material</uri>
              <name>Gazebo/Grey</name>
            </script>
          </material>
        </visual>
        <collision name='back_left_leg'>
          <pose frame=''>-0.68 0.38 0.5 0 -0 0</pose>
          <geometry>
            <cylinder>
              <radius>0.02</radius>
              <length>1</length>
            </cylinder>
          </geometry>
          <max_contacts>10</max_contacts>
          <surface>
            <contact>
              <ode/>
            </contact>
            <bounce/>
            <friction>
              <torsional>
                <ode/>
              </torsional>
              <ode/>
            </friction>
          </surface>
        </collision>
        <visual name='back_left_leg'>
          <pose frame=''>-0.68 0.38 0.5 0 -0 0</pose>
          <geometry>
            <cylinder>
              <radius>0.02</radius>
              <length>1</length>
            </cylinder>
          </geometry>
          <material>
            <script>
              <uri>file://media/materials/scripts/gazebo.material</uri>
              <name>Gazebo/Grey</name>
            </script>
          </material>
        </visual>
        <self_collide>0</self_collide>
        <kinematic>0</kinematic>
      </link>
      <pose frame=''>3.23306 0.062335 0 0 0 -1.58073</pose>
    </model>
    <model name='bookshelf'>
      <static>1</static>
      <link name='link'>
        <inertial>
          <mass>1</mass>
        </inertial>
        <collision name='back'>
          <pose frame=''>0 0.005 0.6 0 -0 0</pose>
          <geometry>
            <box>
              <size>0.9 0.01 1.2</size>
            </box>
          </geometry>
          <max_contacts>10</max_contacts>
          <surface>
            <contact>
              <ode/>
            </contact>
            <bounce/>
            <friction>
              <torsional>
                <ode/>
              </torsional>
              <ode/>
            </friction>
          </surface>
        </collision>
        <visual name='visual1'>
          <pose frame=''>0 0.005 0.6 0 -0 0</pose>
          <geometry>
            <box>
              <size>0.9 0.01 1.2</size>
            </box>
          </geometry>
          <material>
            <script>
              <uri>file://media/materials/scripts/gazebo.material</uri>
              <name>Gazebo/Wood</name>
            </script>
          </material>
        </visual>
        <collision name='left_side'>
          <pose frame=''>0.45 -0.195 0.6 0 -0 0</pose>
          <geometry>
            <box>
              <size>0.02 0.4 1.2</size>
            </box>
          </geometry>
          <max_contacts>10</max_contacts>
          <surface>
            <contact>
              <ode/>
            </contact>
            <bounce/>
            <friction>
              <torsional>
                <ode/>
              </torsional>
              <ode/>
            </friction>
          </surface>
        </collision>
        <visual name='visual2'>
          <pose frame=''>0.45 -0.195 0.6 0 -0 0</pose>
          <geometry>
            <box>
              <size>0.02 0.4 1.2</size>
            </box>
          </geometry>
          <material>
            <script>
              <uri>file://media/materials/scripts/gazebo.material</uri>
              <name>Gazebo/Wood</name>
            </script>
          </material>
        </visual>
        <collision name='right_side'>
          <pose frame=''>-0.45 -0.195 0.6 0 -0 0</pose>
          <geometry>
            <box>
              <size>0.02 0.4 1.2</size>
            </box>
          </geometry>
          <max_contacts>10</max_contacts>
          <surface>
            <contact>
              <ode/>
            </contact>
            <bounce/>
            <friction>
              <torsional>
                <ode/>
              </torsional>
              <ode/>
            </friction>
          </surface>
        </collision>
        <visual name='visual3'>
          <pose frame=''>-0.45 -0.195 0.6 0 -0 0</pose>
          <geometry>
            <box>
              <size>0.02 0.4 1.2</size>
            </box>
          </geometry>
          <material>
            <script>
              <uri>file://media/materials/scripts/gazebo.material</uri>
              <name>Gazebo/Wood</name>
            </script>
          </material>
        </visual>
        <collision name='bottom'>
          <pose frame=''>0 -0.195 0.03 0 -0 0</pose>
          <geometry>
            <box>
              <size>0.88 0.4 0.06</size>
            </box>
          </geometry>
          <max_contacts>10</max_contacts>
          <surface>
            <contact>
              <ode/>
            </contact>
            <bounce/>
            <friction>
              <torsional>
                <ode/>
              </torsional>
              <ode/>
            </friction>
          </surface>
        </collision>
        <visual name='visual4'>
          <pose frame=''>0 -0.195 0.03 0 -0 0</pose>
          <geometry>
            <box>
              <size>0.88 0.4 0.06</size>
            </box>
          </geometry>
          <material>
            <script>
              <uri>file://media/materials/scripts/gazebo.material</uri>
              <name>Gazebo/Wood</name>
            </script>
          </material>
        </visual>
        <collision name='top'>
          <pose frame=''>0 -0.195 1.19 0 -0 0</pose>
          <geometry>
            <box>
              <size>0.88 0.4 0.02</size>
            </box>
          </geometry>
          <max_contacts>10</max_contacts>
          <surface>
            <contact>
              <ode/>
            </contact>
            <bounce/>
            <friction>
              <torsional>
                <ode/>
              </torsional>
              <ode/>
            </friction>
          </surface>
        </collision>
        <visual name='visual5'>
          <pose frame=''>0 -0.195 1.19 0 -0 0</pose>
          <geometry>
            <box>
              <size>0.88 0.4 0.02</size>
            </box>
          </geometry>
          <material>
            <script>
              <uri>file://media/materials/scripts/gazebo.material</uri>
              <name>Gazebo/Wood</name>
            </script>
          </material>
        </visual>
        <collision name='low_shelf'>
          <pose frame=''>0 -0.195 0.43 0 -0 0</pose>
          <geometry>
            <box>
              <size>0.88 0.4 0.02</size>
            </box>
          </geometry>
          <max_contacts>10</max_contacts>
          <surface>
            <contact>
              <ode/>
            </contact>
            <bounce/>
            <friction>
              <torsional>
                <ode/>
              </torsional>
              <ode/>
            </friction>
          </surface>
        </collision>
        <visual name='visual6'>
          <pose frame=''>0 -0.195 0.43 0 -0 0</pose>
          <geometry>
            <box>
              <size>0.88 0.4 0.02</size>
            </box>
          </geometry>
          <material>
            <script>
              <uri>file://media/materials/scripts/gazebo.material</uri>
              <name>Gazebo/Wood</name>
            </script>
          </material>
        </visual>
        <collision name='high_shelf'>
          <pose frame=''>0 -0.195 0.8 0 -0 0</pose>
          <geometry>
            <box>
              <size>0.88 0.4 0.02</size>
            </box>
          </geometry>
          <max_contacts>10</max_contacts>
          <surface>
            <contact>
              <ode/>
            </contact>
            <bounce/>
            <friction>
              <torsional>
                <ode/>
              </torsional>
              <ode/>
            </friction>
          </surface>
        </collision>
        <visual name='visual7'>
          <pose frame=''>0 -0.195 0.8 0 -0 0</pose>
          <geometry>
            <box>
              <size>0.88 0.4 0.02</size>
            </box>
          </geometry>
          <material>
            <script>
              <uri>file://media/materials/scripts/gazebo.material</uri>
              <name>Gazebo/Wood</name>
            </script>
          </material>
        </visual>
        <self_collide>0</self_collide>
        <kinematic>0</kinematic>
      </link>
      <pose frame=''>2.09409 -1.27469 0 0 -0 0</pose>
    </model>
    <state world_name='default'>
      <sim_time>94 309000000</sim_time>
      <real_time>142 748550260</real_time>
      <wall_time>1499415198 384147307</wall_time>
      <iterations>94309</iterations>
      <model name='bender_model'>
        <pose frame=''>-8e-05 1e-05 0.06872 -1e-06 2.8e-05 -8e-06</pose>
        <scale>1 1 1</scale>
        <link name='bender/base_link'>
          <pose frame=''>-8e-05 1e-05 0.06872 -1e-06 2.8e-05 -8e-06</pose>
          <velocity>0 1e-06 9.3e-05 -1e-05 1e-05 -3e-06</velocity>
          <acceleration>0.003036 0.004983 -0.002331 -0.009361 0.00787 -0.005837</acceleration>
          <wrench>0.082268 0.135026 -0.06316 0 -0 0</wrench>
        </link>
        <link name='bender/face_link'>
          <pose frame=''>-0.036079 0.026811 1.45052 -2e-06 0.884618 -0.000799</pose>
          <velocity>1.9e-05 1.3e-05 9.3e-05 -1.4e-05 4.1e-05 -0.0001</velocity>
          <acceleration>0.010741 0.003512 -0.002571 0.567698 0.012448 -0.104029</acceleration>
          <wrench>0.003565 0.001166 -0.000853 0 -0 0</wrench>
        </link>
        <link name='bender/front_left_wheel'>
          <pose frame=''>0.117902 0.157509 0.099717 -1e-06 0.000366 -8e-06</pose>
          <velocity>1e-06 1e-06 9e-05 -1e-05 1.2e-05 0</velocity>
          <acceleration>0.000685 0.000897 -0.005271 -0.008967 0.006841 -0.000428</acceleration>
          <wrench>0.03427 0.044834 -0.263526 0 -0 0</wrench>
        </link>
        <link name='bender/front_right_wheel'>
          <pose frame=''>0.117899 -0.157491 0.099717 -1e-06 0.000361 -8e-06</pose>
          <velocity>1e-06 1e-06 9.3e-05 -8e-06 1.2e-05 0</velocity>
          <acceleration>0.000726 0.000713 -0.001773 -0.007135 0.007255 -0.000217</acceleration>
          <wrench>0.036316 0.03567 -0.088644 0 -0 0</wrench>
        </link>
        <link name='bender/head_link'>
          <pose frame=''>-0.036101 0.000831 1.38262 -1e-06 2.8e-05 -0.000797</pose>
          <velocity>1.5e-05 1.2e-05 9.4e-05 -8e-06 5.7e-05 -0.000103</velocity>
          <acceleration>0.011031 0.011418 -0.000473 0.268193 0.007272 0.063671</acceleration>
          <wrench>0.001984 0.002053 -8.5e-05 0 -0 0</wrench>
        </link>
        <link name='bender/l_elbow_pitch_link'>
          <pose frame=''>0.00993 0.267736 0.847028 -0.037236 -0.041188 -1.3793</pose>
          <velocity>-4.6e-05 0.00096 7.2e-05 -0.001354 -0.00063 8.6e-05</velocity>
          <acceleration>-0.001091 0.010718 -0.002692 -3.10126 0.354955 0.343485</acceleration>
          <wrench>-0.000157 0.001543 -0.000388 0 -0 0</wrench>
        </link>
        <link name='bender/l_elbow_yaw_link'>
          <pose frame=''>-0.016075 0.274396 0.795479 -0.037578 -0.040879 -1.37107</pose>
          <velocity>-1.3e-05 0.000885 5.1e-05 -0.001314 -0.000631 -0.000232</velocity>
          <acceleration>-0.000159 0.013465 -0.003102 3.06677 -0.525594 2.33459</acceleration>
          <wrench>-2.7e-05 0.002255 -0.00052 0 -0 0</wrench>
        </link>
        <link name='bender/l_ext_finger_link'>
          <pose frame=''>-0.010898 0.26768 0.411488 0.468039 0.072572 -1.37534</pose>
          <velocity>0.000257 0.000236 8.7e-05 -0.003083 -0.000974 -0.000168</velocity>
          <acceleration>0.003457 0.004506 -0.003761 0.172889 0.944181 1.43148</acceleration>
          <wrench>0.000553 0.000721 -0.000602 0 -0 0</wrench>
        </link>
        <link name='bender/l_int_finger_link'>
          <pose frame=''>-0.051887 0.287424 0.414848 0.535685 -0.07257 1.76626</pose>
          <velocity>0.000257 0.000253 -1.5e-05 -0.003097 -0.000994 -0.000169</velocity>
          <acceleration>0.002598 0.005299 -0.003475 -0.479728 0.798765 1.25246</acceleration>
          <wrench>0.000416 0.000848 -0.000556 0 -0 0</wrench>
        </link>
        <link name='bender/l_shoulder_pitch_link'>
          <pose frame=''>-0.009104 0.23543 1.22432 -0.000113 0.026017 -1.4e-05</pose>
          <velocity>1.3e-05 1.4e-05 9e-05 -0.000144 0.000201 7e-06</velocity>
          <acceleration>0.009858 0.011341 -0.003892 -2.81878 1.23854 -0.911435</acceleration>
          <wrench>0.001691 0.001945 -0.000668 0 -0 0</wrench>
        </link>
        <link name='bender/l_shoulder_roll_link'>
          <pose frame=''>-0.033896 0.269328 1.19495 -0.061841 0.025999 -1.4e-05</pose>
          <velocity>7e-06 1.4e-05 8.6e-05 0.002724 0.000149 -6.3e-05</velocity>
          <acceleration>0.005729 0.008248 -0.003538 2.59093 1.23717 -2.26181</acceleration>
          <wrench>0.000923 0.001328 -0.00057 0 -0 0</wrench>
        </link>
        <link name='bender/l_shoulder_yaw_link'>
          <pose frame=''>-0.003519 0.260916 1.05827 -0.037273 -0.055776 -1.37875</pose>
          <velocity>-1.6e-05 0.000387 5.8e-05 0.002712 0.000144 -6.7e-05</velocity>
          <acceleration>0.000964 0.009043 -0.002513 -2.65999 -1.29282 2.12785</acceleration>
          <wrench>0.000167 0.001566 -0.000435 0 -0 0</wrench>
        </link>
        <link name='bender/l_wrist_pitch_link'>
          <pose frame=''>-0.011411 0.281284 0.49205 -0.037648 0.07257 -1.37534</pose>
          <velocity>0.00018 0.000484 4.4e-05 -0.00308 -0.000985 -0.000169</velocity>
          <acceleration>0.001123 0.011555 -0.003463 1.47408 0.126141 -1.02388</acceleration>
          <wrench>0.000204 0.002104 -0.000631 0 -0 0</wrench>
        </link>
        <link name='bender/r_elbow_pitch_link'>
          <pose frame=''>-0.016716 -0.238967 0.848731 0.01956 -0.027188 0.023208</pose>
          <velocity>-0.000878 -3.1e-05 0.000178 0.002307 -0.027619 -0.003214</velocity>
          <acceleration>0.039517 -0.103584 0.463458 0.309769 1.38295 -1.31121</acceleration>
          <wrench>0.00569 -0.014914 0.066729 0 -0 0</wrench>
        </link>
        <link name='bender/r_elbow_yaw_link'>
          <pose frame=''>-0.028388 -0.26057 0.796052 0.019516 -0.027308 0.022923</pose>
          <velocity>0.000705 0.000121 0.000518 -0.001603 0.002869 -0.001986</velocity>
          <acceleration>-0.487175 -0.370984 0.666648 -1.50828 -0.857995 -3.12291</acceleration>
          <wrench>-0.081602 -0.06214 0.111664 0 -0 0</wrench>
        </link>
        <link name='bender/r_ext_finger_link'>
          <pose frame=''>-0.05235 -0.271928 0.41434 0.501869 -0.076163 -3.11667</pose>
          <velocity>-0.000413 -0.000556 0.000698 0.006153 0.001429 -0.006564</velocity>
          <acceleration>-1.27509 -0.679975 0.88018 2.19035 1.15716 -0.164238</acceleration>
          <wrench>-0.204015 -0.108796 0.140829 0 -0 0</wrench>
        </link>
        <link name='bender/r_int_finger_link'>
          <pose frame=''>-0.025792 -0.234861 0.412957 0.539401 0.076181 0.024895</pose>
          <velocity>-0.00021 -0.000714 0.000415 -0.007734 0.002175 -0.012464</velocity>
          <acceleration>-0.531164 -2.53377 0.277019 2.14467 -1.51062 0.494546</acceleration>
          <wrench>-0.084986 -0.405403 0.044323 0 -0 0</wrench>
        </link>
        <link name='bender/r_shoulder_pitch_link'>
          <pose frame=''>-0.009106 -0.233767 1.22432 -3.2e-05 0.003036 -6e-06</pose>
          <velocity>-0.000284 -0.000195 -0.000156 0.001907 -0.027238 0.000849</velocity>
          <acceleration>0.069211 -0.246721 -0.292832 -0.832219 0.412957 -0.241877</acceleration>
          <wrench>0.011871 -0.042318 -0.050226 0 -0 0</wrench>
        </link>
        <link name='bender/r_shoulder_roll_link'>
          <pose frame=''>-0.033214 -0.267667 1.19439 0.019503 0.002938 -3.7e-05</pose>
          <velocity>-0.000239 -0.000104 -0.000155 0.001857 -0.006871 -0.002457</velocity>
          <acceleration>0.415048 -0.112536 0.074014 -2.41228 -0.895541 2.44523</acceleration>
          <wrench>0.066839 -0.018123 0.011919 0 -0 0</wrench>
        </link>
        <link name='bender/r_shoulder_yaw_link'>
          <pose frame=''>0.000309 -0.265014 1.05821 0.019561 0.002443 0.023785</pose>
          <velocity>0.000225 2.1e-05 0.000277 0.000955 -0.003457 -0.002016</velocity>
          <acceleration>0.28846 0.152864 0.218399 1.30302 -1.49634 -1.84487</acceleration>
          <wrench>0.049938 0.026464 0.037809 0 -0 0</wrench>
        </link>
        <link name='bender/r_wrist_pitch_link'>
          <pose frame=''>-0.038881 -0.237591 0.493561 0.019561 0.076193 0.024934</pose>
          <velocity>4.3e-05 -0.000479 0.000569 -0.001066 0.005119 -0.003793</velocity>
          <acceleration>-1.03538 -1.00926 0.777284 -3.07462 0.371499 -1.98787</acceleration>
          <wrench>-0.188512 -0.183756 0.14152 0 -0 0</wrench>
        </link>
        <link name='bender/rear_left_wheel'>
          <pose frame=''>-0.132098 0.157511 0.099724 -1e-06 0.000361 -8e-06</pose>
          <velocity>1e-06 1e-06 9.3e-05 -9e-06 1.4e-05 -1e-06</velocity>
          <acceleration>0.001015 0.00078 -0.002763 -0.007804 0.010112 -0.000948</acceleration>
          <wrench>0.050769 0.039015 -0.138129 0 -0 0</wrench>
        </link>
        <link name='bender/rear_right_wheel'>
          <pose frame=''>-0.132101 -0.157489 0.099724 -1e-06 0.00036 -8e-06</pose>
          <velocity>1e-06 1e-06 9.6e-05 -7e-06 1e-05 -1e-06</velocity>
          <acceleration>0.000331 0.000567 0.001048 -0.005672 0.003215 -0.002044</acceleration>
          <wrench>0.016534 0.028353 0.052382 0 -0 0</wrench>
        </link>
      </model>
      <model name='bookshelf'>
        <pose frame=''>1.21889 1.19547 0 0 0 -1.58933</pose>
        <scale>1 1 1</scale>
        <link name='link'>
          <pose frame=''>1.21889 1.19547 0 0 0 -1.58933</pose>
          <velocity>0 0 0 0 -0 0</velocity>
          <acceleration>0 0 0 0 -0 0</acceleration>
          <wrench>0 0 0 0 -0 0</wrench>
        </link>
      </model>
      <model name='ground_plane'>
        <pose frame=''>0 0 0 0 -0 0</pose>
        <scale>1 1 1</scale>
        <link name='link'>
          <pose frame=''>0 0 0 0 -0 0</pose>
          <velocity>0 0 0 0 -0 0</velocity>
          <acceleration>0 0 0 0 -0 0</acceleration>
          <wrench>0 0 0 0 -0 0</wrench>
        </link>
      </model>
      <model name='pringles_red'>
        <pose frame=''>0.619385 0.105611 0.755498 7e-06 3.2e-05 1.5029</pose>
        <scale>1 1 1</scale>
        <link name='link'>
          <pose frame=''>0.619385 0.105611 0.755498 7e-06 3.2e-05 1.5029</pose>
          <velocity>0 0 0 0 -0 0</velocity>
          <acceleration>0 0 0 0 -0 0</acceleration>
          <wrench>0 0 0 0 -0 0</wrench>
        </link>
      </model>
      <model name='table_clone_0'>
        <pose frame=''>1.20801 -0.040679 -0.376387 0 0 -3.13587</pose>
        <scale>1 1 1</scale>
        <link name='link'>
          <pose frame=''>1.20801 -0.040679 -0.376387 0 0 -3.13587</pose>
          <velocity>0 0 0 0 -0 0</velocity>
          <acceleration>0 0 0 0 -0 0</acceleration>
          <wrench>0 0 0 0 -0 0</wrench>
        </link>
      </model>
      <light name='sun'>
        <pose frame=''>0 0 10 0 -0 0</pose>
      </light>
    </state>
    <gui fullscreen='0'>
      <camera name='user_camera'>
        <pose frame=''>-0.345042 2.80868 2.6504 -0 0.707054 -1.25435</pose>
        <view_controller>orbit</view_controller>
        <projection_type>perspective</projection_type>
      </camera>
    </gui>
    <model name='bender_model'>
      <link name='bender/base_link'>
        <pose frame=''>0 0 0 0 -0 0</pose>
        <inertial>
          <pose frame=''>0.007251 0.000236 0.470984 0 -0 0</pose>
          <mass>27.0994</mass>
          <inertia>
            <ixx>4.83643</ixx>
            <ixy>-0.00016498</ixy>
            <ixz>0.015279</ixz>
            <iyy>4.92345</iyy>
            <iyz>0.000346575</iyz>
            <izz>0.718139</izz>
          </inertia>
        </inertial>
        <collision name='bender/base_link_fixed_joint_lump__bender/sensors/laser_front_link_collision'>
          <pose frame=''>0.22 0 0.22 0 -0 0</pose>
          <geometry>
            <box>
              <size>0.05 0.05 0.08</size>
            </box>
          </geometry>
          <surface>
            <contact>
              <ode/>
            </contact>
            <friction>
              <ode/>
              <torsional>
                <ode/>
              </torsional>
            </friction>
            <bounce/>
          </surface>
          <max_contacts>10</max_contacts>
        </collision>
        <collision name='bender/base_link_fixed_joint_lump__bender/sensors/laser_rear_link_collision_1'>
          <pose frame=''>-0.22 0 0.09 -3.14159 -0 3.14159</pose>
          <geometry>
            <box>
              <size>0.05 0.05 0.08</size>
            </box>
          </geometry>
          <surface>
            <contact>
              <ode/>
            </contact>
            <friction>
              <ode/>
              <torsional>
                <ode/>
              </torsional>
            </friction>
            <bounce/>
          </surface>
          <max_contacts>10</max_contacts>
        </collision>
        <collision name='bender/base_link_fixed_joint_lump__bender/mobile_base_link_collision_2'>
          <pose frame=''>0 0 0.075 0 -0 0</pose>
          <geometry>
            <box>
              <size>0.4 0.3 0.15</size>
            </box>
          </geometry>
          <max_contacts>10</max_contacts>
          <surface>
            <contact>
              <ode/>
            </contact>
            <bounce/>
            <friction>
              <torsional>
                <ode/>
              </torsional>
              <ode/>
            </friction>
          </surface>
        </collision>
        <collision name='bender/base_link_fixed_joint_lump__bender/mobile_base_link_collision_3'>
          <pose frame=''>0 0 0.17 0 -0 0</pose>
          <geometry>
            <box>
              <size>0.54 0.38 0.05</size>
            </box>
          </geometry>
          <max_contacts>10</max_contacts>
          <surface>
            <contact>
              <ode/>
            </contact>
            <bounce/>
            <friction>
              <torsional>
                <ode/>
              </torsional>
              <ode/>
            </friction>
          </surface>
        </collision>
        <collision name='bender/base_link_fixed_joint_lump__bender/lower_torso_base_collision_4'>
          <pose frame=''>-0.004058 0.000819 0.52 0 -0 0</pose>
          <geometry>
            <box>
              <size>0.25 0.2 0.25</size>
            </box>
          </geometry>
          <max_contacts>10</max_contacts>
          <surface>
            <contact>
              <ode/>
            </contact>
            <bounce/>
            <friction>
              <torsional>
                <ode/>
              </torsional>
              <ode/>
            </friction>
          </surface>
        </collision>
        <collision name='bender/base_link_fixed_joint_lump__bender/lower_torso_base_collision_5'>
          <pose frame=''>-0.004058 0.000819 0.295 0 -0 0</pose>
          <geometry>
            <box>
              <size>0.25 0.4 0.2</size>
            </box>
          </geometry>
          <max_contacts>10</max_contacts>
          <surface>
            <contact>
              <ode/>
            </contact>
            <bounce/>
            <friction>
              <torsional>
                <ode/>
              </torsional>
              <ode/>
            </friction>
          </surface>
        </collision>
        <collision name='bender/base_link_fixed_joint_lump__bender/psu_base_collision_6'>
          <pose frame=''>0.170942 0.000819 0.525 0 -0 0</pose>
          <geometry>
            <box>
              <size>0.12 0.2 0.27</size>
            </box>
          </geometry>
          <surface>
            <contact>
              <ode/>
            </contact>
            <friction>
              <ode>
                <mu>0.2</mu>
                <mu2>0.2</mu2>
              </ode>
              <torsional>
                <ode/>
              </torsional>
            </friction>
            <bounce/>
          </surface>
          <max_contacts>10</max_contacts>
        </collision>
        <collision name='bender/base_link_fixed_joint_lump__bender/upper_torso_base_collision_7'>
          <pose frame=''>-0.004058 0.000819 0.678 0 -0 0</pose>
          <geometry>
            <box>
              <size>0.25 0.2 0.3</size>
            </box>
          </geometry>
          <max_contacts>10</max_contacts>
          <surface>
            <contact>
              <ode/>
            </contact>
            <bounce/>
            <friction>
              <torsional>
                <ode/>
              </torsional>
              <ode/>
            </friction>
          </surface>
        </collision>
        <collision name='bender/base_link_fixed_joint_lump__bender/upper_torso_base_collision_8'>
          <pose frame=''>-0.004058 0.000819 1.048 0 -0 0</pose>
          <geometry>
            <box>
              <size>0.25 0.3 0.44</size>
            </box>
          </geometry>
          <max_contacts>10</max_contacts>
          <surface>
            <contact>
              <ode/>
            </contact>
            <bounce/>
            <friction>
              <torsional>
                <ode/>
              </torsional>
              <ode/>
            </friction>
          </surface>
        </collision>
        <collision name='bender/base_link_fixed_joint_lump__bender/upper_torso_base_collision_9'>
          <pose frame=''>-0.004058 -0.179181 1.148 0 -0 0</pose>
          <geometry>
            <box>
              <size>0.2 0.08 0.2</size>
            </box>
          </geometry>
          <max_contacts>10</max_contacts>
          <surface>
            <contact>
              <ode/>
            </contact>
            <bounce/>
            <friction>
              <torsional>
                <ode/>
              </torsional>
              <ode/>
            </friction>
          </surface>
        </collision>
        <collision name='bender/base_link_fixed_joint_lump__bender/upper_torso_base_collision_10'>
          <pose frame=''>-0.004058 0.180819 1.148 0 -0 0</pose>
          <geometry>
            <box>
              <size>0.2 0.08 0.2</size>
            </box>
          </geometry>
          <max_contacts>10</max_contacts>
          <surface>
            <contact>
              <ode/>
            </contact>
            <bounce/>
            <friction>
              <torsional>
                <ode/>
              </torsional>
              <ode/>
            </friction>
          </surface>
        </collision>
        <collision name='bender/base_link_fixed_joint_lump__bender/l_arm_base_link_collision_11'>
          <pose frame=''>-0.009058 0.200819 1.138 0 -0 0</pose>
          <geometry>
            <box>
              <size>0.07 0.06 0.17</size>
            </box>
          </geometry>
          <max_contacts>10</max_contacts>
          <surface>
            <contact>
              <ode/>
            </contact>
            <bounce/>
            <friction>
              <torsional>
                <ode/>
              </torsional>
              <ode/>
            </friction>
          </surface>
        </collision>
        <collision name='bender/base_link_fixed_joint_lump__bender/neck_link_collision_12'>
          <pose frame=''>-0.039058 0.000819 1.281 0 -0 0</pose>
          <geometry>
            <box>
              <size>0.08 0.1 0.08</size>
            </box>
          </geometry>
          <max_contacts>10</max_contacts>
          <surface>
            <contact>
              <ode/>
            </contact>
            <bounce/>
            <friction>
              <torsional>
                <ode/>
              </torsional>
              <ode/>
            </friction>
          </surface>
        </collision>
        <collision name='bender/base_link_fixed_joint_lump__bender/r_arm_base_link_collision_13'>
          <pose frame=''>-0.009058 -0.199181 1.138 0 -0 0</pose>
          <geometry>
            <box>
              <size>0.07 0.06 0.17</size>
            </box>
          </geometry>
          <max_contacts>10</max_contacts>
          <surface>
            <contact>
              <ode/>
            </contact>
            <bounce/>
            <friction>
              <torsional>
                <ode/>
              </torsional>
              <ode/>
            </friction>
          </surface>
        </collision>
        <visual name='bender/base_link_fixed_joint_lump__bender/sensors/laser_front_link_visual'>
          <pose frame=''>0.22 0 0.22 0 -0 0</pose>
          <geometry>
            <mesh>
              <scale>1 1 1</scale>
              <uri>/home/giovanni/uchile_ws/ros/bender/base_ws/src/bender_core/bender_description/meshes/sensors/hokuyo.dae</uri>
            </mesh>
          </geometry>
          <material>
            <script>
              <uri>__default__</uri>
              <name>__default__</name>
            </script>
          </material>
        </visual>
        <visual name='bender/base_link_fixed_joint_lump__bender/sensors/laser_rear_link_visual_1'>
          <pose frame=''>-0.22 0 0.09 -3.14159 -0 3.14159</pose>
          <geometry>
            <mesh>
              <scale>1 1 1</scale>
              <uri>/home/giovanni/uchile_ws/ros/bender/base_ws/src/bender_core/bender_description/meshes/sensors/hokuyo.dae</uri>
            </mesh>
          </geometry>
          <material>
            <script>
              <uri>__default__</uri>
              <name>__default__</name>
            </script>
          </material>
        </visual>
        <visual name='bender/base_link_fixed_joint_lump__bender/mobile_base_link_visual_2'>
          <pose frame=''>0 0 0 0 -0 0</pose>
          <geometry>
            <mesh>
              <scale>1 1 1</scale>
              <uri>/home/giovanni/uchile_ws/ros/bender/base_ws/src/bender_core/bender_description/meshes/visual/base.dae</uri>
            </mesh>
          </geometry>
        </visual>
        <visual name='bender/base_link_fixed_joint_lump__bender/lower_torso_base_visual_3'>
          <pose frame=''>-0.004058 0.000819 0.195 -1.5708 0 0</pose>
          <geometry>
            <mesh>
              <scale>1 1 1</scale>
              <uri>/home/giovanni/uchile_ws/ros/bender/base_ws/src/bender_core/bender_description/meshes/visual/lower_torso.dae</uri>
            </mesh>
          </geometry>
        </visual>
        <visual name='bender/base_link_fixed_joint_lump__bender/psu_base_visual_4'>
          <pose frame=''>0.170942 0.000819 0.525 0 -0 0</pose>
          <geometry>
            <box>
              <size>0.12 0.2 0.27</size>
            </box>
          </geometry>
          <material>
            <script>
              <name>Gazebo/Grey</name>
              <uri>file://media/materials/scripts/gazebo.material</uri>
            </script>
          </material>
        </visual>
        <visual name='bender/base_link_fixed_joint_lump__bender/upper_torso_base_visual_5'>
          <pose frame=''>-0.004058 0.000819 0.528 -1.5708 0 0</pose>
          <geometry>
            <mesh>
              <scale>1 1 1</scale>
              <uri>/home/giovanni/uchile_ws/ros/bender/base_ws/src/bender_core/bender_description/meshes/visual/upper_torso.dae</uri>
            </mesh>
          </geometry>
        </visual>
        <visual name='bender/base_link_fixed_joint_lump__bender/l_arm_base_link_visual_6'>
          <pose frame=''>-0.009058 0.230819 1.138 -1.5708 0 0</pose>
          <geometry>
            <mesh>
              <scale>1 1 1</scale>
              <uri>/home/giovanni/uchile_ws/ros/bender/base_ws/src/bender_core/bender_description/meshes/visual/shoulder_base_link.dae</uri>
            </mesh>
          </geometry>
        </visual>
        <visual name='bender/base_link_fixed_joint_lump__bender/neck_link_visual_7'>
          <pose frame=''>-0.009058 0.000819 1.261 -1.5708 0 0</pose>
          <geometry>
            <mesh>
              <scale>1 1 1</scale>
              <uri>/home/giovanni/uchile_ws/ros/bender/base_ws/src/bender_core/bender_description/meshes/visual/neck.dae</uri>
            </mesh>
          </geometry>
        </visual>
        <visual name='bender/base_link_fixed_joint_lump__bender/r_arm_base_link_visual_8'>
          <pose frame=''>-0.009058 -0.229181 1.138 -1.5708 -0 -3.14159</pose>
          <geometry>
            <mesh>
              <scale>1 1 1</scale>
              <uri>/home/giovanni/uchile_ws/ros/bender/base_ws/src/bender_core/bender_description/meshes/visual/shoulder_base_link.dae</uri>
            </mesh>
          </geometry>
        </visual>
        <velocity_decay/>
        <sensor name='laser_front' type='ray'>
          <visualize>0</visualize>
          <update_rate>40</update_rate>
          <ray>
            <scan>
              <horizontal>
                <samples>1080</samples>
                <resolution>1</resolution>
                <min_angle>-2.01</min_angle>
                <max_angle>2.01</max_angle>
              </horizontal>
              <vertical>
                <samples>1</samples>
                <min_angle>0</min_angle>
                <max_angle>0</max_angle>
              </vertical>
            </scan>
            <range>
              <min>0.1</min>
              <max>30</max>
              <resolution>0.01</resolution>
            </range>
            <noise>
              <type>gaussian</type>
              <mean>0</mean>
              <stddev>0.01</stddev>
            </noise>
          </ray>
          <plugin name='gazebo_ros_laser_front_hokuyo_controller' filename='libgazebo_ros_laser.so'>
            <topicName>bender/sensors/laser_front/scan</topicName>
            <frameName>bender/sensors/laser_front_link</frameName>
            <robotNamespace>/</robotNamespace>
          </plugin>
          <pose frame=''>0.22 0 0.22 0 -0 0</pose>
        </sensor>
        <velocity_decay/>
        <sensor name='laser_rear' type='ray'>
          <visualize>0</visualize>
          <update_rate>10</update_rate>
          <ray>
            <scan>
              <horizontal>
                <samples>445</samples>
                <resolution>1</resolution>
                <min_angle>-1.4</min_angle>
                <max_angle>1.4</max_angle>
              </horizontal>
              <vertical>
                <samples>1</samples>
                <min_angle>0</min_angle>
                <max_angle>0</max_angle>
              </vertical>
            </scan>
            <range>
              <min>0.1</min>
              <max>4</max>
              <resolution>0.01</resolution>
            </range>
            <noise>
              <type>gaussian</type>
              <mean>0</mean>
              <stddev>0.01</stddev>
            </noise>
          </ray>
          <plugin name='gazebo_ros_laser_rear_hokuyo_controller' filename='libgazebo_ros_laser.so'>
            <topicName>bender/sensors/laser_rear/scan</topicName>
            <frameName>bender/sensors/laser_rear_link</frameName>
            <robotNamespace>/</robotNamespace>
          </plugin>
          <pose frame=''>-0.22 0 0.09 -3.14159 -0 3.14159</pose>
        </sensor>
        <gravity>1</gravity>
        <velocity_decay/>
        <self_collide>0</self_collide>
        <kinematic>0</kinematic>
      </link>
      <link name='bender/front_left_wheel'>
        <pose frame=''>0.11798 0.1575 0.031 0 -0 0</pose>
        <inertial>
          <pose frame=''>0 0.025 0 1.5708 -0 0</pose>
          <mass>50</mass>
          <inertia>
            <ixx>0.135417</ixx>
            <ixy>0</ixy>
            <ixz>0</ixz>
            <iyy>0.135417</iyy>
            <iyz>0</iyz>
            <izz>0.25</izz>
          </inertia>
        </inertial>
        <collision name='bender/front_left_wheel_collision'>
          <pose frame=''>0 0.025 0 -1.5708 0 0</pose>
          <geometry>
            <cylinder>
              <length>0.05</length>
              <radius>0.1</radius>
            </cylinder>
          </geometry>
          <surface>
            <contact>
              <ode>
                <kp>1e+06</kp>
                <kd>100</kd>
                <max_vel>1</max_vel>
                <min_depth>0</min_depth>
              </ode>
            </contact>
            <friction>
              <ode>
                <mu>0.8</mu>
                <mu2>0.8</mu2>
                <fdir1>1 0 0</fdir1>
              </ode>
              <torsional>
                <ode/>
              </torsional>
            </friction>
            <bounce/>
          </surface>
          <max_contacts>10</max_contacts>
        </collision>
        <visual name='bender/front_left_wheel_visual'>
          <pose frame=''>0 0 0 -3.14159 -0 0</pose>
          <geometry>
            <mesh>
              <scale>1 1 1</scale>
              <uri>/home/giovanni/uchile_ws/ros/bender/base_ws/src/bender_core/bender_description/meshes/visual/wheel.dae</uri>
            </mesh>
          </geometry>
          <material>
            <script>
              <uri>__default__</uri>
              <name>__default__</name>
            </script>
          </material>
        </visual>
        <gravity>1</gravity>
        <velocity_decay/>
        <self_collide>0</self_collide>
        <kinematic>0</kinematic>
      </link>
      <joint name='front_left_wheel_joint' type='revolute'>
        <child>bender/front_left_wheel</child>
        <parent>bender/base_link</parent>
        <axis>
          <xyz>0 1 0</xyz>
          <limit>
            <lower>-1e+16</lower>
            <upper>1e+16</upper>
          </limit>
          <dynamics>
            <spring_reference>0</spring_reference>
            <spring_stiffness>0</spring_stiffness>
          </dynamics>
          <use_parent_model_frame>1</use_parent_model_frame>
        </axis>
      </joint>
      <link name='bender/front_right_wheel'>
        <pose frame=''>0.11798 -0.1575 0.031 0 -0 0</pose>
        <inertial>
          <pose frame=''>0 -0.025 0 1.5708 -0 0</pose>
          <mass>50</mass>
          <inertia>
            <ixx>0.135417</ixx>
            <ixy>0</ixy>
            <ixz>0</ixz>
            <iyy>0.135417</iyy>
            <iyz>0</iyz>
            <izz>0.25</izz>
          </inertia>
        </inertial>
        <collision name='bender/front_right_wheel_collision'>
          <pose frame=''>0 -0.025 0 -1.5708 0 0</pose>
          <geometry>
            <cylinder>
              <length>0.05</length>
              <radius>0.1</radius>
            </cylinder>
          </geometry>
          <surface>
            <contact>
              <ode>
                <kp>1e+06</kp>
                <kd>100</kd>
                <max_vel>1</max_vel>
                <min_depth>0</min_depth>
              </ode>
            </contact>
            <friction>
              <ode>
                <mu>0.8</mu>
                <mu2>0.8</mu2>
                <fdir1>1 0 0</fdir1>
              </ode>
              <torsional>
                <ode/>
              </torsional>
            </friction>
            <bounce/>
          </surface>
          <max_contacts>10</max_contacts>
        </collision>
        <visual name='bender/front_right_wheel_visual'>
          <pose frame=''>0 0 0 0 -0 0</pose>
          <geometry>
            <mesh>
              <scale>1 1 1</scale>
              <uri>/home/giovanni/uchile_ws/ros/bender/base_ws/src/bender_core/bender_description/meshes/visual/wheel.dae</uri>
            </mesh>
          </geometry>
          <material>
            <script>
              <uri>__default__</uri>
              <name>__default__</name>
            </script>
          </material>
        </visual>
        <gravity>1</gravity>
        <velocity_decay/>
        <self_collide>0</self_collide>
        <kinematic>0</kinematic>
      </link>
      <joint name='front_right_wheel_joint' type='revolute'>
        <child>bender/front_right_wheel</child>
        <parent>bender/base_link</parent>
        <axis>
          <xyz>0 1 0</xyz>
          <limit>
            <lower>-1e+16</lower>
            <upper>1e+16</upper>
          </limit>
          <dynamics>
            <spring_reference>0</spring_reference>
            <spring_stiffness>0</spring_stiffness>
          </dynamics>
          <use_parent_model_frame>1</use_parent_model_frame>
        </axis>
      </joint>
      <link name='bender/rear_left_wheel'>
        <pose frame=''>-0.13202 0.1575 0.031 0 -0 0</pose>
        <inertial>
          <pose frame=''>0 0.025 0 1.5708 -0 0</pose>
          <mass>50</mass>
          <inertia>
            <ixx>0.135417</ixx>
            <ixy>0</ixy>
            <ixz>0</ixz>
            <iyy>0.135417</iyy>
            <iyz>0</iyz>
            <izz>0.25</izz>
          </inertia>
        </inertial>
        <collision name='bender/rear_left_wheel_collision'>
          <pose frame=''>0 0.025 0 -1.5708 0 0</pose>
          <geometry>
            <cylinder>
              <length>0.05</length>
              <radius>0.1</radius>
            </cylinder>
          </geometry>
          <surface>
            <contact>
              <ode>
                <kp>1e+06</kp>
                <kd>100</kd>
                <max_vel>1</max_vel>
                <min_depth>0</min_depth>
              </ode>
            </contact>
            <friction>
              <ode>
                <mu>0.8</mu>
                <mu2>0.8</mu2>
                <fdir1>1 0 0</fdir1>
              </ode>
              <torsional>
                <ode/>
              </torsional>
            </friction>
            <bounce/>
          </surface>
          <max_contacts>10</max_contacts>
        </collision>
        <visual name='bender/rear_left_wheel_visual'>
          <pose frame=''>0 0 0 -3.14159 -0 0</pose>
          <geometry>
            <mesh>
              <scale>1 1 1</scale>
              <uri>/home/giovanni/uchile_ws/ros/bender/base_ws/src/bender_core/bender_description/meshes/visual/wheel.dae</uri>
            </mesh>
          </geometry>
          <material>
            <script>
              <uri>__default__</uri>
              <name>__default__</name>
            </script>
          </material>
        </visual>
        <gravity>1</gravity>
        <velocity_decay/>
        <self_collide>0</self_collide>
        <kinematic>0</kinematic>
      </link>
      <joint name='rear_left_wheel_joint' type='revolute'>
        <child>bender/rear_left_wheel</child>
        <parent>bender/base_link</parent>
        <axis>
          <xyz>0 1 0</xyz>
          <limit>
            <lower>-1e+16</lower>
            <upper>1e+16</upper>
          </limit>
          <dynamics>
            <spring_reference>0</spring_reference>
            <spring_stiffness>0</spring_stiffness>
          </dynamics>
          <use_parent_model_frame>1</use_parent_model_frame>
        </axis>
      </joint>
      <link name='bender/rear_right_wheel'>
        <pose frame=''>-0.13202 -0.1575 0.031 0 -0 0</pose>
        <inertial>
          <pose frame=''>0 -0.025 0 1.5708 -0 0</pose>
          <mass>50</mass>
          <inertia>
            <ixx>0.135417</ixx>
            <ixy>0</ixy>
            <ixz>0</ixz>
            <iyy>0.135417</iyy>
            <iyz>0</iyz>
            <izz>0.25</izz>
          </inertia>
        </inertial>
        <collision name='bender/rear_right_wheel_collision'>
          <pose frame=''>0 -0.025 0 -1.5708 0 0</pose>
          <geometry>
            <cylinder>
              <length>0.05</length>
              <radius>0.1</radius>
            </cylinder>
          </geometry>
          <surface>
            <contact>
              <ode>
                <kp>1e+06</kp>
                <kd>100</kd>
                <max_vel>1</max_vel>
                <min_depth>0</min_depth>
              </ode>
            </contact>
            <friction>
              <ode>
                <mu>0.8</mu>
                <mu2>0.8</mu2>
                <fdir1>1 0 0</fdir1>
              </ode>
              <torsional>
                <ode/>
              </torsional>
            </friction>
            <bounce/>
          </surface>
          <max_contacts>10</max_contacts>
        </collision>
        <visual name='bender/rear_right_wheel_visual'>
          <pose frame=''>0 0 0 0 -0 0</pose>
          <geometry>
            <mesh>
              <scale>1 1 1</scale>
              <uri>/home/giovanni/uchile_ws/ros/bender/base_ws/src/bender_core/bender_description/meshes/visual/wheel.dae</uri>
            </mesh>
          </geometry>
          <material>
            <script>
              <uri>__default__</uri>
              <name>__default__</name>
            </script>
          </material>
        </visual>
        <gravity>1</gravity>
        <velocity_decay/>
        <self_collide>0</self_collide>
        <kinematic>0</kinematic>
      </link>
      <joint name='rear_right_wheel_joint' type='revolute'>
        <child>bender/rear_right_wheel</child>
        <parent>bender/base_link</parent>
        <axis>
          <xyz>0 1 0</xyz>
          <limit>
            <lower>-1e+16</lower>
            <upper>1e+16</upper>
          </limit>
          <dynamics>
            <spring_reference>0</spring_reference>
            <spring_stiffness>0</spring_stiffness>
          </dynamics>
          <use_parent_model_frame>1</use_parent_model_frame>
        </axis>
      </joint>
      <link name='bender/l_shoulder_pitch_link'>
        <pose frame=''>-0.009058 0.235419 1.1556 0 -0 0</pose>
        <inertial>
          <pose frame=''>0.000233 0.019812 -0.013482 0 -0 0</pose>
          <mass>0.17152</mass>
          <inertia>
            <ixx>0.00010991</ixx>
            <ixy>-5.6413e-07</ixy>
            <ixz>1.0935e-06</ixz>
            <iyy>0.00010993</iyy>
            <iyz>1.8807e-06</iyz>
            <izz>8.8167e-05</izz>
          </inertia>
        </inertial>
        <collision name='bender/l_shoulder_pitch_link_collision'>
          <pose frame=''>0 0.025 -0.01 0 -0 0</pose>
          <geometry>
            <box>
              <size>0.05 0.05 0.07</size>
            </box>
          </geometry>
          <max_contacts>10</max_contacts>
          <surface>
            <contact>
              <ode/>
            </contact>
            <bounce/>
            <friction>
              <torsional>
                <ode/>
              </torsional>
              <ode/>
            </friction>
          </surface>
        </collision>
        <visual name='bender/l_shoulder_pitch_link_visual'>
          <pose frame=''>0 0 0 -1.5708 0 0</pose>
          <geometry>
            <mesh>
              <scale>1 1 1</scale>
              <uri>/home/giovanni/uchile_ws/ros/bender/base_ws/src/bender_core/bender_description/meshes/visual/shoulder_pitch.dae</uri>
            </mesh>
          </geometry>
        </visual>
        <self_collide>0</self_collide>
        <kinematic>0</kinematic>
      </link>
      <joint name='l_shoulder_pitch_joint' type='revolute'>
        <child>bender/l_shoulder_pitch_link</child>
        <parent>bender/base_link</parent>
        <axis>
          <xyz>0 -1 0</xyz>
          <limit>
            <lower>-1.53397</lower>
            <upper>1.94815</upper>
            <effort>10.85</effort>
            <velocity>5.23599</velocity>
          </limit>
          <dynamics>
            <damping>0.15</damping>
            <friction>0.3</friction>
            <spring_reference>0</spring_reference>
            <spring_stiffness>0</spring_stiffness>
          </dynamics>
          <use_parent_model_frame>1</use_parent_model_frame>
        </axis>
      </joint>
      <link name='bender/l_shoulder_roll_link'>
        <pose frame=''>-0.033078 0.269319 1.1256 0 -0 0</pose>
        <inertial>
          <pose frame=''>0.046779 -9e-06 -0.11466 0 -0 0</pose>
          <mass>0.16104</mass>
          <inertia>
            <ixx>0.00050901</ixx>
            <ixy>6.2439e-09</ixy>
            <ixz>0.00010534</ixz>
            <iyy>0.00055051</iyy>
            <iyz>-6.7534e-08</iyz>
            <izz>0.00011428</izz>
          </inertia>
        </inertial>
        <collision name='bender/l_shoulder_roll_link_collision'>
          <pose frame=''>0.04 0 -0.075 0 -0.25 0</pose>
          <geometry>
            <box>
              <size>0.05 0.035 0.18</size>
            </box>
          </geometry>
          <max_contacts>10</max_contacts>
          <surface>
            <contact>
              <ode/>
            </contact>
            <bounce/>
            <friction>
              <torsional>
                <ode/>
              </torsional>
              <ode/>
            </friction>
          </surface>
        </collision>
        <visual name='bender/l_shoulder_roll_link_visual'>
          <pose frame=''>0 0 0 -1.5708 0 0</pose>
          <geometry>
            <mesh>
              <scale>1 1 1</scale>
              <uri>/home/giovanni/uchile_ws/ros/bender/base_ws/src/bender_core/bender_description/meshes/visual/shoulder_roll.dae</uri>
            </mesh>
          </geometry>
        </visual>
        <self_collide>0</self_collide>
        <kinematic>0</kinematic>
      </link>
      <joint name='l_shoulder_roll_joint' type='revolute'>
        <child>bender/l_shoulder_roll_link</child>
        <parent>bender/l_shoulder_pitch_link</parent>
        <axis>
          <xyz>1 0 0</xyz>
          <limit>
            <lower>-0.23776</lower>
            <upper>1.51096</upper>
            <effort>10.85</effort>
            <velocity>5.23599</velocity>
          </limit>
          <dynamics>
            <damping>0.15</damping>
            <friction>0.3</friction>
            <spring_reference>0</spring_reference>
            <spring_stiffness>0</spring_stiffness>
          </dynamics>
          <use_parent_model_frame>1</use_parent_model_frame>
        </axis>
      </joint>
      <link name='bender/l_shoulder_yaw_link'>
        <pose frame=''>0.000842 0.269319 0.9895 0 -0 0</pose>
        <inertial>
          <pose frame=''>-0.017828 -0.000166 -0.14148 0 -0 0</pose>
          <mass>0.17312</mass>
          <inertia>
            <ixx>0.0008473</ixx>
            <ixy>7.9313e-08</ixy>
            <ixz>3.4804e-05</ixz>
            <iyy>0.00084882</iyy>
            <iyz>-3.1674e-06</iyz>
            <izz>6.5527e-05</izz>
          </inertia>
        </inertial>
        <collision name='bender/l_shoulder_yaw_link_collision'>
          <pose frame=''>-0.015 0 -0.115 0 -0 0</pose>
          <geometry>
            <box>
              <size>0.05 0.035 0.23</size>
            </box>
          </geometry>
          <max_contacts>10</max_contacts>
          <surface>
            <contact>
              <ode/>
            </contact>
            <bounce/>
            <friction>
              <torsional>
                <ode/>
              </torsional>
              <ode/>
            </friction>
          </surface>
        </collision>
        <visual name='bender/l_shoulder_yaw_link_visual'>
          <pose frame=''>0 0 0 -1.5708 0 0</pose>
          <geometry>
            <mesh>
              <scale>1 1 1</scale>
              <uri>/home/giovanni/uchile_ws/ros/bender/base_ws/src/bender_core/bender_description/meshes/visual/shoulder_yaw.dae</uri>
            </mesh>
          </geometry>
        </visual>
        <self_collide>0</self_collide>
        <kinematic>0</kinematic>
      </link>
      <joint name='l_shoulder_yaw_joint' type='revolute'>
        <child>bender/l_shoulder_yaw_link</child>
        <parent>bender/l_shoulder_roll_link</parent>
        <axis>
          <xyz>0 0 -1</xyz>
          <limit>
            <lower>-1.48284</lower>
            <upper>1.38057</upper>
            <effort>4.44054</effort>
            <velocity>5.23599</velocity>
          </limit>
          <dynamics>
            <damping>0.15</damping>
            <friction>0.3</friction>
            <spring_reference>0</spring_reference>
            <spring_stiffness>0</spring_stiffness>
          </dynamics>
          <use_parent_model_frame>1</use_parent_model_frame>
        </axis>
      </joint>
      <link name='bender/l_elbow_pitch_link'>
        <pose frame=''>-0.015056 0.291664 0.7795 0 -0 0</pose>
        <inertial>
          <pose frame=''>0.006745 -0.022124 -0.059507 0 -0 0</pose>
          <mass>0.14398</mass>
          <inertia>
            <ixx>0.00012531</ixx>
            <ixy>1.5127e-07</ixy>
            <ixz>3.5125e-06</ixz>
            <iyy>0.00011254</iyy>
            <iyz>-1.3346e-06</iyz>
            <izz>8.6928e-05</izz>
          </inertia>
        </inertial>
        <collision name='bender/l_elbow_pitch_link_collision'>
          <pose frame=''>0.015 -0.025 -0.05 0 -0 0</pose>
          <geometry>
            <box>
              <size>0.05 0.07 0.1</size>
            </box>
          </geometry>
          <max_contacts>10</max_contacts>
          <surface>
            <contact>
              <ode/>
            </contact>
            <bounce/>
            <friction>
              <torsional>
                <ode/>
              </torsional>
              <ode/>
            </friction>
          </surface>
        </collision>
        <visual name='bender/l_elbow_pitch_link_visual'>
          <pose frame=''>0 0 0 -1.5708 0 0</pose>
          <geometry>
            <mesh>
              <scale>1 1 1</scale>
              <uri>/home/giovanni/uchile_ws/ros/bender/base_ws/src/bender_core/bender_description/meshes/visual/elbow_pitch.dae</uri>
            </mesh>
          </geometry>
        </visual>
        <self_collide>0</self_collide>
        <kinematic>0</kinematic>
      </link>
      <joint name='l_elbow_pitch_joint' type='revolute'>
        <child>bender/l_elbow_pitch_link</child>
        <parent>bender/l_shoulder_yaw_link</parent>
        <axis>
          <xyz>0 -1 0</xyz>
          <limit>
            <lower>-1.0431</lower>
            <upper>1.90213</upper>
            <effort>10.85</effort>
            <velocity>5.23599</velocity>
          </limit>
          <dynamics>
            <damping>0.15</damping>
            <friction>0.3</friction>
            <spring_reference>0</spring_reference>
            <spring_stiffness>0</spring_stiffness>
          </dynamics>
          <use_parent_model_frame>1</use_parent_model_frame>
        </axis>
      </joint>
      <link name='bender/l_elbow_yaw_link'>
        <pose frame=''>-0.028656 0.269319 0.7276 0 -0 0</pose>
        <inertial>
          <pose frame=''>-0.0196 8.5e-05 -0.17771 0 -0 0</pose>
          <mass>0.1675</mass>
          <inertia>
            <ixx>0.0017359</ixx>
            <ixy>-4.8507e-09</ixy>
            <ixz>3.1814e-05</ixz>
            <iyy>0.0017441</iyy>
            <iyz>2.1946e-07</iyz>
            <izz>5.881e-05</izz>
          </inertia>
        </inertial>
        <collision name='bender/l_elbow_yaw_link_collision'>
          <pose frame=''>-0.015 0 -0.15 0 -0 0</pose>
          <geometry>
            <box>
              <size>0.05 0.035 0.32</size>
            </box>
          </geometry>
          <max_contacts>10</max_contacts>
          <surface>
            <contact>
              <ode/>
            </contact>
            <bounce/>
            <friction>
              <torsional>
                <ode/>
              </torsional>
              <ode/>
            </friction>
          </surface>
        </collision>
        <visual name='bender/l_elbow_yaw_link_visual'>
          <pose frame=''>0 0 0 -1.5708 0 0</pose>
          <geometry>
            <mesh>
              <scale>1 1 1</scale>
              <uri>/home/giovanni/uchile_ws/ros/bender/base_ws/src/bender_core/bender_description/meshes/visual/elbow_yaw.dae</uri>
            </mesh>
          </geometry>
        </visual>
        <self_collide>0</self_collide>
        <kinematic>0</kinematic>
      </link>
      <joint name='l_elbow_yaw_joint' type='revolute'>
        <child>bender/l_elbow_yaw_link</child>
        <parent>bender/l_elbow_pitch_link</parent>
        <axis>
          <xyz>0 0 -1</xyz>
          <limit>
            <lower>-1.20161</lower>
            <upper>1.30387</upper>
            <effort>4.44054</effort>
            <velocity>5.23599</velocity>
          </limit>
          <dynamics>
            <damping>0.15</damping>
            <friction>0.3</friction>
            <spring_reference>0</spring_reference>
            <spring_stiffness>0</spring_stiffness>
          </dynamics>
          <use_parent_model_frame>1</use_parent_model_frame>
        </axis>
      </joint>
      <link name='bender/l_wrist_pitch_link'>
        <pose frame=''>-0.046877 0.286634 0.4251 0 -0 0</pose>
        <inertial>
          <pose frame=''>3.9e-05 -0.017418 -0.05204 0 -0 0</pose>
          <mass>0.18207</mass>
          <inertia>
            <ixx>0.000168472</ixx>
            <ixy>-2.80655e-11</ixy>
            <ixz>-2.03417e-07</ixz>
            <iyy>0.000108722</iyy>
            <iyz>6.41597e-07</iyz>
            <izz>0.000117584</izz>
          </inertia>
        </inertial>
        <collision name='bender/l_wrist_pitch_link_collision'>
          <pose frame=''>0 -0.02 -0.05 0 -0 0</pose>
          <geometry>
            <box>
              <size>0.04 0.08 0.07</size>
            </box>
          </geometry>
          <max_contacts>10</max_contacts>
          <surface>
            <contact>
              <ode/>
            </contact>
            <bounce/>
            <friction>
              <torsional>
                <ode/>
              </torsional>
              <ode/>
            </friction>
          </surface>
        </collision>
        <visual name='bender/l_wrist_pitch_link_visual'>
          <pose frame=''>0 0 0 -1.5708 0 0</pose>
          <geometry>
            <mesh>
              <scale>1 1 1</scale>
              <uri>/home/giovanni/uchile_ws/ros/bender/base_ws/src/bender_core/bender_description/meshes/visual/wrist_pitch.dae</uri>
            </mesh>
          </geometry>
        </visual>
        <self_collide>0</self_collide>
        <kinematic>0</kinematic>
      </link>
      <joint name='l_wrist_pitch_joint' type='revolute'>
        <child>bender/l_wrist_pitch_link</child>
        <parent>bender/l_elbow_yaw_link</parent>
        <axis>
          <xyz>0 -1 0</xyz>
          <limit>
            <lower>-1.07378</lower>
            <upper>1.22717</upper>
            <effort>3.1</effort>
            <velocity>5.23599</velocity>
          </limit>
          <dynamics>
            <damping>0.15</damping>
            <friction>0.3</friction>
            <spring_reference>0</spring_reference>
            <spring_stiffness>0</spring_stiffness>
          </dynamics>
          <use_parent_model_frame>1</use_parent_model_frame>
        </axis>
      </joint>
      <link name='bender/l_ext_finger_link'>
        <pose frame=''>-0.027627 0.287484 0.3457 0.523599 -0 0</pose>
        <inertial>
          <pose frame=''>-0.018 -0.03 -0.07 -0.523599 0 0</pose>
          <mass>0.16</mass>
          <inertia>
            <ixx>0.000357667</ixx>
            <ixy>0</ixy>
            <ixz>0</ixz>
            <iyy>0.000374667</iyy>
            <iyz>0</iyz>
            <izz>4.96667e-05</izz>
          </inertia>
        </inertial>
        <collision name='bender/l_ext_finger_link_collision'>
          <pose frame=''>0 0 0.011 0 -0 0</pose>
          <geometry>
            <mesh>
              <scale>1 1 1</scale>
              <uri>/home/giovanni/uchile_ws/ros/bender/base_ws/src/bender_core/bender_description/meshes/collision/finger.stl</uri>
            </mesh>
          </geometry>
          <surface>
            <contact>
              <ode>
                <kp>1e+06</kp>
                <kd>1</kd>
                <min_depth>0.005</min_depth>
              </ode>
            </contact>
            <friction>
              <ode>
                <mu>1</mu>
                <mu2>1</mu2>
              </ode>
              <torsional>
                <ode/>
              </torsional>
            </friction>
            <bounce/>
          </surface>
          <max_contacts>10</max_contacts>
        </collision>
        <visual name='bender/l_ext_finger_link_visual'>
          <pose frame=''>0 0 0 0 -0 0</pose>
          <geometry>
            <mesh>
              <scale>1 1 1</scale>
              <uri>/home/giovanni/uchile_ws/ros/bender/base_ws/src/bender_core/bender_description/meshes/visual/one_finger.stl</uri>
            </mesh>
          </geometry>
          <material>
            <script>
              <name>Gazebo/DarkGrey</name>
              <uri>file://media/materials/scripts/gazebo.material</uri>
            </script>
          </material>
        </visual>
        <gravity>1</gravity>
        <velocity_decay/>
        <self_collide>1</self_collide>
        <kinematic>0</kinematic>
      </link>
      <joint name='l_ext_finger_joint' type='revolute'>
        <child>bender/l_ext_finger_link</child>
        <parent>bender/l_wrist_pitch_link</parent>
        <axis>
          <xyz>1 0 0</xyz>
          <limit>
            <lower>-0.02556</lower>
            <upper>0.69029</upper>
            <effort>3.1</effort>
            <velocity>10</velocity>
          </limit>
          <dynamics>
            <damping>0.2</damping>
            <friction>1</friction>
            <spring_reference>0</spring_reference>
            <spring_stiffness>0</spring_stiffness>
          </dynamics>
          <use_parent_model_frame>1</use_parent_model_frame>
        </axis>
      </joint>
      <link name='bender/l_int_finger_link'>
        <pose frame=''>-0.055127 0.251084 0.3457 0.523599 0 -3.14159</pose>
        <inertial>
          <pose frame=''>-0.018 -0.03 -0.07 -0.523599 0 0</pose>
          <mass>0.16</mass>
          <inertia>
            <ixx>0.000357667</ixx>
            <ixy>0</ixy>
            <ixz>0</ixz>
            <iyy>0.000374667</iyy>
            <iyz>0</iyz>
            <izz>4.96667e-05</izz>
          </inertia>
        </inertial>
        <collision name='bender/l_int_finger_link_collision'>
          <pose frame=''>0.005 0 0.011 0 -0 0</pose>
          <geometry>
            <mesh>
              <scale>1 1 1</scale>
              <uri>/home/giovanni/uchile_ws/ros/bender/base_ws/src/bender_core/bender_description/meshes/collision/finger.stl</uri>
            </mesh>
          </geometry>
          <surface>
            <contact>
              <ode>
                <kp>1e+06</kp>
                <kd>1</kd>
                <min_depth>0.005</min_depth>
              </ode>
            </contact>
            <friction>
              <ode>
                <mu>1</mu>
                <mu2>1</mu2>
              </ode>
              <torsional>
                <ode/>
              </torsional>
            </friction>
            <bounce/>
          </surface>
          <max_contacts>10</max_contacts>
        </collision>
        <visual name='bender/l_int_finger_link_visual'>
          <pose frame=''>0.008 0 0 0 -0 0</pose>
          <geometry>
            <mesh>
              <scale>1 1 1</scale>
              <uri>/home/giovanni/uchile_ws/ros/bender/base_ws/src/bender_core/bender_description/meshes/visual/one_finger.stl</uri>
            </mesh>
          </geometry>
          <material>
            <script>
              <name>Gazebo/DarkGrey</name>
              <uri>file://media/materials/scripts/gazebo.material</uri>
            </script>
          </material>
        </visual>
        <gravity>1</gravity>
        <velocity_decay/>
        <self_collide>1</self_collide>
        <kinematic>0</kinematic>
      </link>
      <joint name='l_int_finger_joint' type='revolute'>
        <child>bender/l_int_finger_link</child>
        <parent>bender/l_wrist_pitch_link</parent>
        <axis>
          <xyz>-1 0 0</xyz>
          <limit>
            <lower>-0.02556</lower>
            <upper>0.69029</upper>
            <effort>3.1</effort>
            <velocity>10</velocity>
          </limit>
          <dynamics>
            <damping>0.2</damping>
            <friction>1</friction>
            <spring_reference>0</spring_reference>
            <spring_stiffness>0</spring_stiffness>
          </dynamics>
          <use_parent_model_frame>1</use_parent_model_frame>
        </axis>
      </joint>
      <link name='bender/head_link'>
        <pose frame=''>-0.036058 0.000819 1.3139 0 -0 0</pose>
        <inertial>
          <pose frame=''>-0.012141 -1.8e-05 0.041401 0 -0 0</pose>
          <mass>0.17983</mass>
          <inertia>
            <ixx>0.00015925</ixx>
            <ixy>4.0867e-07</ixy>
            <ixz>-7.9102e-06</ixz>
            <iyy>0.0001892</iyy>
            <iyz>-6.1427e-08</iyz>
            <izz>8.7881e-05</izz>
          </inertia>
        </inertial>
        <collision name='bender/head_link_collision'>
          <pose frame=''>-0.01 0 0.05 0 -0 0</pose>
          <geometry>
            <box>
              <size>0.08 0.06 0.1</size>
            </box>
          </geometry>
          <max_contacts>10</max_contacts>
          <surface>
            <contact>
              <ode/>
            </contact>
            <bounce/>
            <friction>
              <torsional>
                <ode/>
              </torsional>
              <ode/>
            </friction>
          </surface>
        </collision>
        <visual name='bender/head_link_visual'>
          <pose frame=''>0 0 0 -1.5708 0 0</pose>
          <geometry>
            <mesh>
              <scale>1 1 1</scale>
              <uri>/home/giovanni/uchile_ws/ros/bender/base_ws/src/bender_core/bender_description/meshes/visual/head.dae</uri>
            </mesh>
          </geometry>
        </visual>
        <self_collide>0</self_collide>
        <kinematic>0</kinematic>
      </link>
      <joint name='head_yaw_joint' type='revolute'>
        <child>bender/head_link</child>
        <parent>bender/base_link</parent>
        <axis>
          <xyz>0 0 1</xyz>
          <limit>
            <lower>-1.8919</lower>
            <upper>1.8919</upper>
            <effort>4.44054</effort>
            <velocity>1</velocity>
          </limit>
          <dynamics>
            <damping>0.15</damping>
            <friction>0</friction>
            <spring_reference>0</spring_reference>
            <spring_stiffness>0</spring_stiffness>
          </dynamics>
          <use_parent_model_frame>1</use_parent_model_frame>
        </axis>
      </joint>
      <link name='bender/face_link'>
        <pose frame=''>-0.036058 0.026799 1.3818 0 -0 0</pose>
        <inertial>
          <pose frame=''>0.046115 -0.026111 0.10189 0 -0 0</pose>
          <mass>0.33187</mass>
          <inertia>
            <ixx>0.0013461</ixx>
            <ixy>-2.8029e-07</ixy>
            <ixz>-9.224e-05</ixz>
            <iyy>0.00080978</iyy>
            <iyz>-6.6351e-07</iyz>
            <izz>0.00074443</izz>
          </inertia>
        </inertial>
        <collision name='bender/face_link_collision'>
          <pose frame=''>0.05 -0.03 0.08 0 -0 0</pose>
          <geometry>
            <box>
              <size>0.05 0.18 0.18</size>
            </box>
          </geometry>
          <max_contacts>10</max_contacts>
          <surface>
            <contact>
              <ode/>
            </contact>
            <bounce/>
            <friction>
              <torsional>
                <ode/>
              </torsional>
              <ode/>
            </friction>
          </surface>
        </collision>
        <visual name='bender/face_link_visual'>
          <pose frame=''>0 0 0 -1.5708 0 0</pose>
          <geometry>
            <mesh>
              <scale>1 1 1</scale>
              <uri>/home/giovanni/uchile_ws/ros/bender/base_ws/src/bender_core/bender_description/meshes/visual/face.dae</uri>
            </mesh>
          </geometry>
        </visual>
        <gravity>1</gravity>
        <velocity_decay/>
        <sensor name='rgbd_head' type='depth'>
          <always_on>1</always_on>
          <update_rate>5</update_rate>
          <camera name='__default__'>
            <horizontal_fov>0.994838</horizontal_fov>
            <image>
              <format>B8G8R8</format>
              <width>640</width>
              <height>480</height>
            </image>
            <clip>
              <near>0.01</near>
              <far>5</far>
            </clip>
          </camera>
          <plugin name='rgbd_head_controller' filename='libgazebo_ros_openni_kinect.so'>
            <alwaysOn>true</alwaysOn>
            <updateRate>5.0</updateRate>
            <cameraName>rgbd_head</cameraName>
            <imageTopicName>/bender/sensors/rgbd_head/rgb/image_raw</imageTopicName>
            <cameraInfoTopicName>/bender/sensors/rgbd_head/rgb/camera_info</cameraInfoTopicName>
            <depthImageTopicName>/bender/sensors/rgbd_head/depth/image_raw</depthImageTopicName>
            <depthImageCameraInfoTopicName>/bender/sensors/rgbd_head/depth/camera_info</depthImageCameraInfoTopicName>
            <pointCloudTopicName>/bender/sensors/rgbd_head/depth/points</pointCloudTopicName>
            <frameName>bender/sensors/rgbd_head_depth_optical_frame</frameName>
            <baseline>0.1</baseline>
            <distortion_k1>0.0</distortion_k1>
            <distortion_k2>0.0</distortion_k2>
            <distortion_k3>0.0</distortion_k3>
            <distortion_t1>0.0</distortion_t1>
            <distortion_t2>0.0</distortion_t2>
            <pointCloudCutoff>0.35</pointCloudCutoff>
            <pointCloudCutoffMax>2.0</pointCloudCutoffMax>
            <robotNamespace>/</robotNamespace>
          </plugin>
          <pose frame=''>0.05332 0.0208 0.14105 0 0.031904 0</pose>
        </sensor>
        <self_collide>0</self_collide>
        <kinematic>0</kinematic>
      </link>
      <joint name='head_pitch_joint' type='revolute'>
        <child>bender/face_link</child>
        <parent>bender/head_link</parent>
        <axis>
          <xyz>0 1 0</xyz>
          <limit>
            <lower>-0.39372</lower>
            <upper>0.88459</upper>
            <effort>4.44054</effort>
            <velocity>1</velocity>
          </limit>
          <dynamics>
            <damping>0.15</damping>
            <friction>0</friction>
            <spring_reference>0</spring_reference>
            <spring_stiffness>0</spring_stiffness>
          </dynamics>
          <use_parent_model_frame>1</use_parent_model_frame>
        </axis>
      </joint>
      <link name='bender/r_shoulder_pitch_link'>
        <pose frame=''>-0.009058 -0.233781 1.1556 0 -0 0</pose>
        <inertial>
          <pose frame=''>0.000233 0.019812 -0.013482 0 -0 0</pose>
          <mass>0.17152</mass>
          <inertia>
            <ixx>0.00010991</ixx>
            <ixy>-5.6413e-07</ixy>
            <ixz>1.0935e-06</ixz>
            <iyy>0.00010993</iyy>
            <iyz>1.8807e-06</iyz>
            <izz>8.8167e-05</izz>
          </inertia>
        </inertial>
        <collision name='bender/r_shoulder_pitch_link_collision'>
          <pose frame=''>0 -0.025 -0.01 0 -0 0</pose>
          <geometry>
            <box>
              <size>0.05 0.05 0.07</size>
            </box>
          </geometry>
          <max_contacts>10</max_contacts>
          <surface>
            <contact>
              <ode/>
            </contact>
            <bounce/>
            <friction>
              <torsional>
                <ode/>
              </torsional>
              <ode/>
            </friction>
          </surface>
        </collision>
        <visual name='bender/r_shoulder_pitch_link_visual'>
          <pose frame=''>0 0 0 -1.5708 -0 -3.14159</pose>
          <geometry>
            <mesh>
              <scale>1 1 1</scale>
              <uri>/home/giovanni/uchile_ws/ros/bender/base_ws/src/bender_core/bender_description/meshes/visual/shoulder_pitch.dae</uri>
            </mesh>
          </geometry>
        </visual>
        <self_collide>0</self_collide>
        <kinematic>0</kinematic>
      </link>
      <joint name='r_shoulder_pitch_joint' type='revolute'>
        <child>bender/r_shoulder_pitch_link</child>
        <parent>bender/base_link</parent>
        <axis>
          <xyz>0 -1 0</xyz>
          <limit>
            <lower>-1.53397</lower>
            <upper>1.94815</upper>
            <effort>10.85</effort>
            <velocity>5.23599</velocity>
          </limit>
          <dynamics>
            <damping>0.15</damping>
            <friction>0.3</friction>
            <spring_reference>0</spring_reference>
            <spring_stiffness>0</spring_stiffness>
          </dynamics>
          <use_parent_model_frame>1</use_parent_model_frame>
        </axis>
      </joint>
      <link name='bender/r_shoulder_roll_link'>
        <pose frame=''>-0.033078 -0.267681 1.1256 0 -0 0</pose>
        <inertial>
          <pose frame=''>0.046779 -9e-06 -0.11466 0 -0 0</pose>
          <mass>0.16104</mass>
          <inertia>
            <ixx>0.00050901</ixx>
            <ixy>6.2439e-09</ixy>
            <ixz>0.00010534</ixz>
            <iyy>0.00055051</iyy>
            <iyz>-6.7534e-08</iyz>
            <izz>0.00011428</izz>
          </inertia>
        </inertial>
        <collision name='bender/r_shoulder_roll_link_collision'>
          <pose frame=''>0.04 0 -0.075 0 -0.25 0</pose>
          <geometry>
            <box>
              <size>0.05 0.035 0.18</size>
            </box>
          </geometry>
          <max_contacts>10</max_contacts>
          <surface>
            <contact>
              <ode/>
            </contact>
            <bounce/>
            <friction>
              <torsional>
                <ode/>
              </torsional>
              <ode/>
            </friction>
          </surface>
        </collision>
        <visual name='bender/r_shoulder_roll_link_visual'>
          <pose frame=''>0 0 0 -1.5708 0 0</pose>
          <geometry>
            <mesh>
              <scale>1 1 1</scale>
              <uri>/home/giovanni/uchile_ws/ros/bender/base_ws/src/bender_core/bender_description/meshes/visual/shoulder_roll.dae</uri>
            </mesh>
          </geometry>
        </visual>
        <self_collide>0</self_collide>
        <kinematic>0</kinematic>
      </link>
      <joint name='r_shoulder_roll_joint' type='revolute'>
        <child>bender/r_shoulder_roll_link</child>
        <parent>bender/r_shoulder_pitch_link</parent>
        <axis>
          <xyz>-1 0 0</xyz>
          <limit>
            <lower>-0.23776</lower>
            <upper>1.51096</upper>
            <effort>10.85</effort>
            <velocity>5.23599</velocity>
          </limit>
          <dynamics>
            <damping>0.15</damping>
            <friction>0.3</friction>
            <spring_reference>0</spring_reference>
            <spring_stiffness>0</spring_stiffness>
          </dynamics>
          <use_parent_model_frame>1</use_parent_model_frame>
        </axis>
      </joint>
      <link name='bender/r_shoulder_yaw_link'>
        <pose frame=''>0.000842 -0.267681 0.9895 0 -0 0</pose>
        <inertial>
          <pose frame=''>-0.017828 -0.000166 -0.14148 0 -0 0</pose>
          <mass>0.17312</mass>
          <inertia>
            <ixx>0.0008473</ixx>
            <ixy>7.9313e-08</ixy>
            <ixz>3.4804e-05</ixz>
            <iyy>0.00084882</iyy>
            <iyz>-3.1674e-06</iyz>
            <izz>6.5527e-05</izz>
          </inertia>
        </inertial>
        <collision name='bender/r_shoulder_yaw_link_collision'>
          <pose frame=''>-0.015 0 -0.115 0 -0 0</pose>
          <geometry>
            <box>
              <size>0.05 0.035 0.23</size>
            </box>
          </geometry>
          <max_contacts>10</max_contacts>
          <surface>
            <contact>
              <ode/>
            </contact>
            <bounce/>
            <friction>
              <torsional>
                <ode/>
              </torsional>
              <ode/>
            </friction>
          </surface>
        </collision>
        <visual name='bender/r_shoulder_yaw_link_visual'>
          <pose frame=''>0 0 0 -1.5708 0 0</pose>
          <geometry>
            <mesh>
              <scale>1 1 1</scale>
              <uri>/home/giovanni/uchile_ws/ros/bender/base_ws/src/bender_core/bender_description/meshes/visual/shoulder_yaw.dae</uri>
            </mesh>
          </geometry>
        </visual>
        <self_collide>0</self_collide>
        <kinematic>0</kinematic>
      </link>
      <joint name='r_shoulder_yaw_joint' type='revolute'>
        <child>bender/r_shoulder_yaw_link</child>
        <parent>bender/r_shoulder_roll_link</parent>
        <axis>
          <xyz>0 0 1</xyz>
          <limit>
            <lower>-1.48284</lower>
            <upper>1.38057</upper>
            <effort>4.44054</effort>
            <velocity>5.23599</velocity>
          </limit>
          <dynamics>
            <damping>0.15</damping>
            <friction>0.3</friction>
            <spring_reference>0</spring_reference>
            <spring_stiffness>0</spring_stiffness>
          </dynamics>
          <use_parent_model_frame>1</use_parent_model_frame>
        </axis>
      </joint>
      <link name='bender/r_elbow_pitch_link'>
        <pose frame=''>-0.015056 -0.245336 0.7795 0 -0 0</pose>
        <inertial>
          <pose frame=''>0.006745 -0.022124 -0.059507 0 -0 0</pose>
          <mass>0.14398</mass>
          <inertia>
            <ixx>0.00012531</ixx>
            <ixy>1.5127e-07</ixy>
            <ixz>3.5125e-06</ixz>
            <iyy>0.00011254</iyy>
            <iyz>-1.3346e-06</iyz>
            <izz>8.6928e-05</izz>
          </inertia>
        </inertial>
        <collision name='bender/r_elbow_pitch_link_collision'>
          <pose frame=''>0.015 -0.025 -0.05 0 -0 0</pose>
          <geometry>
            <box>
              <size>0.05 0.07 0.1</size>
            </box>
          </geometry>
          <max_contacts>10</max_contacts>
          <surface>
            <contact>
              <ode/>
            </contact>
            <bounce/>
            <friction>
              <torsional>
                <ode/>
              </torsional>
              <ode/>
            </friction>
          </surface>
        </collision>
        <visual name='bender/r_elbow_pitch_link_visual'>
          <pose frame=''>0 0 0 -1.5708 0 0</pose>
          <geometry>
            <mesh>
              <scale>1 1 1</scale>
              <uri>/home/giovanni/uchile_ws/ros/bender/base_ws/src/bender_core/bender_description/meshes/visual/elbow_pitch.dae</uri>
            </mesh>
          </geometry>
        </visual>
        <self_collide>0</self_collide>
        <kinematic>0</kinematic>
      </link>
      <joint name='r_elbow_pitch_joint' type='revolute'>
        <child>bender/r_elbow_pitch_link</child>
        <parent>bender/r_shoulder_yaw_link</parent>
        <axis>
          <xyz>0 -1 0</xyz>
          <limit>
            <lower>-1.0431</lower>
            <upper>1.90213</upper>
            <effort>10.85</effort>
            <velocity>5.23599</velocity>
          </limit>
          <dynamics>
            <damping>0.15</damping>
            <friction>0.3</friction>
            <spring_reference>0</spring_reference>
            <spring_stiffness>0</spring_stiffness>
          </dynamics>
          <use_parent_model_frame>1</use_parent_model_frame>
        </axis>
      </joint>
      <link name='bender/r_elbow_yaw_link'>
        <pose frame=''>-0.028656 -0.267681 0.7276 0 -0 0</pose>
        <inertial>
          <pose frame=''>-0.0196 8.5e-05 -0.17771 0 -0 0</pose>
          <mass>0.1675</mass>
          <inertia>
            <ixx>0.0017359</ixx>
            <ixy>-4.8507e-09</ixy>
            <ixz>3.1814e-05</ixz>
            <iyy>0.0017441</iyy>
            <iyz>2.1946e-07</iyz>
            <izz>5.881e-05</izz>
          </inertia>
        </inertial>
        <collision name='bender/r_elbow_yaw_link_collision'>
          <pose frame=''>-0.015 0 -0.15 0 -0 0</pose>
          <geometry>
            <box>
              <size>0.05 0.035 0.32</size>
            </box>
          </geometry>
          <max_contacts>10</max_contacts>
          <surface>
            <contact>
              <ode/>
            </contact>
            <bounce/>
            <friction>
              <torsional>
                <ode/>
              </torsional>
              <ode/>
            </friction>
          </surface>
        </collision>
        <visual name='bender/r_elbow_yaw_link_visual'>
          <pose frame=''>0 0 0 -1.5708 0 0</pose>
          <geometry>
            <mesh>
              <scale>1 1 1</scale>
              <uri>/home/giovanni/uchile_ws/ros/bender/base_ws/src/bender_core/bender_description/meshes/visual/elbow_yaw.dae</uri>
            </mesh>
          </geometry>
        </visual>
        <self_collide>0</self_collide>
        <kinematic>0</kinematic>
      </link>
      <joint name='r_elbow_yaw_joint' type='revolute'>
        <child>bender/r_elbow_yaw_link</child>
        <parent>bender/r_elbow_pitch_link</parent>
        <axis>
          <xyz>0 0 1</xyz>
          <limit>
            <lower>-1.20161</lower>
            <upper>1.30387</upper>
            <effort>4.44054</effort>
            <velocity>5.23599</velocity>
          </limit>
          <dynamics>
            <damping>0.15</damping>
            <friction>0.3</friction>
            <spring_reference>0</spring_reference>
            <spring_stiffness>0</spring_stiffness>
          </dynamics>
          <use_parent_model_frame>1</use_parent_model_frame>
        </axis>
      </joint>
      <link name='bender/r_wrist_pitch_link'>
        <pose frame=''>-0.046877 -0.250366 0.4251 0 -0 0</pose>
        <inertial>
          <pose frame=''>3.9e-05 -0.017418 -0.05204 0 -0 0</pose>
          <mass>0.18207</mass>
          <inertia>
            <ixx>0.000168472</ixx>
            <ixy>-2.80655e-11</ixy>
            <ixz>-2.03417e-07</ixz>
            <iyy>0.000108722</iyy>
            <iyz>6.41597e-07</iyz>
            <izz>0.000117584</izz>
          </inertia>
        </inertial>
        <collision name='bender/r_wrist_pitch_link_collision'>
          <pose frame=''>0 -0.02 -0.05 0 -0 0</pose>
          <geometry>
            <box>
              <size>0.04 0.08 0.07</size>
            </box>
          </geometry>
          <max_contacts>10</max_contacts>
          <surface>
            <contact>
              <ode/>
            </contact>
            <bounce/>
            <friction>
              <torsional>
                <ode/>
              </torsional>
              <ode/>
            </friction>
          </surface>
        </collision>
        <visual name='bender/r_wrist_pitch_link_visual'>
          <pose frame=''>0 0 0 -1.5708 0 0</pose>
          <geometry>
            <mesh>
              <scale>1 1 1</scale>
              <uri>/home/giovanni/uchile_ws/ros/bender/base_ws/src/bender_core/bender_description/meshes/visual/wrist_pitch.dae</uri>
            </mesh>
          </geometry>
        </visual>
        <self_collide>0</self_collide>
        <kinematic>0</kinematic>
      </link>
      <joint name='r_wrist_pitch_joint' type='revolute'>
        <child>bender/r_wrist_pitch_link</child>
        <parent>bender/r_elbow_yaw_link</parent>
        <axis>
          <xyz>0 -1 0</xyz>
          <limit>
            <lower>-1.07378</lower>
            <upper>1.22717</upper>
            <effort>3.1</effort>
            <velocity>5.23599</velocity>
          </limit>
          <dynamics>
            <damping>0.15</damping>
            <friction>0.3</friction>
            <spring_reference>0</spring_reference>
            <spring_stiffness>0</spring_stiffness>
          </dynamics>
          <use_parent_model_frame>1</use_parent_model_frame>
        </axis>
      </joint>
      <link name='bender/r_ext_finger_link'>
        <pose frame=''>-0.055127 -0.285916 0.3457 0.523599 0 -3.14159</pose>
        <inertial>
          <pose frame=''>-0.018 -0.03 -0.07 -0.523599 0 0</pose>
          <mass>0.16</mass>
          <inertia>
            <ixx>0.000357667</ixx>
            <ixy>0</ixy>
            <ixz>0</ixz>
            <iyy>0.000374667</iyy>
            <iyz>0</iyz>
            <izz>4.96667e-05</izz>
          </inertia>
        </inertial>
        <collision name='bender/r_ext_finger_link_collision'>
          <pose frame=''>0.0355 0 0.011 0 -0 0</pose>
          <geometry>
            <mesh>
              <scale>1 1 1</scale>
              <uri>/home/giovanni/uchile_ws/ros/bender/base_ws/src/bender_core/bender_description/meshes/collision/finger.stl</uri>
            </mesh>
          </geometry>
          <surface>
            <contact>
              <ode>
                <kp>1e+06</kp>
                <kd>1</kd>
                <min_depth>0.005</min_depth>
              </ode>
            </contact>
            <friction>
              <ode>
                <mu>1</mu>
                <mu2>1</mu2>
              </ode>
              <torsional>
                <ode/>
              </torsional>
            </friction>
            <bounce/>
          </surface>
          <max_contacts>10</max_contacts>
        </collision>
        <visual name='bender/r_ext_finger_link_visual'>
          <pose frame=''>0.008 0 0 0 -0 0</pose>
          <geometry>
            <mesh>
              <scale>1 1 1</scale>
              <uri>/home/giovanni/uchile_ws/ros/bender/base_ws/src/bender_core/bender_description/meshes/visual/two_finger.stl</uri>
            </mesh>
          </geometry>
          <material>
            <script>
              <name>Gazebo/DarkGrey</name>
              <uri>file://media/materials/scripts/gazebo.material</uri>
            </script>
          </material>
        </visual>
        <gravity>1</gravity>
        <velocity_decay/>
        <self_collide>1</self_collide>
        <kinematic>0</kinematic>
      </link>
      <joint name='r_ext_finger_joint' type='revolute'>
        <child>bender/r_ext_finger_link</child>
        <parent>bender/r_wrist_pitch_link</parent>
        <axis>
          <xyz>-1 0 0</xyz>
          <limit>
            <lower>-0.02556</lower>
            <upper>0.69029</upper>
            <effort>3.1</effort>
            <velocity>10</velocity>
          </limit>
          <dynamics>
            <damping>0.2</damping>
            <friction>1</friction>
            <spring_reference>0</spring_reference>
            <spring_stiffness>0</spring_stiffness>
          </dynamics>
          <use_parent_model_frame>1</use_parent_model_frame>
        </axis>
      </joint>
      <link name='bender/r_int_finger_link'>
        <pose frame=''>-0.027627 -0.249516 0.3457 0.523599 -0 0</pose>
        <inertial>
          <pose frame=''>-0.018 -0.03 -0.07 -0.523599 0 0</pose>
          <mass>0.16</mass>
          <inertia>
            <ixx>0.000357667</ixx>
            <ixy>0</ixy>
            <ixz>0</ixz>
            <iyy>0.000374667</iyy>
            <iyz>0</iyz>
            <izz>4.96667e-05</izz>
          </inertia>
        </inertial>
        <collision name='bender/r_int_finger_link_collision'>
          <pose frame=''>0.0275 0 0.011 0 -0 0</pose>
          <geometry>
            <mesh>
              <scale>1 1 1</scale>
              <uri>/home/giovanni/uchile_ws/ros/bender/base_ws/src/bender_core/bender_description/meshes/collision/finger.stl</uri>
            </mesh>
          </geometry>
          <surface>
            <contact>
              <ode>
                <kp>1e+06</kp>
                <kd>1</kd>
                <min_depth>0.005</min_depth>
              </ode>
            </contact>
            <friction>
              <ode>
                <mu>1</mu>
                <mu2>1</mu2>
              </ode>
              <torsional>
                <ode/>
              </torsional>
            </friction>
            <bounce/>
          </surface>
          <max_contacts>10</max_contacts>
        </collision>
        <visual name='bender/r_int_finger_link_visual'>
          <pose frame=''>0 0 0 0 -0 0</pose>
          <geometry>
            <mesh>
              <scale>1 1 1</scale>
              <uri>/home/giovanni/uchile_ws/ros/bender/base_ws/src/bender_core/bender_description/meshes/visual/two_finger.stl</uri>
            </mesh>
          </geometry>
          <material>
            <script>
              <name>Gazebo/DarkGrey</name>
              <uri>file://media/materials/scripts/gazebo.material</uri>
            </script>
          </material>
        </visual>
        <gravity>1</gravity>
        <velocity_decay/>
        <self_collide>1</self_collide>
        <kinematic>0</kinematic>
      </link>
      <joint name='r_int_finger_joint' type='revolute'>
        <child>bender/r_int_finger_link</child>
        <parent>bender/r_wrist_pitch_link</parent>
        <axis>
          <xyz>1 0 0</xyz>
          <limit>
            <lower>-0.02556</lower>
            <upper>0.69029</upper>
            <effort>3.1</effort>
            <velocity>10</velocity>
          </limit>
          <dynamics>
            <damping>0.2</damping>
            <friction>1</friction>
            <spring_reference>0</spring_reference>
            <spring_stiffness>0</spring_stiffness>
          </dynamics>
          <use_parent_model_frame>1</use_parent_model_frame>
        </axis>
      </joint>
      <plugin name='skid_steer_drive_controller' filename='libgazebo_ros_skid_steer_drive.so'>
        <robotNamespace>bender/nav</robotNamespace>
        <updateRate>50.0</updateRate>
        <leftFrontJoint>front_left_wheel_joint</leftFrontJoint>
        <rightFrontJoint>front_right_wheel_joint</rightFrontJoint>
        <leftRearJoint>rear_left_wheel_joint</leftRearJoint>
        <rightRearJoint>rear_right_wheel_joint</rightRearJoint>
        <wheelSeparation>0.4</wheelSeparation>
        <wheelDiameter>0.215</wheelDiameter>
        <robotBaseFrame>bender/base_link</robotBaseFrame>
        <torque>400</torque>
        <MaxForce>10.0</MaxForce>
        <commandTopic>base/cmd_vel</commandTopic>
        <odometryTopic>odom</odometryTopic>
        <odometryFrame>bender/odom</odometryFrame>
        <broadcastTF>1</broadcastTF>
      </plugin>
      <static>0</static>
      <plugin name='ros_control' filename='libgazebo_ros_control.so'>
        <robotNamespace>bender/</robotNamespace>
      </plugin>
      <pose frame=''>0 0 0 0 -0 0</pose>
    </model>
    <model name='pringles_red'>
      <pose frame=''>0.606763 -0.079973 0.11525 0 -0 0</pose>
      <link name='link'>
        <inertial>
          <mass>0.2</mass>
          <inertia>
            <ixx>0.000908</ixx>
            <ixy>0</ixy>
            <ixz>0</ixz>
            <iyy>0.000908</iyy>
            <iyz>0</iyz>
            <izz>0.0002025</izz>
          </inertia>
        </inertial>
        <collision name='collision'>
          <geometry>
            <cylinder>
              <radius>0.04</radius>
              <length>0.235</length>
            </cylinder>
          </geometry>
          <surface>
            <contact>
              <ode>
                <min_depth>0.005</min_depth>
              </ode>
            </contact>
            <friction>
              <ode>
                <mu>0.9</mu>
                <mu2>0.9</mu2>
              </ode>
              <torsional>
                <ode/>
              </torsional>
            </friction>
            <bounce/>
          </surface>
          <max_contacts>10</max_contacts>
        </collision>
        <visual name='visual'>
          <pose frame=''>0 0 0 3.1415 -0 0</pose>
          <geometry>
            <cylinder>
              <radius>0.04</radius>
              <length>0.235</length>
            </cylinder>
          </geometry>
          <material>
            <script>
              <uri>model://pringles_red/material/scripts</uri>
              <uri>model://pringles_red/material/textures</uri>
              <name>Custom/PringlesRed</name>
            </script>
          </material>
        </visual>
        <self_collide>0</self_collide>
        <kinematic>0</kinematic>
      </link>
    </model>
  </world>
</sdf>
