<?xml version="1.0"?>
<robot
  xmlns:xacro="http://www.ros.org/wiki/xacro"
  name="base">

  <xacro:macro name="base_wheel" params="name parent front reflect prefix">
    <joint
      name="${name}_wheel_joint"
      type="continuous">
        <!-- Front case -->
        <xacro:if value="${(front+1)/2}">
          <origin
            xyz="0.11798 ${-reflect*0.1575} 0.031"
            rpy="0 0 0" />
        </xacro:if>
        <!-- Rear case -->
        <xacro:unless value="${(front+1)/2}">
          <origin
            xyz="-0.13202 ${-reflect*0.1575} 0.031"
            rpy="0 0 0" />
        </xacro:unless>
      <parent
        link="${parent}" />
      <child
        link="${prefix}${name}_wheel" />
      <axis
        xyz="0 1 0" />
    </joint>
    
    <link
      name="${prefix}${name}_wheel">
      <inertial>
        <origin
          xyz="0 ${- reflect * 0.025} 0"
          rpy="${M_PI/2} 0 0" />
        <cylinder_inertia_def length="0.05" radius="0.1" mass="50.0"/>
        <mass value="50.0" />
      </inertial>
      <visual>
        <xacro:if value="${(reflect+1)/2}">
          <origin
            xyz="0 0 0"
            rpy="0 0 0" />
        </xacro:if>
        <xacro:unless value="${(reflect+1)/2}">
          <origin
            xyz="0 0 0"
            rpy="${M_PI} 0 0" />
        </xacro:unless>
        <geometry>
          <mesh
            filename="package://bender_description/meshes/visual/wheel.dae" />
        </geometry>
        <material name="Grey3" />
      </visual>
      <collision>
        <origin
          xyz="0 ${- reflect * 0.025} 0"
          rpy="-${M_PI/2} 0 0" />
        <geometry>
          <cylinder length="0.05" radius="0.1"/>
        </geometry>
      </collision>
    </link>
    <xacro:joint_transmission joint="${name}_wheel_joint" />
    <xacro:gazebo_wheel_link link="${prefix}${name}_wheel" reflect="${reflect}"/>
  </xacro:macro>

  <xacro:macro name="base" params="prefix">
    <!-- Macro for wheels -->
    <xacro:base_wheel parent="${prefix}mobile_base_link" name="front_right" front="1" reflect="1" prefix="${prefix}" />
    <xacro:base_wheel parent="${prefix}mobile_base_link" name="rear_right" front="-1" reflect="1" prefix="${prefix}" />
    <xacro:base_wheel parent="${prefix}mobile_base_link" name="front_left" front="1" reflect="-1" prefix="${prefix}" />
    <xacro:base_wheel parent="${prefix}mobile_base_link" name="rear_left" front="-1" reflect="-1" prefix="${prefix}" />

    
    <!-- Gazebo P3AT Controller and transmissions-->
    <xacro:p3at_controller ns="${prefix}nav" prefix="${prefix}"/>

    <link name="${prefix}base_link" />
    <joint
      name="mobile_base_fixed_joint"
      type="fixed">
      <origin
        xyz="0 0 0"
        rpy="0 0 0" />
      <parent
        link="${prefix}base_link" />
      <child
        link="${prefix}mobile_base_link" />
    </joint>
    <link
      name="${prefix}mobile_base_link">
      <inertial>
        <origin
          xyz="0 0 0.1"
          rpy="0 0 0" />
        <mass value="12.0" />
        <cuboid_inertia_def x="0.54" y="0.38" z="0.2" mass="12.0"/>
      </inertial>
      <visual>
        <origin
          xyz="0 0 0"
          rpy="0 0 0" />
        <geometry>
          <mesh
            filename="package://bender_description/meshes/visual/base.dae" />
        </geometry>
        <material
          name="">
          <color
            rgba="0.1 0.1 0.1 1" />
        </material>
      </visual>
      <collision>
        <origin
          xyz="0 0 0.1"
          rpy="0 0 0" />
        <geometry>
          <box size="0.54 0.38 0.2"/>
        </geometry>
      </collision>
    </link>
    
    <!-- Base footprint -->
    <link name="${prefix}base_footprint">
       <xacro:dummy_inertial/>
    </link>
    <joint
      name="base_footprint_fixed_joint"
      type="fixed">
      <origin
        xyz="0 0 -0.069"
        rpy="0 0 0" />
      <parent
        link="${prefix}base_link" />
      <child
        link="${prefix}base_footprint" />
      <axis
        xyz="0 0 0" />
    </joint>
    
    <!-- Torso base link -->
    <link
      name="${prefix}torso_base_link">
       <xacro:dummy_inertial/>
    </link>
    <joint
      name="torso_base_fixed_joint"
      type="fixed">
      <origin
        xyz="-0.0040583 0.00081911 0.195"
        rpy="0 0 0" />
      <parent
        link="${prefix}base_link" />
      <child
        link="${prefix}torso_base_link" />
      <axis
        xyz="0 0 0" />
    </joint>

  </xacro:macro>

</robot>