<?xml version="1.0"?>
<robot
  xmlns:xacro="http://www.ros.org/wiki/xacro"
  name="arm">

  <!-- Soft margin 5 deg -->
  <xacro:property name="soft_margin" value="${M_PI/36}" />

  <!-- Generado con script desde configuracion de motores Dynamixel -->
  <xacro:property name="elbow_yaw_joint_upper" value="1.30387" />
  <xacro:property name="elbow_yaw_joint_lower" value="-1.20161" />

  <xacro:property name="shoulder_yaw_joint_upper" value="1.38057" />
  <xacro:property name="shoulder_yaw_joint_lower" value="-1.48284" />

  <xacro:property name="shoulder_pitch_joint_upper" value="1.94815" />
  <xacro:property name="shoulder_pitch_joint_lower" value="-1.53397" />

  <xacro:property name="wrist_pitch_joint_upper" value="1.22717" />
  <xacro:property name="wrist_pitch_joint_lower" value="-1.07378" />

  <xacro:property name="elbow_pitch_joint_upper" value="1.86378" />
  <xacro:property name="elbow_pitch_joint_lower" value="-1.03543" />

  <xacro:property name="shoulder_roll_joint_upper" value="1.51096" />
  <xacro:property name="shoulder_roll_joint_lower" value="-0.23776" />

  <!-- Torque -->
  <xacro:property name="shoulder_pitch_torque" value="${mx106_torque}" />
  <xacro:property name="shoulder_roll_torque"  value="${mx106_torque}" />
  <xacro:property name="shoulder_yaw_torque"   value="${rx64_torque}" />
  <xacro:property name="elbow_pitch_torque"    value="${mx106_torque}" />
  <xacro:property name="elbow_yaw_torque"      value="${rx64_torque}" />
  <xacro:property name="wrist_pitch_torque"    value="${rx28_torque}" />
  
  <xacro:macro name="arm" params="side parent reflect prefix">

    <!-- Transmissions -->
    <xacro:joint_transmission joint="${side}_shoulder_pitch_joint"/>
    <xacro:joint_transmission joint="${side}_shoulder_roll_joint"/>
    <xacro:joint_transmission joint="${side}_shoulder_yaw_joint"/>
    <xacro:joint_transmission joint="${side}_elbow_pitch_joint"/>
    <xacro:joint_transmission joint="${side}_elbow_yaw_joint"/>
    <xacro:joint_transmission joint="${side}_wrist_pitch_joint"/>
    
    <!-- Base fixed joint and link -->
    <joint
      name="${side}_arm_base_fixed_joint"
      type="fixed">
      <origin
        xyz="0 0 0"
        rpy="0 0 0" />
      <parent
        link="${parent}" />
      <child
        link="${prefix}${side}_arm_base_link" />
      <axis
        xyz="0 0 0" />
    </joint>
    <link
      name="${prefix}${side}_arm_base_link">
      <inertial>
        <origin
          xyz="3.1697E-06 -0.017088 0.00063087"
          rpy="0 0 0" />
        <mass
          value="0.17471" />
        <inertia
          ixx="0.00037909"
          ixy="7.4755E-09"
          ixz="2.8692E-09"
          iyy="0.00040178"
          iyz="8.0104E-07"
          izz="9.5869E-05" />
      </inertial>
      <visual>
        <xacro:if value="${(reflect+1)/2}">
        <origin
          xyz="0 0 0"
          rpy="${-M_PI/2} 0 ${M_PI}" />
        </xacro:if >
        <xacro:unless value="${(reflect+1)/2}">
        <origin
          xyz="0 0 0"
          rpy="${-M_PI/2} 0 0" />
        </xacro:unless >

        <geometry>
          <mesh
            filename="package://bender_description/meshes/visual/shoulder_base_link.dae" />
        </geometry>
        <material
          name="">
          <color
            rgba="0.1 0.1 0.1 1" />
        </material>
      </visual>
      <collision>
        <origin
          xyz="0 ${reflect * 0.03} 0"
          rpy="0 0 0" />
        <geometry>
          <box size="0.07 0.06 0.17"/>
        </geometry>
      </collision>
    </link>
    
    <!-- Shoulder pitch -->
    <link
      name="${prefix}${side}_shoulder_pitch_link">
      <inertial>
        <origin
          xyz="0.00023251 0.019812 -0.013482"
          rpy="0 0 0" />
        <mass
          value="0.17152" />
        <inertia
          ixx="0.00010991"
          ixy="-5.6413E-07"
          ixz="1.0935E-06"
          iyy="0.00010993"
          iyz="1.8807E-06"
          izz="8.8167E-05" />
      </inertial>
      <visual>
        <xacro:if value="${(reflect+1)/2}">
        <origin
          xyz="0 0 0"
          rpy="${-M_PI/2} 0 ${M_PI}" />
        </xacro:if >
        <xacro:unless value="${(reflect+1)/2}">
        <origin
          xyz="0 0 0"
          rpy="${-M_PI/2} 0 0" />
        </xacro:unless >
        <geometry>
          <mesh
            filename="package://bender_description/meshes/visual/shoulder_pitch.dae" />
        </geometry>
        <material
          name="">
          <color
            rgba="0.1 0.1 0.1 1" />
        </material>
      </visual>
      <collision>
        <origin
          xyz="0 ${- reflect * 0.025} -0.01"
          rpy="0 0 0" />
        <geometry>
          <box size="0.05 0.05 0.07"/>
        </geometry>
      </collision>
    </link>
    <joint
      name="${side}_shoulder_pitch_joint"
      type="revolute">
      <origin
        xyz="0 ${- reflect * 0.0046} 0.0176"
        rpy="0 0 0" />
      <parent
        link="${prefix}${side}_arm_base_link" />
      <child
        link="${prefix}${side}_shoulder_pitch_link" />
      <axis
        xyz="0 -1 0" />
      <limit
        effort="${shoulder_pitch_torque}"
        lower="${shoulder_pitch_joint_lower}"
        upper="${shoulder_pitch_joint_upper}"
        velocity="${vel_arm * M_PI / 180}"/>
      <dynamics damping="${dxl_damping}" friction="${dxl_friction}" />
      <safety_controller soft_lower_limit="${shoulder_pitch_joint_lower-soft_margin}" soft_upper_limit="${shoulder_pitch_joint_upper+soft_margin}" k_position="30" k_velocity="30"/>
    </joint>
    
    <!-- Shoulder roll -->
    <link
      name="${prefix}${side}_shoulder_roll_link">
      <inertial>
        <origin
          xyz="0.046779 -9.3259E-06 -0.11466"
          rpy="0 0 0" />
        <mass
          value="0.16104" />
        <inertia
          ixx="0.00050901"
          ixy="6.2439E-09"
          ixz="0.00010534"
          iyy="0.00055051"
          iyz="-6.7534E-08"
          izz="0.00011428" />
      </inertial>
      <visual>
        <origin
          xyz="0 0 0"
          rpy="${-M_PI/2} 0 0" />
        <geometry>
          <mesh
            filename="package://bender_description/meshes/visual/shoulder_roll.dae" />
        </geometry>
        <material
          name="">
          <color
            rgba="0.1 0.1 0.1 1" />
        </material>
      </visual>
      <collision>
        <origin
          xyz="0.04 0 -0.075"
          rpy="0 -0.25 0" />
        <geometry>
          <box size="0.05 0.035 0.18"/>
        </geometry>
      </collision>
    </link>
    <joint
      name="${side}_shoulder_roll_joint"
      type="revolute">
      <origin
        xyz="-0.02402 ${- reflect * 0.0339} -0.03"
        rpy="0 0 0" />
      <parent
        link="${prefix}${side}_shoulder_pitch_link" />
      <child
        link="${prefix}${side}_shoulder_roll_link" />
      <axis
        xyz="${- reflect} 0 0" />
      <limit
        lower="${shoulder_roll_joint_lower}"
        upper="${shoulder_roll_joint_upper}"
        effort="${shoulder_roll_torque}"
        velocity="${vel_arm * M_PI / 180}" />
      <dynamics damping="${dxl_damping}" friction="${dxl_friction}" />
      <safety_controller soft_lower_limit="${shoulder_roll_joint_lower-soft_margin}" soft_upper_limit="${shoulder_roll_joint_upper+soft_margin}" k_position="30" k_velocity="30"/>
    </joint>

    <!-- Shoulder yaw -->
    <link
      name="${prefix}${side}_shoulder_yaw_link">
      <inertial>
        <origin
          xyz="-0.017828 -0.00016574 -0.14148"
          rpy="0 0 0" />
        <mass
          value="0.17312" />
        <inertia
          ixx="0.0008473"
          ixy="7.9313E-08"
          ixz="3.4804E-05"
          iyy="0.00084882"
          iyz="-3.1674E-06"
          izz="6.5527E-05" />
      </inertial>
      <visual>
        <origin
          xyz="0 0 0"
          rpy="${-M_PI/2} 0 0" />
        <geometry>
          <mesh
            filename="package://bender_description/meshes/visual/shoulder_yaw.dae" />
        </geometry>
        <material
          name="">
          <color
            rgba="0.1 0.1 0.1 1" />
        </material>
      </visual>
      <collision>
        <origin
          xyz="-0.015 0 -0.115"
          rpy="0 0 0" />
        <geometry>
          <box size="0.05 0.035 0.23"/>
        </geometry>
      </collision>
    </link>
    <joint
      name="${side}_shoulder_yaw_joint"
      type="revolute">
      <origin
        xyz="0.03392 0 -0.1361"
        rpy="0 0 0" />
      <parent
        link="${prefix}${side}_shoulder_roll_link" />
      <child
        link="${prefix}${side}_shoulder_yaw_link" />
      <axis
        xyz="0 0 ${reflect}" />
      <limit
        lower="${shoulder_yaw_joint_lower}"
        upper="${shoulder_yaw_joint_upper}"
        effort="${shoulder_yaw_torque}"
        velocity="${vel_arm * M_PI / 180}" />
      <dynamics damping="${dxl_damping}" friction="${dxl_friction}" />
      <safety_controller soft_lower_limit="${shoulder_yaw_joint_lower-soft_margin}" soft_upper_limit="${shoulder_yaw_joint_upper+soft_margin}" k_position="30" k_velocity="30"/>
    </joint>
    
    <!-- Elbow pitch -->
    <link
      name="${prefix}${side}_elbow_pitch_link">
      <inertial>
        <origin
          xyz="0.0067447 -0.022124 -0.059507"
          rpy="0 0 0" />
        <mass
          value="0.14398" />
        <inertia
          ixx="0.00012531"
          ixy="1.5127E-07"
          ixz="3.5125E-06"
          iyy="0.00011254"
          iyz="-1.3346E-06"
          izz="8.6928E-05" />
      </inertial>
      <visual>
        <origin
          xyz="0 0 0"
          rpy="${-M_PI/2} 0 0" />
        <geometry>
          <mesh
            filename="package://bender_description/meshes/visual/elbow_pitch.dae" />
        </geometry>
        <material
          name="">
          <color
            rgba="0.1 0.1 0.1 1" />
        </material>
      </visual>
      <collision>
        <origin
          xyz="0.015 -0.025 -0.05"
          rpy="0 0 0" />
        <geometry>
          <box size="0.05 0.07 0.10"/>
        </geometry>
      </collision>
    </link>
    <joint
      name="${side}_elbow_pitch_joint"
      type="revolute">
      <origin
        xyz="-0.015898 0.022345 -0.21"
        rpy="0 0 0" />
      <parent
        link="${prefix}${side}_shoulder_yaw_link" />
      <child
        link="${prefix}${side}_elbow_pitch_link" />
      <axis
        xyz="0 -1 0" />
      <limit
        lower="${elbow_pitch_joint_lower}"
        upper="${elbow_pitch_joint_upper}"
        effort="${elbow_pitch_torque}"
        velocity="${vel_arm * M_PI / 180}" />
      <dynamics damping="${dxl_damping}" friction="${dxl_friction}" />
      <safety_controller soft_lower_limit="${elbow_pitch_joint_lower-soft_margin}" soft_upper_limit="${elbow_pitch_joint_upper+soft_margin}" k_position="30" k_velocity="30"/>
    </joint>

    <!-- Elbow yaw -->
    <link
      name="${prefix}${side}_elbow_yaw_link">
      <inertial>
        <origin
          xyz="-0.0196 8.4626E-05 -0.17771"
          rpy="0 0 0" />
        <mass
          value="0.1675" />
        <inertia
          ixx="0.0017359"
          ixy="-4.8507E-09"
          ixz="3.1814E-05"
          iyy="0.0017441"
          iyz="2.1946E-07"
          izz="5.881E-05" />
      </inertial>
      <visual>
        <origin
          xyz="0 0 0"
          rpy="${-M_PI/2} 0 0" />
        <geometry>
          <mesh
            filename="package://bender_description/meshes/visual/elbow_yaw.dae" />
        </geometry>
        <material
          name="">
          <color
            rgba="0.1 0.1 0.1 1" />
        </material>
      </visual>
      <collision>
        <origin
          xyz="-0.015 0 -0.15"
          rpy="0 0 0" />
        <geometry>
          <box size="0.05 0.035 0.32"/>
        </geometry>
      </collision>
    </link>
    <joint
      name="${side}_elbow_yaw_joint"
      type="revolute">
      <origin
        xyz="-0.0136 -0.022345 -0.0519"
        rpy="0 0 0" />
      <parent
        link="${prefix}${side}_elbow_pitch_link" />
      <child
        link="${prefix}${side}_elbow_yaw_link" />
      <axis
        xyz="0 0 ${reflect}" />
      <limit
        lower="${elbow_yaw_joint_lower}"
        upper="${elbow_yaw_joint_upper}"
        effort="${elbow_yaw_torque}"
        velocity="${vel_arm * M_PI / 180}" />
      <dynamics damping="${dxl_damping}" friction="${dxl_friction}" />
      <safety_controller soft_lower_limit="${elbow_yaw_joint_lower-soft_margin}" soft_upper_limit="${elbow_yaw_joint_upper+soft_margin}" k_position="30" k_velocity="30"/>
    </joint>
    
    <!-- Wrist pitch -->
    <link
      name="${prefix}${side}_wrist_pitch_link">
      <inertial>
        <origin
          xyz="3.6806E-05 -0.017418 -0.052037"
          rpy="0 0 0" />
        <mass
          value="0.18205" />
        <inertia
          ixx="0.00016645"
          ixy="-1.9384E-12"
          ixz="-2.1393E-07"
          iyy="0.0001067"
          iyz="6.4156E-07"
          izz="0.00011557" />
      </inertial>
      <visual>
        <origin
          xyz="0 0 0"
          rpy="${-M_PI/2} 0 0" />
        <geometry>
          <mesh
            filename="package://bender_description/meshes/visual/wrist_pitch.dae" />
        </geometry>
        <material
          name="">
          <color
            rgba="0.1 0.1 0.1 1" />
        </material>
      </visual>
      <collision>
        <origin
          xyz="0 -0.02 -0.05"
          rpy="0 0 0" />
        <geometry>
          <box size="0.04 0.08 0.07"/>
        </geometry>
      </collision>
    </link>
    <joint
      name="${side}_wrist_pitch_joint"
      type="revolute">
      <origin
        xyz="-0.018221 0.017315 -0.3025"
        rpy="0 0 0" />
      <parent
        link="${prefix}${side}_elbow_yaw_link" />
      <child
        link="${prefix}${side}_wrist_pitch_link" />
      <axis
        xyz="0 -1 0" />
      <limit
        lower="${wrist_pitch_joint_lower}"
        upper="${wrist_pitch_joint_upper}"
        effort="${wrist_pitch_torque}"
        velocity="${vel_arm * M_PI / 180}" />
      <dynamics damping="${dxl_damping}" friction="${dxl_friction}" />
      <safety_controller soft_lower_limit="${wrist_pitch_joint_lower-soft_margin}" soft_upper_limit="${wrist_pitch_joint_upper+soft_margin}" k_position="30" k_velocity="30"/>
    </joint>
    
    <!-- Gripper mount -->
    <link
      name="${prefix}${side}_ext_finger_mount_link">
      <xacro:dummy_inertial/>
    </link>
    <joint
      name="${side}_ext_finger_mount_fixed_joint"
      type="fixed">
      <xacro:if value="${(reflect+1)/2}">
        <origin
          xyz="0.01925 -0.03555 -0.0794"
          rpy="0 0 0" />
      </xacro:if >
      <xacro:unless value="${(reflect+1)/2}">
        <origin
          xyz="0.01925 0.00085 -0.0794"
          rpy="0 0 0" />
      </xacro:unless >
      <parent
        link="${prefix}${side}_wrist_pitch_link" />
      <child
        link="${prefix}${side}_ext_finger_mount_link" />
      <axis
        xyz="0 0 0" />
    </joint>
    <link
      name="${prefix}${side}_int_finger_mount_link">
      <xacro:dummy_inertial/>
    </link>
    <joint
      name="${side}_int_finger_mount_fixed_joint"
      type="fixed">
      <xacro:if value="${(reflect+1)/2}">
        <origin
          xyz="0.01925 0.00085 -0.0794"
          rpy="0 0 0" />
      </xacro:if >
      <xacro:unless value="${(reflect+1)/2}">
        <origin
          xyz="0.01925 -0.03555 -0.0794"
          rpy="0 0 0" />
      </xacro:unless >
      <parent
        link="${prefix}${side}_wrist_pitch_link" />
      <child
        link="${prefix}${side}_int_finger_mount_link" />
      <axis
        xyz="0 0 0" />
    </joint>
  </xacro:macro>

</robot>