<?xml version="1.0" ?>
<!-- =================================================================================== -->
<!-- |    This document was autogenerated by xacro from bender_standart.urdf.xacro     | -->
<!-- |    EDITING THIS FILE BY HAND IS NOT RECOMMENDED                                 | -->
<!-- =================================================================================== -->
<robot name="bender" xmlns:xacro="http://ros.org/wiki/xacro">
  <!-- Parameters -->
  <!-- PI constant -->
  <!-- Dynamics -->
  <!-- Friccion -->
  <!-- Velocity -->
  <!-- Inertial cuboid element -->
  <!-- Same def that box primitive (center) -->
  <!-- Same def that box primitive -->
  <!-- Inertial sphere element -->
  <!-- Inertial cylinder element -->
  <!-- Axis along z (length) -->
  <!-- Inertial dummy element -->
  <!-- URDF Materials -->
  <material name="Grey1">
    <color rgba="0.1 0.1 0.1 1"/>
  </material>
  <material name="Grey2">
    <color rgba="0.2 0.2 0.2 1"/>
  </material>
  <material name="Grey3">
    <color rgba="0.3 0.3 0.3 1"/>
  </material>
  <material name="Body">
    <color rgba="0.85 0.85 0.85 1"/>
  </material>
  <material name="Head">
    <color rgba="0.75 0.75 0.75 1"/>
  </material>
  <!-- Gazebo macros -->
  <!-- ROS Control -->
  <!-- For Effort controllers -->
  <!-- For Position controllers -->
  <!-- No gravity links -->
  <!-- Normal links -->
  <!-- Wheel links -->
  <!-- Gripper links -->
  <!-- Depth camera plugin -->
  <!-- Base wheels plugin -->
  <!-- Laser sensor plugin -->
  <!-- Laser sensor plugin -->
  <!-- Calibration parameters, used for arms in body.urdf.xacro -->
  <!-- Normally all in 0.0 -->
  <!-- Left Arm -->
  <!-- Joint offset parameters for l_arm_base -->
  <!-- Right Arm -->
  <!-- Joint offset parameters for r_arm_base -->
  <!-- Dynamixel parameters -->
  <!-- Max torque estimation -->
  <!-- Torque/voltage relation from dynamixel_driver (this relation only works for stall torque) -->
  <!-- Friction model from "Characterization and modeling of a Dynamixel servo" by Arno Mensin (model AX12, better than nothing) -->
  <!-- Damping N.m.s/rad -->
  <!-- Friccion N.m -->
  <!-- ******** Bender Parts ******** -->
  <!-- Base -->
  <!-- Macro for wheels -->
  <joint name="front_right_wheel_joint" type="continuous">
    <!-- Front case -->
    <origin rpy="0 0 0" xyz="0.11798 -0.1575 0.031"/>
    <!-- Rear case -->
    <parent link="bendermobile_base_link"/>
    <child link="benderfront_right_wheel"/>
    <axis xyz="0 1 0"/>
  </joint>
  <link name="benderfront_right_wheel">
    <inertial>
      <origin rpy="1.57079632679 0 0" xyz="0 -0.025 0"/>
      <inertia ixx="0.135416666667" ixy="0.0" ixz="0.0" iyy="0.135416666667" iyz="0.0" izz="0.25"/>
      <mass value="50.0"/>
    </inertial>
    <visual>
      <origin rpy="0 0 0" xyz="0 0 0"/>
      <geometry>
        <mesh filename="package://bender_description/meshes/visual/wheel.dae"/>
      </geometry>
      <material name="Grey3"/>
    </visual>
    <collision>
      <origin rpy="-1.57079632679 0 0" xyz="0 -0.025 0"/>
      <geometry>
        <cylinder length="0.05" radius="0.1"/>
      </geometry>
    </collision>
  </link>
  <transmission name="front_right_wheel_joint_transmission">
    <type>transmission_interface/SimpleTransmission</type>
    <joint name="front_right_wheel_joint">
      <hardwareInterface>EffortJointInterface</hardwareInterface>
    </joint>
    <actuator name="front_right_wheel_joint_motor">
      <hardwareInterface>EffortJointInterface</hardwareInterface>
      <mechanicalReduction>1</mechanicalReduction>
    </actuator>
  </transmission>
  <gazebo reference="benderfront_right_wheel">
    <kp>1000000.0</kp>
    <!-- kp and kd for rubber -->
    <kd>100.0</kd>
    <mu1>0.8</mu1>
    <!-- was 10 -->
    <mu2>0.8</mu2>
    <!-- how to get these into <surface><friction><ode>... ?
          slip1 0.5 /slip1 
           slip2 0 /slip2 
        -->
    <fdir1>1 0 0</fdir1>
    <!-- is this correct? -->
    <maxVel>1.0</maxVel>
    <minDepth>0.00</minDepth>
  </gazebo>
  <joint name="rear_right_wheel_joint" type="continuous">
    <!-- Front case -->
    <!-- Rear case -->
    <origin rpy="0 0 0" xyz="-0.13202 -0.1575 0.031"/>
    <parent link="bendermobile_base_link"/>
    <child link="benderrear_right_wheel"/>
    <axis xyz="0 1 0"/>
  </joint>
  <link name="benderrear_right_wheel">
    <inertial>
      <origin rpy="1.57079632679 0 0" xyz="0 -0.025 0"/>
      <inertia ixx="0.135416666667" ixy="0.0" ixz="0.0" iyy="0.135416666667" iyz="0.0" izz="0.25"/>
      <mass value="50.0"/>
    </inertial>
    <visual>
      <origin rpy="0 0 0" xyz="0 0 0"/>
      <geometry>
        <mesh filename="package://bender_description/meshes/visual/wheel.dae"/>
      </geometry>
      <material name="Grey3"/>
    </visual>
    <collision>
      <origin rpy="-1.57079632679 0 0" xyz="0 -0.025 0"/>
      <geometry>
        <cylinder length="0.05" radius="0.1"/>
      </geometry>
    </collision>
  </link>
  <transmission name="rear_right_wheel_joint_transmission">
    <type>transmission_interface/SimpleTransmission</type>
    <joint name="rear_right_wheel_joint">
      <hardwareInterface>EffortJointInterface</hardwareInterface>
    </joint>
    <actuator name="rear_right_wheel_joint_motor">
      <hardwareInterface>EffortJointInterface</hardwareInterface>
      <mechanicalReduction>1</mechanicalReduction>
    </actuator>
  </transmission>
  <gazebo reference="benderrear_right_wheel">
    <kp>1000000.0</kp>
    <!-- kp and kd for rubber -->
    <kd>100.0</kd>
    <mu1>0.8</mu1>
    <!-- was 10 -->
    <mu2>0.8</mu2>
    <!-- how to get these into <surface><friction><ode>... ?
          slip1 0.5 /slip1 
           slip2 0 /slip2 
        -->
    <fdir1>1 0 0</fdir1>
    <!-- is this correct? -->
    <maxVel>1.0</maxVel>
    <minDepth>0.00</minDepth>
  </gazebo>
  <joint name="front_left_wheel_joint" type="continuous">
    <!-- Front case -->
    <origin rpy="0 0 0" xyz="0.11798 0.1575 0.031"/>
    <!-- Rear case -->
    <parent link="bendermobile_base_link"/>
    <child link="benderfront_left_wheel"/>
    <axis xyz="0 1 0"/>
  </joint>
  <link name="benderfront_left_wheel">
    <inertial>
      <origin rpy="1.57079632679 0 0" xyz="0 0.025 0"/>
      <inertia ixx="0.135416666667" ixy="0.0" ixz="0.0" iyy="0.135416666667" iyz="0.0" izz="0.25"/>
      <mass value="50.0"/>
    </inertial>
    <visual>
      <origin rpy="3.14159265359 0 0" xyz="0 0 0"/>
      <geometry>
        <mesh filename="package://bender_description/meshes/visual/wheel.dae"/>
      </geometry>
      <material name="Grey3"/>
    </visual>
    <collision>
      <origin rpy="-1.57079632679 0 0" xyz="0 0.025 0"/>
      <geometry>
        <cylinder length="0.05" radius="0.1"/>
      </geometry>
    </collision>
  </link>
  <transmission name="front_left_wheel_joint_transmission">
    <type>transmission_interface/SimpleTransmission</type>
    <joint name="front_left_wheel_joint">
      <hardwareInterface>EffortJointInterface</hardwareInterface>
    </joint>
    <actuator name="front_left_wheel_joint_motor">
      <hardwareInterface>EffortJointInterface</hardwareInterface>
      <mechanicalReduction>1</mechanicalReduction>
    </actuator>
  </transmission>
  <gazebo reference="benderfront_left_wheel">
    <kp>1000000.0</kp>
    <!-- kp and kd for rubber -->
    <kd>100.0</kd>
    <mu1>0.8</mu1>
    <!-- was 10 -->
    <mu2>0.8</mu2>
    <!-- how to get these into <surface><friction><ode>... ?
          slip1 0.5 /slip1 
           slip2 0 /slip2 
        -->
    <fdir1>1 0 0</fdir1>
    <!-- is this correct? -->
    <maxVel>1.0</maxVel>
    <minDepth>0.00</minDepth>
  </gazebo>
  <joint name="rear_left_wheel_joint" type="continuous">
    <!-- Front case -->
    <!-- Rear case -->
    <origin rpy="0 0 0" xyz="-0.13202 0.1575 0.031"/>
    <parent link="bendermobile_base_link"/>
    <child link="benderrear_left_wheel"/>
    <axis xyz="0 1 0"/>
  </joint>
  <link name="benderrear_left_wheel">
    <inertial>
      <origin rpy="1.57079632679 0 0" xyz="0 0.025 0"/>
      <inertia ixx="0.135416666667" ixy="0.0" ixz="0.0" iyy="0.135416666667" iyz="0.0" izz="0.25"/>
      <mass value="50.0"/>
    </inertial>
    <visual>
      <origin rpy="3.14159265359 0 0" xyz="0 0 0"/>
      <geometry>
        <mesh filename="package://bender_description/meshes/visual/wheel.dae"/>
      </geometry>
      <material name="Grey3"/>
    </visual>
    <collision>
      <origin rpy="-1.57079632679 0 0" xyz="0 0.025 0"/>
      <geometry>
        <cylinder length="0.05" radius="0.1"/>
      </geometry>
    </collision>
  </link>
  <transmission name="rear_left_wheel_joint_transmission">
    <type>transmission_interface/SimpleTransmission</type>
    <joint name="rear_left_wheel_joint">
      <hardwareInterface>EffortJointInterface</hardwareInterface>
    </joint>
    <actuator name="rear_left_wheel_joint_motor">
      <hardwareInterface>EffortJointInterface</hardwareInterface>
      <mechanicalReduction>1</mechanicalReduction>
    </actuator>
  </transmission>
  <gazebo reference="benderrear_left_wheel">
    <kp>1000000.0</kp>
    <!-- kp and kd for rubber -->
    <kd>100.0</kd>
    <mu1>0.8</mu1>
    <!-- was 10 -->
    <mu2>0.8</mu2>
    <!-- how to get these into <surface><friction><ode>... ?
          slip1 0.5 /slip1 
           slip2 0 /slip2 
        -->
    <fdir1>1 0 0</fdir1>
    <!-- is this correct? -->
    <maxVel>1.0</maxVel>
    <minDepth>0.00</minDepth>
  </gazebo>
  <!-- Gazebo P3AT Controller and transmissions-->
  <gazebo>
    <plugin filename="libgazebo_ros_skid_steer_drive.so" name="skid_steer_drive_controller">
      <robotNamespace>bendernav</robotNamespace>
      <updateRate>50.0</updateRate>
      <leftFrontJoint>front_left_wheel_joint</leftFrontJoint>
      <rightFrontJoint>front_right_wheel_joint</rightFrontJoint>
      <leftRearJoint>rear_left_wheel_joint</leftRearJoint>
      <rightRearJoint>rear_right_wheel_joint</rightRearJoint>
      <wheelSeparation>0.4</wheelSeparation>
      <wheelDiameter>0.215</wheelDiameter>
      <robotBaseFrame>benderbase_link</robotBaseFrame>
      <torque>400</torque>
      <MaxForce>10.0</MaxForce>
      <commandTopic>base/cmd_vel</commandTopic>
      <odometryTopic>odom</odometryTopic>
      <odometryFrame>benderodom</odometryFrame>
      <broadcastTF>1</broadcastTF>
    </plugin>
  </gazebo>
  <link name="benderbase_link"/>
  <joint name="mobile_base_fixed_joint" type="fixed">
    <origin rpy="0 0 0" xyz="0 0 0"/>
    <parent link="benderbase_link"/>
    <child link="bendermobile_base_link"/>
  </joint>
  <link name="bendermobile_base_link">
    <inertial>
      <origin rpy="0 0 0" xyz="0 0 0.1"/>
      <mass value="12.0"/>
      <inertia ixx="0.1844" ixy="0.0" ixz="0.0" iyy="0.3316" iyz="0.0" izz="0.436"/>
    </inertial>
    <visual>
      <origin rpy="0 0 0" xyz="0 0 0"/>
      <geometry>
        <mesh filename="package://bender_description/meshes/visual/base.dae"/>
      </geometry>
      <material name="">
        <color rgba="0.1 0.1 0.1 1"/>
      </material>
    </visual>
    <collision>
      <origin rpy="0 0 0" xyz="0 0 0.075"/>
      <geometry>
        <box size="0.4 0.3 0.15"/>
      </geometry>
    </collision>
    <collision>
      <origin rpy="0 0 0" xyz="0 0 0.17"/>
      <geometry>
        <box size="0.54 0.38 0.05"/>
      </geometry>
    </collision>
  </link>
  <!-- Base footprint -->
  <link name="benderbase_footprint">
    <inertial>
      <mass value="1e-5"/>
      <origin rpy="0 0 0" xyz="0 0 0"/>
      <inertia ixx="1e-6" ixy="0" ixz="0" iyy="1e-6" iyz="0" izz="1e-6"/>
    </inertial>
  </link>
  <joint name="base_footprint_fixed_joint" type="fixed">
    <origin rpy="0 0 0" xyz="0 0 -0.069"/>
    <parent link="benderbase_link"/>
    <child link="benderbase_footprint"/>
    <axis xyz="0 0 0"/>
  </joint>
  <!-- Torso base link -->
  <link name="bendertorso_base_link">
    <inertial>
      <mass value="1e-5"/>
      <origin rpy="0 0 0" xyz="0 0 0"/>
      <inertia ixx="1e-6" ixy="0" ixz="0" iyy="1e-6" iyz="0" izz="1e-6"/>
    </inertial>
  </link>
  <joint name="torso_base_fixed_joint" type="fixed">
    <origin rpy="0 0 0" xyz="-0.0040583 0.00081911 0.195"/>
    <parent link="benderbase_link"/>
    <child link="bendertorso_base_link"/>
    <axis xyz="0 0 0"/>
  </joint>
  <!-- Torso -->
  <!-- Body Base link (Parent of all future links)-->
  <link name="bendertorso">
    <inertial>
      <origin rpy="0 0 0" xyz="-0.000124342717756221 0.400487766454633 -0.000124342717754612"/>
      <mass value="2.6839966623691"/>
      <inertia ixx="0.215476685026517" ixy="-0.000126615345980391" ixz="4.14975715549634E-08" iyy="0.00132668550681761" iyz="-0.000126615345980623" izz="0.215476685026517"/>
    </inertial>
    <visual>
      <origin rpy="0 0 0" xyz="0 0 0.2"/>
      <geometry>
        <mesh filename="package://espr/meshes/torso.STL"/>
      </geometry>
      <material name="">
        <color rgba="0.650980392156863 0.619607843137255 0.588235294117647 1"/>
      </material>
    </visual>
    <collision>
      <origin rpy="0 0 0" xyz="0 0 0.2"/>
      <geometry>
        <mesh filename="package://espr/meshes/torso.STL"/>
      </geometry>
    </collision>
  </link>
  <!--Base of the PC-->
  <link name="benderPC_Base">
    <inertial>
      <origin rpy="0 0 1.57" xyz="-0.047995 -0.034202 -0.7282"/>
      <mass value="0.30233"/>
      <inertia ixx="0.005103" ixy="0.0004073" ixz="-0.00044025" iyy="0.0027955" iyz="-7.5418E-05" izz="0.0027419"/>
    </inertial>
    <visual>
      <origin rpy="0 0 1.57" xyz="0 0 0"/>
      <geometry>
        <mesh filename="package://espr/meshes/PC_Base.STL"/>
      </geometry>
      <material name="">
        <color rgba="0.79216 0.81961 0.93333 1"/>
      </material>
    </visual>
    <collision>
      <origin rpy="0 0 1.57" xyz="0 0 0"/>
      <geometry>
        <mesh filename="package://espr/meshes/PC_Base.STL"/>
      </geometry>
    </collision>
  </link>
  <!--joining the PCBASE LINK to the TORSO LINK-->
  <joint name="PC_Base_torso_joint" type="fixed">
    <origin rpy="0 0 0" xyz="0 0 0.2"/>
    <parent link="bendertorso"/>
    <child link="benderPC_Base"/>
    <axis xyz="0 0 1"/>
  </joint>
  <!--Router Box Link-->
  <link name="benderrouter">
    <inertial>
      <origin rpy="0 0 0" xyz="0.1305 0.0071427 -0.10701"/>
      <mass value="0.22663"/>
      <inertia ixx="0.00094829" ixy="-3.2425E-10" ixz="-1.2029E-09" iyy="0.0026031" iyz="-3.6199E-05" izz="0.0017029"/>
    </inertial>
    <visual>
      <origin rpy="3.14 0 1.57" xyz="0 -0.1305 0"/>
      <geometry>
        <mesh filename="package://espr/meshes/router.STL"/>
      </geometry>
      <material name="">
        <color rgba="0.75294 0.75294 0.75294 1"/>
      </material>
    </visual>
    <collision>
      <origin rpy="3.14 0 1.57" xyz="0 -0.1305 0"/>
      <geometry>
        <mesh filename="package://espr/meshes/router.STL"/>
      </geometry>
    </collision>
  </link>
  <!--Joint Between the Router and the BOdy-->
  <joint name="router_to_torso_joint" type="fixed">
    <origin rpy="0 0 0" xyz="0.02305 0 0.44504"/>
    <parent link="bendertorso"/>
    <child link="benderrouter"/>
    <axis xyz="0 0 -1"/>
  </joint>
  <!--Bender Left shoulder, here we will later fixe the left arm-->
  <link name="benderleft_shoulder">
    <inertial>
      <origin rpy="0 0 0" xyz="0.0575 -2.6795E-06 0.09625"/>
      <mass value="0.78738"/>
      <inertia ixx="0.0023474" ixy="-4.2942E-18" ixz="2.2768E-18" iyy="0.0045718" iyz="-1.7258E-18" izz="0.0024042"/>
    </inertial>
    <visual>
      <origin rpy="1.57 1.57 0" xyz="0 0 0"/>
      <geometry>
        <mesh filename="package://espr/meshes/left_shoulder.STL"/>
      </geometry>
      <material name="">
        <color rgba="0.89804 0.91765 0.92941 1"/>
      </material>
    </visual>
    <collision>
      <origin rpy="1.57 1.57 0" xyz="0 0 0"/>
      <geometry>
        <mesh filename="package://espr/meshes/left_shoulder.STL"/>
      </geometry>
    </collision>
  </link>
  <!-- Here we join the left shoulder with the Body with the-->
  <joint name="left_shoulder_to_torso_joint" type="fixed">
    <origin rpy="0 0 0" xyz="0 0 1.0575"/>
    <parent link="bendertorso"/>
    <child link="benderleft_shoulder"/>
  </joint>
  <!--Bender right shoulder, here we will later fixe the right arm-->
  <link name="benderright_shoulder">
    <inertial>
      <origin rpy="0 0 0" xyz="-0.0575 -2.6795E-06 0.09625"/>
      <mass value="0.78738"/>
      <inertia ixx="0.0023474" ixy="3.0862E-19" ixz="1.8431E-18" iyy="0.0045718" iyz="-4.9816E-19" izz="0.0024042"/>
    </inertial>
    <visual>
      <origin rpy="-1.57 -1.57 0" xyz="0 0 0"/>
      <geometry>
        <mesh filename="package://espr/meshes/right_shoulder.STL"/>
      </geometry>
      <material name="">
        <color rgba="0.89804 0.91765 0.92941 1"/>
      </material>
    </visual>
    <collision>
      <origin rpy="-1.57 -1.57 0" xyz="0 0 0"/>
      <geometry>
        <mesh filename="package://espr/meshes/right_shoulder.STL"/>
      </geometry>
    </collision>
  </link>
  <!-- Here we join the left shoulder with the Body with the-->
  <joint name="right_shoulder_to_torso_joint" type="fixed">
    <origin rpy="0 0 0" xyz="0 0 1.0575"/>
    <parent link="bendertorso"/>
    <child link="benderright_shoulder"/>
  </joint>
  <!-- here we have already created the Torso of Bender, so now we will create the joint with the other bender base-->
  <!-- Torso joint to the Base-->
  <joint name="lower_torso_mount_fixed_joint" type="fixed">
    <origin rpy="0 0 0" xyz="0 0 0"/>
    <parent link="bendermobile_base_link"/>
    <child link="bendertorso"/>
  </joint>
  <!--Neck base link -->
  <link name="benderneck_base"/>
  <joint name="neck_base_to_body" type="fixed">
    <origin rpy="0 0 0" xyz="0.03 0 1.1"/>
    <parent link="bendertorso"/>
    <child link="benderneck_base"/>
  </joint>
  <!-- Arm -->
  <!-- Left Arm -->
  <link name="benderl_arm_base_link ">
    <inertial>
      <origin rpy="0 0 0" xyz="0.0339059249220753 -0.0346573513549 -0.0793288246357902"/>
      <mass value="0.324615512393576"/>
      <inertia ixx="0.00094969466163847" ixy="3.03268200003588E-08" ixz="-1.68045404581414E-09" iyy="0.00102886083053475" iyz="2.95215412733647E-06" izz="0.000216458880037149"/>
    </inertial>
    <visual>
      <origin rpy="0 0 -3.14" xyz="0 0 0"/>
      <geometry>
        <mesh filename="package://mark_xi_urdf/meshes/l_arm_base_link .STL"/>
      </geometry>
      <material name="">
        <color rgba="0.792156862745098 0.819607843137255 0.933333333333333 1"/>
      </material>
    </visual>
    <collision>
      <origin rpy="0 0 -3.14" xyz="0 0 0"/>
      <geometry>
        <mesh filename="package://mark_xi_urdf/meshes/l_arm_base_link .STL"/>
      </geometry>
    </collision>
  </link>
  <link name="benderl_shoulder_pitch_link">
    <inertial>
      <origin rpy="0 0 0" xyz="-0.000221371017997962 -0.0215149739448 -0.0138464644250362"/>
      <mass value="0.118005125822399"/>
      <inertia ixx="6.71552220838397E-05" ixy="-2.93566896160789E-07" ixz="1.02730316391641E-06" iyy="6.67648208042396E-05" iyz="1.04550036931575E-06" izz="5.29945450856649E-05"/>
    </inertial>
    <visual>
      <origin rpy="0 0 3.14" xyz="0 0 0"/>
      <geometry>
        <mesh filename="package://mark_xi_urdf/meshes/l_shoulder_pitch_link.STL"/>
      </geometry>
      <material name="">
        <color rgba="0.792156862745098 0.819607843137255 0.933333333333333 1"/>
      </material>
    </visual>
    <collision>
      <origin rpy="0 0 3.14" xyz="0 0 0"/>
      <geometry>
        <mesh filename="package://mark_xi_urdf/meshes/l_shoulder_pitch_link.STL"/>
      </geometry>
    </collision>
  </link>
  <joint name="l_shoulder_pitch_joint" type="revolute">
    <origin rpy="4.5542E-05 5.6528E-07 -0.02481" xyz="-0.0339 -0.0594 -0.0618"/>
    <parent link="benderl_arm_base_link "/>
    <child link="benderl_shoulder_pitch_link"/>
    <axis xyz="-0.024808 0.99969 -4.5542E-05"/>
    <limit effort="5" lower="-1.57" upper="1.57" velocity="5"/>
    <transmission name="l_shoulder_pitch_joint_transmission">
      <type>transmission_interface/SimpleTransmission</type>
      <joint name="l_shoulder_pitch_joint">
        <hardwareInterface>EffortJointInterface</hardwareInterface>
      </joint>
      <actuator name="l_shoulder_pitch_joint_motor">
        <hardwareInterface>EffortJointInterface</hardwareInterface>
        <mechanicalReduction>1</mechanicalReduction>
      </actuator>
    </transmission>
  </joint>
  <link name="benderl_shoulder_roll_link">
    <inertial>
      <origin rpy="0 0 0" xyz="-0.0127881033931593 0.00116689875427 -0.0732629777499247"/>
      <mass value="0.129672533071992"/>
      <inertia ixx="0.000106058562030565" ixy="-2.00812092058978E-07" ixz="1.4889560969923E-05" iyy="0.000121640210228128" iyz="-1.18206261114108E-07" izz="7.10184582455892E-05"/>
    </inertial>
    <visual>
      <origin rpy="0 0 0" xyz="0 0 0"/>
      <geometry>
        <mesh filename="package://mark_xi_urdf/meshes/l_shoulder_roll_link.STL"/>
      </geometry>
      <material name="">
        <color rgba="0.792156862745098 0.819607843137255 0.933333333333333 1"/>
      </material>
    </visual>
    <collision>
      <origin rpy="0 0 0" xyz="0 0 0"/>
      <geometry>
        <mesh filename="package://mark_xi_urdf/meshes/l_shoulder_roll_link.STL"/>
      </geometry>
    </collision>
  </link>
  <joint name="l_shoulder_roll_joint" type="revolute">
    <origin rpy="0 0 0" xyz="0.030013 -0.029852 -0.030058"/>
    <parent link="benderl_shoulder_pitch_link"/>
    <child link="benderl_shoulder_roll_link"/>
    <axis xyz="0.99969 0.024807 -0.0018441"/>
    <limit effort="5" lower="-1.57" upper="0.1" velocity="5"/>
    <transmission name="l_shoulder_roll_joint_transmission">
      <type>transmission_interface/SimpleTransmission</type>
      <joint name="l_shoulder_roll_joint">
        <hardwareInterface>EffortJointInterface</hardwareInterface>
      </joint>
      <actuator name="l_shoulder_roll_joint_motor">
        <hardwareInterface>EffortJointInterface</hardwareInterface>
        <mechanicalReduction>1</mechanicalReduction>
      </actuator>
    </transmission>
  </joint>
  <link name="benderl_shoulder_yaw_link">
    <inertial>
      <origin rpy="0 0 0" xyz="-0.0042741524333052 0.00147100758699 -0.125094329141736"/>
      <mass value="0.193031535918604"/>
      <inertia ixx="0.000638890655282308" ixy="7.46808129045532E-07" ixz="6.43023973460341E-05" iyy="0.00063979193548822" iyz="-7.99651206771933E-06" izz="7.9269769463747E-05"/>
    </inertial>
    <visual>
      <origin rpy="0 0 0" xyz="0 0 0"/>
      <geometry>
        <mesh filename="package://mark_xi_urdf/meshes/l_shoulder_yaw_link.STL"/>
      </geometry>
      <material name="">
        <color rgba="0.792156862745098 0.819607843137255 0.933333333333333 1"/>
      </material>
    </visual>
    <collision>
      <origin rpy="0 0 0" xyz="0 0 0"/>
      <geometry>
        <mesh filename="package://mark_xi_urdf/meshes/l_shoulder_yaw_link.STL"/>
      </geometry>
    </collision>
  </link>
  <joint name="l_shoulder_yaw_joint" type="revolute">
    <origin rpy="0 0 0" xyz="-0.030926 0.0014463 -0.061069"/>
    <parent link="benderl_shoulder_roll_link"/>
    <child link="benderl_shoulder_yaw_link"/>
    <axis xyz="0.001568 0.011145 0.99994"/>
    <limit effort="5" lower="-1.37" upper="1.37" velocity="5"/>
    <transmission name="l_shoulder_yaw_joint_transmission">
      <type>transmission_interface/SimpleTransmission</type>
      <joint name="l_shoulder_yaw_joint">
        <hardwareInterface>EffortJointInterface</hardwareInterface>
      </joint>
      <actuator name="l_shoulder_yaw_joint_motor">
        <hardwareInterface>EffortJointInterface</hardwareInterface>
        <mechanicalReduction>1</mechanicalReduction>
      </actuator>
    </transmission>
  </joint>
  <link name="benderl_elbow_pitch_link">
    <inertial>
      <origin rpy="0 0 0" xyz="-0.0205546644536709 0.0301741743082 -0.0621442193179244"/>
      <mass value="0.129181389472737"/>
      <inertia ixx="0.000115532355980425" ixy="-1.36144419821721E-07" ixz="3.27716548999973E-06" iyy="0.000103173310386321" iyz="-8.00426740669056E-07" izz="7.79747801198953E-05"/>
    </inertial>
    <visual>
      <origin rpy="0 0 0" xyz="0 0 0"/>
      <geometry>
        <mesh filename="package://mark_xi_urdf/meshes/l_elbow_pitch_link.STL"/>
      </geometry>
      <material name="">
        <color rgba="0.792156862745098 0.819607843137255 0.933333333333333 1"/>
      </material>
    </visual>
    <collision>
      <origin rpy="0 0 0" xyz="0 0 0"/>
      <geometry>
        <mesh filename="package://mark_xi_urdf/meshes/l_elbow_pitch_link.STL"/>
      </geometry>
    </collision>
  </link>
  <joint name="l_elbow_pitch_joint" type="revolute">
    <origin rpy="0 0 0" xyz="-0.00086942 -0.032609 -0.18837"/>
    <parent link="benderl_shoulder_yaw_link"/>
    <child link="benderl_elbow_pitch_link"/>
    <axis xyz="0 0.99994 -0.011145"/>
    <limit effort="5" lower="-1.57" upper="0" velocity="5"/>
    <transmission name="l_elbow_pitch_joint_transmission">
      <type>transmission_interface/SimpleTransmission</type>
      <joint name="l_elbow_pitch_joint">
        <hardwareInterface>EffortJointInterface</hardwareInterface>
      </joint>
      <actuator name="l_elbow_pitch_joint_motor">
        <hardwareInterface>EffortJointInterface</hardwareInterface>
        <mechanicalReduction>1</mechanicalReduction>
      </actuator>
    </transmission>
  </joint>
  <link name="benderl_elbow_yaw_link">
    <inertial>
      <origin rpy="0 0 0" xyz="0.00350640702176266 0.00173363568001 -0.172601672590221"/>
      <mass value="0.155262882498321"/>
      <inertia ixx="0.00163142852685609" ixy="-8.6800076732075E-07" ixz="-7.92260626771847E-05" iyy="0.00163324433834166" iyz="-1.77335791004885E-05" izz="5.36208143914715E-05"/>
    </inertial>
    <visual>
      <origin rpy="0 0 0" xyz="0 0 0"/>
      <geometry>
        <mesh filename="package://mark_xi_urdf/meshes/l_elbow_yaw_link.STL"/>
      </geometry>
      <material name="">
        <color rgba="0.792156862745098 0.819607843137255 0.933333333333333 1"/>
      </material>
    </visual>
    <collision>
      <origin rpy="0 0 0" xyz="0 0 0"/>
      <geometry>
        <mesh filename="package://mark_xi_urdf/meshes/l_elbow_yaw_link.STL"/>
      </geometry>
    </collision>
  </link>
  <joint name="l_elbow_yaw_joint" type="revolute">
    <origin rpy="0 0 0" xyz="0.00091833 0.030253 -0.049238"/>
    <parent link="benderl_elbow_pitch_link"/>
    <child link="benderl_elbow_yaw_link"/>
    <axis xyz="-6.9045E-05 0.011145 0.99994"/>
    <limit effort="5" lower="-1.2" upper="1.2" velocity="5"/>
    <transmission name="l_elbow_yaw_joint_transmission">
      <type>transmission_interface/SimpleTransmission</type>
      <joint name="l_elbow_yaw_joint">
        <hardwareInterface>EffortJointInterface</hardwareInterface>
      </joint>
      <actuator name="l_elbow_yaw_joint_motor">
        <hardwareInterface>EffortJointInterface</hardwareInterface>
        <mechanicalReduction>1</mechanicalReduction>
      </actuator>
    </transmission>
  </joint>
  <link name="benderl_wrist_pitch_link">
    <inertial>
      <origin rpy="0 0 0" xyz="-0.000553462649978603 -0.0167424085523 -0.0540051282198145"/>
      <mass value="0.173798825796448"/>
      <inertia ixx="0.000150181197524477" ixy="1.42925638605822E-06" ixz="1.5108541448373E-07" iyy="9.27339297169167E-05" iyz="2.0947431248222E-07" izz="0.000112444049132553"/>
    </inertial>
    <visual>
      <origin rpy="0 0 0" xyz="0 0 0"/>
      <geometry>
        <mesh filename="package://mark_xi_urdf/meshes/l_wrist_pitch_link.STL"/>
      </geometry>
      <material name="">
        <color rgba="0.792156862745098 0.819607843137255 0.933333333333333 1"/>
      </material>
    </visual>
    <collision>
      <origin rpy="0 0 0" xyz="0 0 0"/>
      <geometry>
        <mesh filename="package://mark_xi_urdf/meshes/l_wrist_pitch_link.STL"/>
      </geometry>
    </collision>
  </link>
  <joint name="l_wrist_pitch_joint" type="revolute">
    <origin rpy="0 0 0" xyz="0.00020829 -0.019843 -0.29049"/>
    <parent link="benderl_elbow_yaw_link"/>
    <child link="benderl_wrist_pitch_link"/>
    <axis xyz="-0.024817 0.99963 -0.011143"/>
    <limit effort="5" lower="-1.57" upper="1.57" velocity="5"/>
    <transmission name="l_wrist_pitch_joint_transmission">
      <type>transmission_interface/SimpleTransmission</type>
      <joint name="l_wrist_pitch_joint">
        <hardwareInterface>EffortJointInterface</hardwareInterface>
      </joint>
      <actuator name="l_wrist_pitch_joint_motor">
        <hardwareInterface>EffortJointInterface</hardwareInterface>
        <mechanicalReduction>1</mechanicalReduction>
      </actuator>
    </transmission>
  </joint>
  <!--****Union Arms and shoulders*****-->
  <joint name="benderl_arm_to_benderleft_shoulder_joint" type="fixed">
    <origin rpy="0 0 0" xyz="0.03 -0.15 0.017"/>
    <parent link="benderleft_shoulder"/>
    <child link="benderl_arm_base_link "/>
  </joint>
  <!-- Right Arm -->
  <link name="benderr_arm_base_link ">
    <inertial>
      <origin rpy="0 0 0" xyz="0.0339059249220753 0.0346573513549 -0.0793288246357902"/>
      <mass value="0.324615512393576"/>
      <inertia ixx="0.00094969466163847" ixy="3.03268200003588E-08" ixz="-1.68045404581414E-09" iyy="0.00102886083053475" iyz="2.95215412733647E-06" izz="0.000216458880037149"/>
    </inertial>
    <visual>
      <origin rpy="0 0 0" xyz="0 0 0"/>
      <geometry>
        <mesh filename="package://mark_xi_urdf/meshes/l_arm_base_link .STL"/>
      </geometry>
      <material name="">
        <color rgba="0.792156862745098 0.819607843137255 0.933333333333333 1"/>
      </material>
    </visual>
    <collision>
      <origin rpy="0 0 0" xyz="0 0 0"/>
      <geometry>
        <mesh filename="package://mark_xi_urdf/meshes/l_arm_base_link .STL"/>
      </geometry>
    </collision>
  </link>
  <link name="benderr_shoulder_pitch_link">
    <inertial>
      <origin rpy="0 0 0" xyz="-0.000221371017997962 0.0215149739448 -0.0138464644250362"/>
      <mass value="0.118005125822399"/>
      <inertia ixx="6.71552220838397E-05" ixy="-2.93566896160789E-07" ixz="1.02730316391641E-06" iyy="6.67648208042396E-05" iyz="1.04550036931575E-06" izz="5.29945450856649E-05"/>
    </inertial>
    <visual>
      <origin rpy="0 0 0" xyz="0 0 0"/>
      <geometry>
        <mesh filename="package://mark_xi_urdf/meshes/l_shoulder_pitch_link.STL"/>
      </geometry>
      <material name="">
        <color rgba="0.792156862745098 0.819607843137255 0.933333333333333 1"/>
      </material>
    </visual>
    <collision>
      <origin rpy="0 0 0" xyz="0 0 0"/>
      <geometry>
        <mesh filename="package://mark_xi_urdf/meshes/l_shoulder_pitch_link.STL"/>
      </geometry>
    </collision>
  </link>
  <joint name="r_shoulder_pitch_joint" type="revolute">
    <origin rpy="4.5542E-05 5.6528E-07 -0.02481" xyz="0.0339 0.0594 -0.0618"/>
    <parent link="benderr_arm_base_link "/>
    <child link="benderr_shoulder_pitch_link"/>
    <axis xyz="-0.024808 0.99969 -4.5542E-05"/>
    <limit effort="5" lower="-1.57" upper="1.57" velocity="5"/>
  </joint>
  <link name="benderr_shoulder_roll_link">
    <inertial>
      <origin rpy="0 0 0" xyz="-0.0127881033931593 -0.00116689875426995 -0.0732629777499247"/>
      <mass value="0.129672533071992"/>
      <inertia ixx="0.000106058562030565" ixy="-2.00812092058978E-07" ixz="1.4889560969923E-05" iyy="0.000121640210228128" iyz="-1.18206261114108E-07" izz="7.10184582455892E-05"/>
    </inertial>
    <visual>
      <origin rpy="0 0 0" xyz="0 0 0"/>
      <geometry>
        <mesh filename="package://mark_xi_urdf/meshes/l_shoulder_roll_link.STL"/>
      </geometry>
      <material name="">
        <color rgba="0.792156862745098 0.819607843137255 0.933333333333333 1"/>
      </material>
    </visual>
    <collision>
      <origin rpy="0 0 0" xyz="0 0 0"/>
      <geometry>
        <mesh filename="package://mark_xi_urdf/meshes/l_shoulder_roll_link.STL"/>
      </geometry>
    </collision>
  </link>
  <joint name="r_shoulder_roll_joint" type="revolute">
    <origin rpy="0 0 0" xyz="0.030013 0.029852 -0.030058"/>
    <parent link="benderr_shoulder_pitch_link"/>
    <child link="benderr_shoulder_roll_link"/>
    <axis xyz="0.99969 0.024807 -0.0018441"/>
    <limit effort="5" lower="-0.1" upper="1.57" velocity="5"/>
  </joint>
  <link name="benderr_shoulder_yaw_link">
    <inertial>
      <origin rpy="0 0 0" xyz="-0.0042741524333052 -0.00147100758699 -0.125094329141736"/>
      <mass value="0.193031535918604"/>
      <inertia ixx="0.000638890655282308" ixy="7.46808129045532E-07" ixz="6.43023973460341E-05" iyy="0.00063979193548822" iyz="-7.99651206771933E-06" izz="7.9269769463747E-05"/>
    </inertial>
    <visual>
      <origin rpy="0 0 0" xyz="0 0 0"/>
      <geometry>
        <mesh filename="package://mark_xi_urdf/meshes/l_shoulder_yaw_link.STL"/>
      </geometry>
      <material name="">
        <color rgba="0.792156862745098 0.819607843137255 0.933333333333333 1"/>
      </material>
    </visual>
    <collision>
      <origin rpy="0 0 0" xyz="0 0 0"/>
      <geometry>
        <mesh filename="package://mark_xi_urdf/meshes/l_shoulder_yaw_link.STL"/>
      </geometry>
    </collision>
  </link>
  <joint name="r_shoulder_yaw_joint" type="revolute">
    <origin rpy="0 0 0" xyz="-0.030926 -0.0014463 -0.061069"/>
    <parent link="benderr_shoulder_roll_link"/>
    <child link="benderr_shoulder_yaw_link"/>
    <axis xyz="0.001568 0.011145 0.99994"/>
    <limit effort="5" lower="-1.37" upper="1.37" velocity="5"/>
  </joint>
  <link name="benderr_elbow_pitch_link">
    <inertial>
      <origin rpy="0 0 0" xyz="-0.0205546644536709 -0.0301741743082 -0.0621442193179244"/>
      <mass value="0.129181389472737"/>
      <inertia ixx="0.000115532355980425" ixy="-1.36144419821721E-07" ixz="3.27716548999973E-06" iyy="0.000103173310386321" iyz="-8.00426740669056E-07" izz="7.79747801198953E-05"/>
    </inertial>
    <visual>
      <origin rpy="0 0 0" xyz="0 0 0"/>
      <geometry>
        <mesh filename="package://mark_xi_urdf/meshes/l_elbow_pitch_link.STL"/>
      </geometry>
      <material name="">
        <color rgba="0.792156862745098 0.819607843137255 0.933333333333333 1"/>
      </material>
    </visual>
    <collision>
      <origin rpy="0 0 0" xyz="0 0 0"/>
      <geometry>
        <mesh filename="package://mark_xi_urdf/meshes/l_elbow_pitch_link.STL"/>
      </geometry>
    </collision>
  </link>
  <joint name="r_elbow_pitch_joint" type="revolute">
    <origin rpy="0 0 0" xyz="-0.00086942 -0.032609 -0.18837"/>
    <parent link="benderr_shoulder_yaw_link"/>
    <child link="benderr_elbow_pitch_link"/>
    <axis xyz="0 0.99994 -0.011145"/>
    <limit effort="5" lower="-1.57" upper="0" velocity="5"/>
  </joint>
  <link name="benderr_elbow_yaw_link">
    <inertial>
      <origin rpy="0 0 0" xyz="0.00350640702176266 -0.00173363568001 -0.172601672590221"/>
      <mass value="0.155262882498321"/>
      <inertia ixx="0.00163142852685609" ixy="-8.6800076732075E-07" ixz="-7.92260626771847E-05" iyy="0.00163324433834166" iyz="-1.77335791004885E-05" izz="5.36208143914715E-05"/>
    </inertial>
    <visual>
      <origin rpy="0 0 0" xyz="0 0 0"/>
      <geometry>
        <mesh filename="package://mark_xi_urdf/meshes/l_elbow_yaw_link.STL"/>
      </geometry>
      <material name="">
        <color rgba="0.792156862745098 0.819607843137255 0.933333333333333 1"/>
      </material>
    </visual>
    <collision>
      <origin rpy="0 0 0" xyz="0 0 0"/>
      <geometry>
        <mesh filename="package://mark_xi_urdf/meshes/l_elbow_yaw_link.STL"/>
      </geometry>
    </collision>
  </link>
  <joint name="r_elbow_yaw_joint" type="revolute">
    <origin rpy="0 0 0" xyz="0.00091833 0.030253 -0.049238"/>
    <parent link="benderr_elbow_pitch_link"/>
    <child link="benderr_elbow_yaw_link"/>
    <axis xyz="-6.9045E-05 0.011145 0.99994"/>
    <limit effort="5" lower="-1.2" upper="1.2" velocity="5"/>
  </joint>
  <link name="benderr_wrist_pitch_link">
    <inertial>
      <origin rpy="0 0 0" xyz="-0.000553462649978603 0.0167424085523 -0.0540051282198145"/>
      <mass value="0.173798825796448"/>
      <inertia ixx="0.000150181197524477" ixy="1.42925638605822E-06" ixz="1.5108541448373E-07" iyy="9.27339297169167E-05" iyz="2.0947431248222E-07" izz="0.000112444049132553"/>
    </inertial>
    <visual>
      <origin rpy="0 0 0" xyz="0 0 0"/>
      <geometry>
        <mesh filename="package://mark_xi_urdf/meshes/l_wrist_pitch_link.STL"/>
      </geometry>
      <material name="">
        <color rgba="0.792156862745098 0.819607843137255 0.933333333333333 1"/>
      </material>
    </visual>
    <collision>
      <origin rpy="0 0 0" xyz="0 0 0"/>
      <geometry>
        <mesh filename="package://mark_xi_urdf/meshes/l_wrist_pitch_link.STL"/>
      </geometry>
    </collision>
  </link>
  <joint name="r_wrist_pitch_joint" type="revolute">
    <origin rpy="0 0 0" xyz="0.00020829 -0.019843 -0.29049"/>
    <parent link="benderr_elbow_yaw_link"/>
    <child link="benderr_wrist_pitch_link"/>
    <axis xyz="-0.024817 0.99963 -0.011143"/>
    <limit effort="5" lower="-1.57" upper="1.57" velocity="5"/>
  </joint>
  <!--****Union Arms and shoulders*****-->
  <joint name="benderr_arm_to_benderright_shoulder_joint" type="fixed">
    <origin rpy="0 0 0" xyz="-0.03 0.15 0.017"/>
    <parent link="benderright_shoulder"/>
    <child link="benderr_arm_base_link "/>
  </joint>
  <!-- Head with Asus depth camera -->
  <!-- Torque -->
  <!-- Gazebo Links material 
    <xacro:gazebo_link link="${prefix}neck_link" color="Grey" />
    <xacro:gazebo_link link="${prefix}face_link" color="Grey" />
    <xacro:gazebo_link link="${prefix}head_link" color="DarkGrey" />
    -->
  <!-- Transmissions -->
  <transmission name="head_yaw_joint_transmission">
    <type>transmission_interface/SimpleTransmission</type>
    <joint name="head_yaw_joint">
      <hardwareInterface>EffortJointInterface</hardwareInterface>
    </joint>
    <actuator name="head_yaw_joint_motor">
      <hardwareInterface>EffortJointInterface</hardwareInterface>
      <mechanicalReduction>1</mechanicalReduction>
    </actuator>
  </transmission>
  <transmission name="head_pitch_joint_transmission">
    <type>transmission_interface/SimpleTransmission</type>
    <joint name="head_pitch_joint">
      <hardwareInterface>EffortJointInterface</hardwareInterface>
    </joint>
    <actuator name="head_pitch_joint_motor">
      <hardwareInterface>EffortJointInterface</hardwareInterface>
      <mechanicalReduction>1</mechanicalReduction>
    </actuator>
  </transmission>
  <link name="benderneck_link">
    <inertial>
      <origin rpy="0 0 0" xyz="-0.027227 -1.1356E-07 0.017004"/>
      <mass value="0.092467"/>
      <inertia ixx="0.00013489" ixy="-3.52E-09" ixz="-6.6205E-07" iyy="7.5254E-05" iyz="1.356E-10" izz="0.00012174"/>
    </inertial>
    <visual>
      <origin rpy="-1.57079632679 0 0" xyz="0 0 0"/>
      <geometry>
        <mesh filename="package://bender_description/meshes/visual/neck.dae"/>
      </geometry>
      <material name="Grey3"/>
    </visual>
    <collision>
      <origin rpy="0 0 0" xyz="-0.03 0 0.02"/>
      <geometry>
        <box size="0.08 0.1 0.08"/>
      </geometry>
    </collision>
  </link>
  <joint name="neck_mount_fixed_joint" type="fixed">
    <origin rpy="0 0 0" xyz="0 0 0"/>
    <parent link="benderneck_base"/>
    <child link="benderneck_link"/>
  </joint>
  <link name="benderhead_link">
    <inertial>
      <origin rpy="0 0 0" xyz="-0.012141 -1.7505E-05 0.041401"/>
      <mass value="0.17983"/>
      <inertia ixx="0.00015925" ixy="4.0867E-07" ixz="-7.9102E-06" iyy="0.0001892" iyz="-6.1427E-08" izz="8.7881E-05"/>
    </inertial>
    <visual>
      <origin rpy="-1.57079632679 0 0" xyz="0 0 0"/>
      <geometry>
        <mesh filename="package://bender_description/meshes/visual/head.dae"/>
      </geometry>
      <material name="Grey3"/>
    </visual>
    <collision>
      <origin rpy="0 0 0" xyz="-0.01 0 0.05"/>
      <geometry>
        <box size="0.08 0.06 0.10"/>
      </geometry>
    </collision>
  </link>
  <joint name="head_yaw_joint" type="revolute">
    <origin rpy="0 0 0" xyz="-0.027 0 0.0529"/>
    <parent link="benderneck_link"/>
    <child link="benderhead_link"/>
    <axis xyz="0 0 1"/>
    <limit effort="4.44054054054" lower="-1.8919" upper="1.8919" velocity="1.0"/>
    <dynamics damping="0.15"/>
  </joint>
  <link name="benderface_link">
    <inertial>
      <origin rpy="0 0 0" xyz="0.046115 -0.026111 0.10189"/>
      <mass value="0.33187"/>
      <inertia ixx="0.0013461" ixy="-2.8029E-07" ixz="-9.224E-05" iyy="0.00080978" iyz="-6.6351E-07" izz="0.00074443"/>
    </inertial>
    <visual>
      <origin rpy="-1.57079632679 0 0" xyz="0 0 0"/>
      <geometry>
        <mesh filename="package://bender_description/meshes/visual/face.dae"/>
      </geometry>
      <material name="Grey3"/>
    </visual>
    <collision>
      <origin rpy="0 0 0" xyz="0.05 -0.03 0.08"/>
      <geometry>
        <box size="0.05 0.18 0.18"/>
      </geometry>
    </collision>
  </link>
  <joint name="head_pitch_joint" type="revolute">
    <origin rpy="0 0 0" xyz="0 0.02598 0.0679"/>
    <parent link="benderhead_link"/>
    <child link="benderface_link"/>
    <axis xyz="0 1 0"/>
    <limit effort="4.44054054054" lower="-0.39372" upper="0.88459" velocity="1.0"/>
    <dynamics damping="0.15"/>
  </joint>
  <!-- Camera RGB and depth frames -->
  <link name="bendersensors/rgbd_head_rgb_frame"/>
  <joint name="rgbd_head_rgb_joint" type="fixed">
    <origin rpy="0 0.031904 0" xyz="0.05332 -0.0042 0.14105"/>
    <parent link="benderface_link"/>
    <child link="bendersensors/rgbd_head_rgb_frame"/>
    <axis xyz="0 0 0"/>
  </joint>
  <link name="bendersensors/rgbd_head_depth_frame"/>
  <joint name="rgbd_head_depth_joint" type="fixed">
    <origin rpy="0 0.031904 0" xyz="0.05332 0.0208 0.14105"/>
    <parent link="benderface_link"/>
    <child link="bendersensors/rgbd_head_depth_frame"/>
    <axis xyz="0 0 0"/>
  </joint>
  <!-- Optical frames -->
  <joint name="rgbd_head_rgb_optical_joint" type="fixed">
    <origin rpy="-1.57079632679 0 -1.57079632679" xyz="0 0 0"/>
    <parent link="bendersensors/rgbd_head_rgb_frame"/>
    <child link="bendersensors/rgbd_head_rgb_optical_frame"/>
  </joint>
  <link name="bendersensors/rgbd_head_rgb_optical_frame"/>
  <joint name="rgbd_head_depth_optical_joint" type="fixed">
    <origin rpy="-1.57079632679 0 -1.57079632679" xyz="0 0 0"/>
    <parent link="bendersensors/rgbd_head_depth_frame"/>
    <child link="bendersensors/rgbd_head_depth_optical_frame"/>
  </joint>
  <link name="bendersensors/rgbd_head_depth_optical_frame"/>
  <!-- Camera depth Gazebo -->
  <gazebo reference="bendersensors/rgbd_head_depth_frame">
    <sensor name="rgbd_head" type="depth">
      <always_on>true</always_on>
      <update_rate>5.0</update_rate>
      <camera>
        <horizontal_fov>0.994837673637</horizontal_fov>
        <image>
          <format>B8G8R8</format>
          <width>640</width>
          <height>480</height>
        </image>
        <clip>
          <near>0.01</near>
          <far>5</far>
        </clip>
      </camera>
      <plugin filename="libgazebo_ros_openni_kinect.so" name="rgbd_head_controller">
        <alwaysOn>true</alwaysOn>
        <updateRate>5.0</updateRate>
        <cameraName>rgbd_head</cameraName>
        <imageTopicName>/bendersensors/rgbd_head/rgb/image_raw</imageTopicName>
        <cameraInfoTopicName>/bendersensors/rgbd_head/rgb/camera_info</cameraInfoTopicName>
        <depthImageTopicName>/bendersensors/rgbd_head/depth/image_raw</depthImageTopicName>
        <depthImageCameraInfoTopicName>/bendersensors/rgbd_head/depth/camera_info</depthImageCameraInfoTopicName>
        <pointCloudTopicName>/bendersensors/rgbd_head/depth/points</pointCloudTopicName>
        <frameName>bendersensors/rgbd_head_depth_optical_frame</frameName>
        <baseline>0.1</baseline>
        <distortion_k1>0.0</distortion_k1>
        <distortion_k2>0.0</distortion_k2>
        <distortion_k3>0.0</distortion_k3>
        <distortion_t1>0.0</distortion_t1>
        <distortion_t2>0.0</distortion_t2>
        <pointCloudCutoff>0.35</pointCloudCutoff>
        <pointCloudCutoffMax>2.0</pointCloudCutoffMax>
      </plugin>
    </sensor>
  </gazebo>
  <!--joint name="neck_to_torso_joint" type="fixed">
      <origin xyz="0 0 0" rpy="0 0 0"/>
      <parent link="${parent}"/>
      <child link="${prefix}neck_link" />
    </joint-->
  <gazebo>
    <plugin filename="libgazebo_ros_control.so" name="ros_control">
      <robotNamespace>bender</robotNamespace>
    </plugin>
  </gazebo>
</robot>

