<?xml version="1.0" ?>
<!-- =================================================================================== -->
<!-- |    This document was autogenerated by xacro from arm_starter.urdf.xacro         | -->
<!-- |    EDITING THIS FILE BY HAND IS NOT RECOMMENDED                                 | -->
<!-- =================================================================================== -->
<robot name="juan" xmlns:xacro="http://www.ros.org/wiki/xacro">
  <!-- Parameters -->
  <!-- PI constant -->
  <!-- Dynamics -->
  <!-- Friccion -->
  <!-- Velocity -->
  <!-- Inertial cuboid element -->
  <!-- Same def that box primitive (center) -->
  <!-- Same def that box primitive -->
  <!-- Inertial sphere element -->
  <!-- Inertial cylinder element -->
  <!-- Axis along z (length) -->
  <!-- Inertial dummy element -->
  <!-- URDF Materials -->
  <material name="Grey1">
    <color rgba="0.1 0.1 0.1 1"/>
  </material>
  <material name="Grey2">
    <color rgba="0.2 0.2 0.2 1"/>
  </material>
  <material name="Grey3">
    <color rgba="0.3 0.3 0.3 1"/>
  </material>
  <material name="Body">
    <color rgba="0.85 0.85 0.85 1"/>
  </material>
  <material name="Head">
    <color rgba="0.75 0.75 0.75 1"/>
  </material>
  <!-- Gazebo macros -->
  <!-- ROS Control -->
  <!-- For Effort controllers -->
  <!-- For Position controllers -->
  <!-- No gravity links -->
  <!-- Normal links -->
  <!-- Wheel links -->
  <!-- Gripper links -->
  <!-- Depth camera plugin -->
  <!-- Base wheels plugin -->
  <!-- Laser sensor plugin -->
  <!-- Laser sensor plugin -->
  <!-- Calibration parameters, used for arms in body.urdf.xacro -->
  <!-- Normally all in 0.0 -->
  <!-- Left Arm -->
  <!-- Joint offset parameters for l_arm_base -->
  <!-- Right Arm -->
  <!-- Joint offset parameters for r_arm_base -->
  <!-- Dynamixel parameters -->
  <!-- Max torque estimation -->
  <!-- Torque/voltage relation from dynamixel_driver (this relation only works for stall torque) -->
  <!-- Friction model from "Characterization and modeling of a Dynamixel servo" by Arno Mensin (model AX12, better than nothing) -->
  <!-- Damping N.m.s/rad -->
  <!-- Friccion N.m -->
  <link name="world"/>
  <!-- ******** Bender Parts ******** -->
  <!-- Arm -->
  <!-- Left Arm -->
  <link name="benderl_arm_base_link ">
    <inertial>
      <origin rpy="0 0 0" xyz="0.0339059249220753 -0.0346573513549 -0.0793288246357902"/>
      <mass value="0.324615512393576"/>
      <inertia ixx="0.00094969466163847" ixy="3.03268200003588E-08" ixz="-1.68045404581414E-09" iyy="0.00102886083053475" iyz="2.95215412733647E-06" izz="0.000216458880037149"/>
    </inertial>
    <visual>
      <origin rpy="0 0 0" xyz="0 0 0"/>
      <geometry>
        <mesh filename="package://mark_xi_urdf/meshes/l_arm_base_link .STL"/>
      </geometry>
      <material name="">
        <color rgba="0.792156862745098 0.819607843137255 0.933333333333333 1"/>
      </material>
    </visual>
    <collision>
      <origin rpy="1.57 0 0" xyz="0 -0.3 0"/>
      <geometry>
        <mesh filename="package://mark_xi_urdf/meshes/l_arm_base_link .STL"/>
      </geometry>
    </collision>
  </link>
  <link name="benderl_shoulder_pitch_link">
    <inertial>
      <origin rpy="0 0 0" xyz="-0.000221371017997962 -0.0215149739448 -0.0138464644250362"/>
      <mass value="0.118005125822399"/>
      <inertia ixx="6.71552220838397E-05" ixy="-2.93566896160789E-07" ixz="1.02730316391641E-06" iyy="6.67648208042396E-05" iyz="1.04550036931575E-06" izz="5.29945450856649E-05"/>
    </inertial>
    <visual>
      <origin rpy="0 0 0" xyz="0 0 0"/>
      <geometry>
        <mesh filename="package://mark_xi_urdf/meshes/l_shoulder_pitch_link.STL"/>
      </geometry>
      <material name="">
        <color rgba="0.792156862745098 0.819607843137255 0.933333333333333 1"/>
      </material>
    </visual>
    <collision>
      <origin rpy="0 0 0" xyz="0 0 0"/>
      <geometry>
        <mesh filename="package://mark_xi_urdf/meshes/l_shoulder_pitch_link.STL"/>
      </geometry>
    </collision>
  </link>
  <joint name="l_shoulder_pitch_joint" type="revolute">
    <origin rpy="4.5542E-05 5.6528E-07 -0.02481" xyz="0.0339 0.0594 -0.0618"/>
    <parent link="benderl_arm_base_link "/>
    <child link="benderl_shoulder_pitch_link"/>
    <axis xyz="-0.024808 0.99969 -4.5542E-05"/>
    <limit effort="5" lower="-1.57" upper="1.57" velocity="5"/>
  </joint>
  <link name="benderl_shoulder_roll_link">
    <inertial>
      <origin rpy="0 0 0" xyz="-0.0127881033931593 0.00116689875427 -0.0732629777499247"/>
      <mass value="0.129672533071992"/>
      <inertia ixx="0.000106058562030565" ixy="-2.00812092058978E-07" ixz="1.4889560969923E-05" iyy="0.000121640210228128" iyz="-1.18206261114108E-07" izz="7.10184582455892E-05"/>
    </inertial>
    <visual>
      <origin rpy="0 0 0" xyz="0 0 0"/>
      <geometry>
        <mesh filename="package://mark_xi_urdf/meshes/l_shoulder_roll_link.STL"/>
      </geometry>
      <material name="">
        <color rgba="0.792156862745098 0.819607843137255 0.933333333333333 1"/>
      </material>
    </visual>
    <collision>
      <origin rpy="0 0 0" xyz="0 0 0"/>
      <geometry>
        <mesh filename="package://mark_xi_urdf/meshes/l_shoulder_roll_link.STL"/>
      </geometry>
    </collision>
  </link>
  <joint name="l_shoulder_roll_joint" type="revolute">
    <origin rpy="0 0 0" xyz="0.030013 0.029852 -0.030058"/>
    <parent link="benderl_shoulder_pitch_link"/>
    <child link="benderl_shoulder_roll_link"/>
    <axis xyz="0.99969 0.024807 -0.0018441"/>
    <limit effort="5" lower="-0.1" upper="1.57" velocity="5"/>
  </joint>
  <link name="benderl_shoulder_yaw_link">
    <inertial>
      <origin rpy="0 0 0" xyz="-0.0042741524333052 0.00147100758699 -0.125094329141736"/>
      <mass value="0.193031535918604"/>
      <inertia ixx="0.000638890655282308" ixy="7.46808129045532E-07" ixz="6.43023973460341E-05" iyy="0.00063979193548822" iyz="-7.99651206771933E-06" izz="7.9269769463747E-05"/>
    </inertial>
    <visual>
      <origin rpy="0 0 0" xyz="0 0 0"/>
      <geometry>
        <mesh filename="package://mark_xi_urdf/meshes/l_shoulder_yaw_link.STL"/>
      </geometry>
      <material name="">
        <color rgba="0.792156862745098 0.819607843137255 0.933333333333333 1"/>
      </material>
    </visual>
    <collision>
      <origin rpy="0 0 0" xyz="0 0 0"/>
      <geometry>
        <mesh filename="package://mark_xi_urdf/meshes/l_shoulder_yaw_link.STL"/>
      </geometry>
    </collision>
  </link>
  <joint name="l_shoulder_yaw_joint" type="revolute">
    <origin rpy="0 0 0" xyz="-0.030926 -0.0014463 -0.061069"/>
    <parent link="benderl_shoulder_roll_link"/>
    <child link="benderl_shoulder_yaw_link"/>
    <axis xyz="0.001568 0.011145 0.99994"/>
    <limit effort="5" lower="-1.37" upper="1.37" velocity="5"/>
  </joint>
  <link name="benderl_elbow_pitch_link">
    <inertial>
      <origin rpy="0 0 0" xyz="-0.0205546644536709 0.0301741743082 -0.0621442193179244"/>
      <mass value="0.129181389472737"/>
      <inertia ixx="0.000115532355980425" ixy="-1.36144419821721E-07" ixz="3.27716548999973E-06" iyy="0.000103173310386321" iyz="-8.00426740669056E-07" izz="7.79747801198953E-05"/>
    </inertial>
    <visual>
      <origin rpy="0 0 0" xyz="0 0 0"/>
      <geometry>
        <mesh filename="package://mark_xi_urdf/meshes/l_elbow_pitch_link.STL"/>
      </geometry>
      <material name="">
        <color rgba="0.792156862745098 0.819607843137255 0.933333333333333 1"/>
      </material>
    </visual>
    <collision>
      <origin rpy="0 0 0" xyz="0 0 0"/>
      <geometry>
        <mesh filename="package://mark_xi_urdf/meshes/l_elbow_pitch_link.STL"/>
      </geometry>
    </collision>
  </link>
  <joint name="l_elbow_pitch_joint" type="revolute">
    <origin rpy="0 0 0" xyz="-0.00086942 -0.032609 -0.18837"/>
    <parent link="benderl_shoulder_yaw_link"/>
    <child link="benderl_elbow_pitch_link"/>
    <axis xyz="0 0.99994 -0.011145"/>
    <limit effort="5" lower="-1.57" upper="0" velocity="5"/>
  </joint>
  <link name="benderl_elbow_yaw_link">
    <inertial>
      <origin rpy="0 0 0" xyz="0.00350640702176266 0.00173363568001 -0.172601672590221"/>
      <mass value="0.155262882498321"/>
      <inertia ixx="0.00163142852685609" ixy="-8.6800076732075E-07" ixz="-7.92260626771847E-05" iyy="0.00163324433834166" iyz="-1.77335791004885E-05" izz="5.36208143914715E-05"/>
    </inertial>
    <visual>
      <origin rpy="0 0 0" xyz="0 0 0"/>
      <geometry>
        <mesh filename="package://mark_xi_urdf/meshes/l_elbow_yaw_link.STL"/>
      </geometry>
      <material name="">
        <color rgba="0.792156862745098 0.819607843137255 0.933333333333333 1"/>
      </material>
    </visual>
    <collision>
      <origin rpy="0 0 0" xyz="0 0 0"/>
      <geometry>
        <mesh filename="package://mark_xi_urdf/meshes/l_elbow_yaw_link.STL"/>
      </geometry>
    </collision>
  </link>
  <joint name="l_elbow_yaw_joint" type="revolute">
    <origin rpy="0 0 0" xyz="0.00091833 0.030253 -0.049238"/>
    <parent link="benderl_elbow_pitch_link"/>
    <child link="benderl_elbow_yaw_link"/>
    <axis xyz="-6.9045E-05 0.011145 0.99994"/>
    <limit effort="5" lower="-1.2" upper="1.2" velocity="5"/>
  </joint>
  <link name="benderl_wrist_pitch_link">
    <inertial>
      <origin rpy="0 0 0" xyz="-0.000553462649978603 -0.0167424085523 -0.0540051282198145"/>
      <mass value="0.173798825796448"/>
      <inertia ixx="0.000150181197524477" ixy="1.42925638605822E-06" ixz="1.5108541448373E-07" iyy="9.27339297169167E-05" iyz="2.0947431248222E-07" izz="0.000112444049132553"/>
    </inertial>
    <visual>
      <origin rpy="0 0 0" xyz="0 0 0"/>
      <geometry>
        <mesh filename="package://mark_xi_urdf/meshes/l_wrist_pitch_link.STL"/>
      </geometry>
      <material name="">
        <color rgba="0.792156862745098 0.819607843137255 0.933333333333333 1"/>
      </material>
    </visual>
    <collision>
      <origin rpy="0 0 0" xyz="0 0 0"/>
      <geometry>
        <mesh filename="package://mark_xi_urdf/meshes/l_wrist_pitch_link.STL"/>
      </geometry>
    </collision>
  </link>
  <joint name="l_wrist_pitch_joint" type="revolute">
    <origin rpy="0 0 0" xyz="0.00020829 -0.019843 -0.29049"/>
    <parent link="benderl_elbow_yaw_link"/>
    <child link="benderl_wrist_pitch_link"/>
    <axis xyz="-0.024817 0.99963 -0.011143"/>
    <limit effort="5" lower="-1.57" upper="1.57" velocity="5"/>
  </joint>
  <!--****Union Arms and shoulders*****-->
  <joint name="benderl_arm_to_world_joint" type="fixed">
    <origin rpy="0 0 0" xyz="0 0 0"/>
    <parent link="world"/>
    <child link="benderl_arm_base_link "/>
  </joint>
  <!-- Right Arm -->
  <!--xacro:arm side="r" parent="${prefix}right_shoulder" reflect="1" prefix="${prefix}"/-->
</robot>

